Workbook

Sheet Master Template
D2: Feed Stock Property | P2: Product
D3: ABQ3358 | P3: HPS | AB3: LTO | AN3: High Gas | AZ3: Low Gas
C4: Pilot Plant Operation | D4: 45643 | E4: 45644 | F4: 45645 | G4: 45646 | H4: 45647 | I4: 45648 | J4: 45649 | K4: 45650 | L4: 45651 | M4: 45652 | N4: 45653 | P4: 45643 | Q4: 45644 | R4: 45645 | S4: 45646 | T4: 45647 | U4: 45648 | V4: 45649 | W4: 45650 | X4: 45651 | Y4: 45652 | Z4: 45653 | AB4: 45643 | AC4: 45644 | AD4: 45645 | AE4: 45646 | AF4: 45647 | AG4: 45648 | AH4: 45649 | AI4: 45650 | AJ4: 45651 | AK4: 45652 | AL4: 45653 | AN4: 45643 | AO4: 45644 | AP4: 45645 | AQ4: 45646 | AR4: 45647 | AS4: 45648 | AT4: 45649 | AU4: 45650 | AV4: 45651 | AW4: 45652 | AX4: 45653 | AZ4: 45643 | BA4: 45644 | BB4: 45645 | BC4: 45646 | BD4: 45647 | BE4: 45648 | BF4: 45649 | BG4: 45650 | BH4: 45651 | BI4: 45652 | BJ4: 45653
C5: Lab Date--> | D5: 45644 | E5: 45645 | F5: 45646 | G5: 45647 | H5: 45648 | I5: 45649 | J5: 45650 | K5: 45651 | L5: 45652 | M5: 45653 | N5: 45654 | P5: 45644 | Q5: 45645 | R5: 45646 | S5: 45647 | T5: 45648 | U5: 45649 | V5: 45650 | W5: 45651 | X5: 45652 | Y5: 45653 | Z5: 45654 | AB5: 45644 | AC5: 45645 | AD5: 45646 | AE5: 45647 | AF5: 45648 | AG5: 45649 | AH5: 45650 | AI5: 45651 | AJ5: 45652 | AK5: 45653 | AL5: 45654 | AN5: 45644 | AO5: 45645 | AP5: 45646 | AQ5: 45647 | AR5: 45648 | AS5: 45649 | AT5: 45650 | AU5: 45651 | AV5: 45652 | AW5: 45653 | AX5: 45654 | AZ5: 45644 | BA5: 45645 | BB5: 45646 | BC5: 45647 | BD5: 45648 | BE5: 45649 | BF5: 45650 | BG5: 45651 | BH5: 45652 | BI5: 45653 | BJ5: 45654
C6: Day--> | D6: 1 | E6: 2 | F6: 3 | G6: 4 | H6: 5 | I6: 6 | J6: 7 | K6: 8 | L6: 9 | M6: 10 | N6: 11 | P6: 1 | Q6: 2 | R6: 3 | S6: 4 | T6: 5 | U6: 6 | V6: 7 | W6: 8 | X6: 9 | Y6: 10 | Z6: 11 | AB6: 1 | AC6: 2 | AD6: 3 | AE6: 4 | AF6: 5 | AG6: 6 | AH6: 7 | AI6: 8 | AJ6: 9 | AK6: 10 | AL6: 11 | AN6: 1 | AO6: 2 | AP6: 3 | AQ6: 4 | AR6: 5 | AS6: 6 | AT6: 7 | AU6: 8 | AV6: 9 | AW6: 10 | AX6: 11 | AZ6: 1 | BA6: 2 | BB6: 3 | BC6: 4 | BD6: 5 | BE6: 6 | BF6: 7 | BG6: 8 | BH6: 9 | BI6: 10 | BJ6: 11
C7: IBP-90, wt% | D7: {='MEBU HPS DAILY'!$G$63:$G$70} -> 0 | E7: {='MEBU HPS DAILY'!$G$63:$G$70} -> 0 | F7: {='MEBU HPS DAILY'!$G$63:$G$70} -> 0 | G7: {='MEBU HPS DAILY'!$G$63:$G$70} -> 0 | H7: {='MEBU HPS DAILY'!$G$63:$G$70} -> 0 | I7: {='MEBU HPS DAILY'!$G$63:$G$70} -> 0 | J7: {='MEBU HPS DAILY'!$G$63:$G$70} -> 0 | K7: {='MEBU HPS DAILY'!$G$63:$G$70} -> 0 | ... N7: {='MEBU HPS DAILY'!$G$63:$G$70} -> 0 | P7: {='MEBU HPS DAILY'!L63:V70} -> 0 | Q7: 0.42 | R7: 0.38 | S7: 0.4 | T7: 0.067 | U7: 0 | V7: 0.41 | W7: 0.68 | X7: 0.79 | Y7: 0.63 | Z7: 1.068 | AB7: {='MEBU LTO DAILY'!H54:R61} -> 2.5 | AC7: 2.5 | AD7: 3.5 | AE7: 12 | AF7: 12 | AG7: 12 | AH7: 12.5 | AI7: 11.5 | AJ7: 12 | AK7: 12.5 | AL7: 12
C8: 90-160, wt% | D8: 0 | E8: 0 | F8: 0 | G8: 0 | H8: 0 | I8: 0 | J8: 0 | K8: 0 | L8: 0 | M8: 0 | N8: 0 | P8: 1.4 | Q8: 2.06 | R8: 1.91 | S8: 1.93 | T8: 1.721 | U8: 0.4 | V8: 2.01 | W8: 2.13 | X8: 1.97 | Y8: 2.15 | Z8: 1.803 | AB8: 17.5 | AC8: 18 | AD8: 18.5 | AE8: 23 | AF8: 23 | AG8: 23 | AH8: 22.5 | AI8: 22.5 | AJ8: 23 | AK8: 23 | AL8: 23
C9: 160-250, wt% | D9: 0 | E9: 0 | F9: 0 | G9: 0 | H9: 0 | I9: 0 | J9: 0 | K9: 0 | L9: 0 | M9: 0 | N9: 0 | P9: 7 | Q9: 7.37 | R9: 6.96 | S9: 6.87 | T9: 7.262 | U9: 6.5 | V9: 6.73 | W9: 7.22 | X9: 7.11 | Y9: 7.22 | Z9: 7.265 | AB9: 40 | AC9: 42.5 | AD9: 42 | AE9: 35 | AF9: 35.5 | AG9: 35.5 | AH9: 36 | AI9: 36 | AJ9: 36 | AK9: 35.5 | AL9: 36
C10: 250-360, wt% | D10: 0 | E10: 0 | F10: 0 | G10: 0 | H10: 0 | I10: 0 | J10: 0 | K10: 0 | L10: 0 | M10: 0 | N10: 0 | P10: 15.7 | Q10: 17.8 | R10: 16.87 | S10: 16.9 | T10: 16.489 | U10: 16.1 | V10: 15.94 | W10: 17.44 | X10: 17.21 | Y10: 17.65 | Z10: 16.48 | AB10: 30 | AC10: 30 | AD10: 29 | AE10: 24 | AF10: 24 | AG10: 24 | AH10: 23.5 | AI10: 24.5 | AJ10: 23.5 | AK10: 23.5 | AL10: 23.5
C11: 360-500, wt% | D11: 4.17 | E11: 4.17 | F11: 4.17 | G11: 4.17 | H11: 4.17 | I11: 4.17 | J11: 4.17 | K11: 4.17 | L11: 4.17 | M11: 4.17 | N11: 4.17 | P11: 25.8 | Q11: 30.78 | R11: 29.69 | S11: 29.89 | T11: 29.027 | U11: 29.2 | V11: 28.88 | W11: 30.36 | X11: 29.71 | Y11: 30.88 | Z11: 28.138 | AB11: 10 | AC11: 7 | AD11: 7 | AE11: 6 | AF11: 5.5 | AG11: 5.5 | AH11: 5.5 | AI11: 5.5 | AJ11: 5.5 | AK11: 5.5 | AL11: 5.5
C12: 500-560, wt% | D12: 9.88 | E12: 9.88 | F12: 9.88 | G12: 9.88 | H12: 9.88 | I12: 9.88 | J12: 9.88 | K12: 9.88 | L12: 9.88 | M12: 9.88 | N12: 9.88 | P12: 11.5 | Q12: 14.66 | R12: 13.97 | S12: 14.02 | T12: 13.299 | U12: 14 | V12: 13.74 | W12: 13.49 | X12: 13.31 | Y12: 13.7 | Z12: 12.109 | AB12: 0 | AC12: 0 | AD12: 0 | AE12: 0 | AF12: 0 | AG12: 0 | AH12: 0 | AI12: 0 | AJ12: 0 | AK12: 0 | AL12: 0
C13: 560 plus, wt% | D13: 85.95 | E13: 85.95 | F13: 85.95 | G13: 85.95 | H13: 85.95 | I13: 85.95 | J13: 85.95 | K13: 85.95 | L13: 85.95 | M13: 85.95 | N13: 85.95 | P13: 38.6 | Q13: 26.91 | R13: 30.22 | S13: 29.99 | T13: 32.135 | U13: 33.8 | V13: 32.29 | W13: 28.68 | X13: 29.9 | Y13: 27.77 | Z13: 33.137 | AB13: 0 | AC13: 0 | AD13: 0 | AE13: 0 | AF13: 0 | AG13: 0 | AH13: 0 | AI13: 0 | AJ13: 0 | AK13: 0 | AL13: 0
C14: Total | D14: 100 | E14: 100 | F14: 100 | G14: 100 | H14: 100 | I14: 100 | J14: 100 | K14: 100 | L14: 100 | M14: 100 | N14: 100 | P14: 100 | Q14: 100 | R14: 100 | S14: 100 | T14: 100 | U14: 100 | V14: 100 | W14: 100 | X14: 100 | Y14: 100 | Z14: 100 | AB14: 100 | AC14: 100 | AD14: 100 | AE14: 100 | AF14: 100 | AG14: 100 | AH14: 100 | AI14: 100 | AJ14: 100 | AK14: 100 | AL14: 100
C16: Ni, ppm | D16: {='MEBU HPS DAILY'!$G$40:$G$41} -> 73.4 | E16: {='MEBU HPS DAILY'!$G$40:$G$41} -> 73.4 | F16: {='MEBU HPS DAILY'!$G$40:$G$41} -> 73.4 | G16: {='MEBU HPS DAILY'!$G$40:$G$41} -> 73.4 | H16: {='MEBU HPS DAILY'!$G$40:$G$41} -> 73.4 | I16: {='MEBU HPS DAILY'!$G$40:$G$41} -> 73.4 | J16: {='MEBU HPS DAILY'!$G$40:$G$41} -> 73.4 | K16: {='MEBU HPS DAILY'!$G$40:$G$41} -> 73.4 | ... N16: {='MEBU HPS DAILY'!$G$40:$G$41} -> 73.4 | P16: {='MEBU HPS DAILY'!L40:V41} -> 4.56 | Q16: 4.83 | R16: 6.31 | S16: 6.74 | T16: 7.68 | U16: 8.52 | V16: 9.16 | W16: 8.95 | X16: 9.61 | Y16: 9.66 | Z16: 10.08 | AB16: 0 | AC16: 0 | AD16: 0 | AE16: 0 | AF16: 0 | AG16: 0 | AH16: 0 | AI16: 0 | AJ16: 0 | AK16: 0 | AL16: 0
C17: V, ppm | D17: 238.34 | E17: 238.34 | F17: 238.34 | G17: 238.34 | H17: 238.34 | I17: 238.34 | J17: 238.34 | K17: 238.34 | L17: 238.34 | M17: 238.34 | N17: 238.34 | P17: 2.66 | Q17: 0.91 | R17: 1.61 | S17: 1.76 | T17: 2.18 | U17: 2.52 | V17: 2.81 | W17: 2.53 | X17: 3.14 | Y17: 3.16 | Z17: 3.32 | AB17: 0 | AC17: 0 | AD17: 0 | AE17: 0 | AF17: 0 | AG17: 0 | AH17: 0 | AI17: 0 | AJ17: 0 | AK17: 0 | AL17: 0
C18: Fe, ppm | D18: ='MEBU HPS DAILY'!$G$44 -> 19.4 | E18: ='MEBU HPS DAILY'!$G$44 -> 19.4 | F18: ='MEBU HPS DAILY'!$G$44 -> 19.4 | G18: ='MEBU HPS DAILY'!$G$44 -> 19.4 | H18: ='MEBU HPS DAILY'!$G$44 -> 19.4 | I18: ='MEBU HPS DAILY'!$G$44 -> 19.4 | J18: ='MEBU HPS DAILY'!$G$44 -> 19.4 | K18: ='MEBU HPS DAILY'!$G$44 -> 19.4 | ... N18: ='MEBU HPS DAILY'!$G$44 -> 19.4 | P18: {='MEBU HPS DAILY'!L44:V44} -> 3.03 | Q18: 7.08 | R18: 2.19 | S18: 0.44 | T18: 0.87 | U18: 0.61 | V18: 0.45 | W18: 0.45 | X18: 0.54 | Y18: 1.43 | Z18: 0.32 | AB18: 0 | AC18: 0 | AD18: 0 | AE18: 0 | AF18: 0 | AG18: 0 | AH18: 0 | AI18: 0 | AJ18: 0 | AK18: 0 | AL18: 0
C20: N, wt% (ASTM D5762) | D20: ='MEBU HPS DAILY'!$G$23 -> 0.3301 | E20: ='MEBU HPS DAILY'!$G$23 -> 0.3301 | F20: ='MEBU HPS DAILY'!$G$23 -> 0.3301 | G20: ='MEBU HPS DAILY'!$G$23 -> 0.3301 | H20: ='MEBU HPS DAILY'!$G$23 -> 0.3301 | I20: ='MEBU HPS DAILY'!$G$23 -> 0.3301 | J20: ='MEBU HPS DAILY'!$G$23 -> 0.3301 | K20: ='MEBU HPS DAILY'!$G$23 -> 0.3301 | ... N20: ='MEBU HPS DAILY'!$G$23 -> 0.3301 | P20: {='MEBU HPS DAILY'!L23:V23} -> 0.1962 | Q20: 0.215878 | R20: 0.227188 | S20: 0.236633 | T20: 0.250962 | U20: 0.258309 | V20: 0.267549 | W20: 0.272297 | X20: 0.279689 | Y20: 0.276106 | Z20: 0.281071 | AB20: {='MEBU LTO DAILY'!H23:R23} -> 0.081 | AC20: 0.073492 | AD20: 0.078723 | AE20: 0.065492 | AF20: 0.068977 | AG20: 0.06836 | AH20: 0.07056 | AI20: 0.068092 | AJ20: 0.072433 | AK20: 0.054379 | AL20: 0.074608
C21: S, wt% (ASTM D4294) | D21: ='MEBU HPS DAILY'!$G$18 -> 5.986 | E21: ='MEBU HPS DAILY'!$G$18 -> 5.986 | F21: ='MEBU HPS DAILY'!$G$18 -> 5.986 | G21: ='MEBU HPS DAILY'!$G$18 -> 5.986 | H21: ='MEBU HPS DAILY'!$G$18 -> 5.986 | I21: ='MEBU HPS DAILY'!$G$18 -> 5.986 | J21: ='MEBU HPS DAILY'!$G$18 -> 5.986 | K21: ='MEBU HPS DAILY'!$G$18 -> 5.986 | ... N21: ='MEBU HPS DAILY'!$G$18 -> 5.986 | P21: {='MEBU HPS DAILY'!L18:V18} -> 0.832 | Q21: 0.975 | R21: 1.09 | S21: 1.155 | T21: 1.246 | U21: 1.306 | V21: 1.338 | W21: 1.28 | X21: 1.418 | Y21: 1.427 | Z21: 1.419 | AB21: {='MEBU LTO DAILY'!H18:R18} -> 0.181 | AC21: 0.1149 | AD21: 0.113 | AE21: 0.0934 | AF21: 0.259 | AG21: 0.2507 | AH21: 0.2867 | AI21: 0.2153 | AJ21: 0.234 | AK21: 0.2385 | AL21: 0.2482
C23: C5 Asphaltene, wt% | D23: ='MEBU HPS DAILY'!$G$83 -> 21.02 | E23: ='MEBU HPS DAILY'!$G$83 -> 21.02 | F23: ='MEBU HPS DAILY'!$G$83 -> 21.02 | G23: ='MEBU HPS DAILY'!$G$83 -> 21.02 | H23: ='MEBU HPS DAILY'!$G$83 -> 21.02 | I23: ='MEBU HPS DAILY'!$G$83 -> 21.02 | J23: ='MEBU HPS DAILY'!$G$83 -> 21.02 | K23: ='MEBU HPS DAILY'!$G$83 -> 21.02 | ... N23: ='MEBU HPS DAILY'!$G$83 -> 21.02 | P23: {='MEBU HPS DAILY'!L83:V84} -> 3.9 | Q23: 4.7 | R23: 5.3 | S23: 5.6 | T23: 5.6 | U23: 6.1 | V23: 6.4 | W23: 6.2 | X23: 6.9 | Y23: 6.5 | Z23: 6.9 | AB23: 0 | AC23: 0 | AD23: 0 | AE23: 0 | AF23: 0 | AG23: 0 | AH23: 0 | AI23: 0 | AJ23: 0 | AK23: 0 | AL23: 0
C24: C7 Asphaltene, wt% | D24: ='MEBU HPS DAILY'!$G$84 -> 12.86 | E24: ='MEBU HPS DAILY'!$G$84 -> 12.86 | F24: ='MEBU HPS DAILY'!$G$84 -> 12.86 | G24: ='MEBU HPS DAILY'!$G$84 -> 12.86 | H24: ='MEBU HPS DAILY'!$G$84 -> 12.86 | I24: ='MEBU HPS DAILY'!$G$84 -> 12.86 | J24: ='MEBU HPS DAILY'!$G$84 -> 12.86 | K24: ='MEBU HPS DAILY'!$G$84 -> 12.86 | ... N24: ='MEBU HPS DAILY'!$G$84 -> 12.86 | P24: 1.1 | Q24: 1.6 | R24: 1.5 | S24: 1.8 | T24: 2.1 | U24: 2.3 | V24: 2.7 | W24: 2.4 | X24: 2.6 | Y24: 2.4 | Z24: 2.5 | AB24: 0 | AC24: 0 | AD24: 0 | AE24: 0 | AF24: 0 | AG24: 0 | AH24: 0 | AI24: 0 | AJ24: 0 | AK24: 0 | AL24: 0
C26: MCRT, wt% | D26: ='MEBU HPS DAILY'!$G$85 -> 26.05 | E26: ='MEBU HPS DAILY'!$G$85 -> 26.05 | F26: ='MEBU HPS DAILY'!$G$85 -> 26.05 | G26: ='MEBU HPS DAILY'!$G$85 -> 26.05 | H26: ='MEBU HPS DAILY'!$G$85 -> 26.05 | I26: ='MEBU HPS DAILY'!$G$85 -> 26.05 | J26: ='MEBU HPS DAILY'!$G$85 -> 26.05 | K26: ='MEBU HPS DAILY'!$G$85 -> 26.05 | ... N26: ='MEBU HPS DAILY'!$G$85 -> 26.05 | P26: {='MEBU HPS DAILY'!L85:V85} -> 7.1075 | Q26: 7.51 | R26: 8.22745 | S26: 8.8036 | T26: 9.2672 | U26: 9.29115 | V26: 9.2228 | W26: 9.14 | X26: 9.618 | Y26: 9.3308 | Z26: 9.68 | AB26: 0 | AC26: 0 | AD26: 0 | AE26: 0 | AF26: 0 | AG26: 0 | AH26: 0 | AI26: 0 | AJ26: 0 | AK26: 0 | AL26: 0
C28: C, wt% (ASTM D5291) | D28: {='MEBU HPS DAILY'!$G$25:$G$27} -> 84.31 | E28: {='MEBU HPS DAILY'!$G$25:$G$27} -> 84.31 | F28: {='MEBU HPS DAILY'!$G$25:$G$27} -> 84.31 | G28: {='MEBU HPS DAILY'!$G$25:$G$27} -> 84.31 | H28: {='MEBU HPS DAILY'!$G$25:$G$27} -> 84.31 | I28: {='MEBU HPS DAILY'!$G$25:$G$27} -> 84.31 | J28: {='MEBU HPS DAILY'!$G$25:$G$27} -> 84.31 | K28: {='MEBU HPS DAILY'!$G$25:$G$27} -> 84.31 | ... N28: {='MEBU HPS DAILY'!$G$25:$G$27} -> 84.31 | P28: {='MEBU HPS DAILY'!L25:V27} -> 88.11 | Q28: 88.14 | R28: 87.88 | S28: 87.49 | T28: 87.66 | U28: 87.51 | V28: 87.78 | W28: 87.97 | X28: 88.01 | Y28: 87.81 | Z28: 86.8 | AB28: {='MEBU LTO DAILY'!H25:R27} -> 86.73 | AC28: 86.7 | AD28: 86.31 | AE28: 84.06 | AF28: 84.66 | AG28: 85.42 | AH28: 84.56 | AI28: 84.67 | AJ28: 84.65 | AK28: 85.81 | AL28: 84.46
C29: H, wt% (ASTM D5291) | D29: 9.782 | E29: 9.782 | F29: 9.782 | G29: 9.782 | H29: 9.782 | I29: 9.782 | J29: 9.782 | K29: 9.782 | L29: 9.782 | M29: 9.782 | N29: 9.782 | P29: 11.45 | Q29: 11.27 | R29: 11.41 | S29: 11.41 | T29: 11.2 | U29: 11.33 | V29: 11.32 | W29: 11.23 | X29: 11.26 | Y29: 11.39 | Z29: 10.94 | AB29: 13.23 | AC29: 13.17 | AD29: 13.46 | AE29: 13.55 | AF29: 13.56 | AG29: 13.52 | AH29: 13.55 | AI29: 13.35 | AJ29: 12.94 | AK29: 13.74 | AL29: 13.48
C30: N, wt% (ASTM D5291) | D30: 0.4519 | E30: 0.4519 | F30: 0.4519 | G30: 0.4519 | H30: 0.4519 | I30: 0.4519 | J30: 0.4519 | K30: 0.4519 | L30: 0.4519 | M30: 0.4519 | N30: 0.4519 | P30: 0.2675 | Q30: 0.3033 | R30: 0.2964 | S30: 0.3436 | T30: 0.3529 | U30: 0.3355 | V30: 0.325 | W30: 0.3319 | X30: 0.3282 | Y30: 0.3438 | Z30: 0.3161 | AB30: 0.08088 | AC30: 0.09388 | AD30: 0.07133 | AE30: 0.117 | AF30: 0.09208 | AG30: 0.10049 | AH30: 0.06362 | AI30: 0.06731 | AJ30: 0.04694 | AK30: 0.05397 | AL30: 0.08906
C31: S, wt% (ASTM D4294) | D31: =$D$21 -> 5.986 | E31: =$D$21 -> 5.986 | F31: =$D$21 -> 5.986 | G31: =$D$21 -> 5.986 | H31: =$D$21 -> 5.986 | I31: =$D$21 -> 5.986 | J31: =$D$21 -> 5.986 | K31: =$D$21 -> 5.986 | ... N31: =$D$21 -> 5.986 | P31: {=_xlfn.ANCHORARRAY(P21)} -> 0.832 | Q31: 0.975 | R31: 1.09 | S31: 1.155 | T31: 1.246 | U31: 1.306 | V31: 1.338 | W31: 1.28 | X31: 1.418 | Y31: 1.427 | Z31: 1.419 | AB31: =AB21 -> 0.181 | AC31: =AC21 -> 0.1149 | AD31: =AD21 -> 0.113 | AE31: =AE21 -> 0.0934 | AF31: =AF21 -> 0.259 | AG31: =AG21 -> 0.2507 | AH31: =AH21 -> 0.2867 | AI31: =AI21 -> 0.2153 | ... AK31: =AK21 -> 0.2385
C33: CN, wt% | D33: {='MEBU HPS DAILY'!$G$29:$G$30} -> 83.974158 | E33: {='MEBU HPS DAILY'!$G$29:$G$30} -> 83.974158 | F33: {='MEBU HPS DAILY'!$G$29:$G$30} -> 83.974158 | G33: {='MEBU HPS DAILY'!$G$29:$G$30} -> 83.974158 | H33: {='MEBU HPS DAILY'!$G$29:$G$30} -> 83.974158 | I33: {='MEBU HPS DAILY'!$G$29:$G$30} -> 83.974158 | J33: {='MEBU HPS DAILY'!$G$29:$G$30} -> 83.974158 | K33: {='MEBU HPS DAILY'!$G$29:$G$30} -> 83.974158 | ... N33: {='MEBU HPS DAILY'!$G$29:$G$30} -> 83.974158 | P33: {='MEBU HPS DAILY'!L29:V30} -> 87.595408 | Q33: 87.614461 | R33: 87.35042 | S33: 87.2369 | T33: 87.349542 | U33: 87.158674 | V33: 87.165813 | W33: 87.313954 | X33: 87.167215 | Y33: 87.025082 | Z33: 87.28929 | AB33: {='MEBU LTO DAILY'!H29:R30} -> 86.537886 | AC33: 86.649437 | AD33: 86.343037 | AE33: 85.978342 | AF33: 85.907462 | AG33: 86.057725 | AH33: 85.876238 | AI33: 86.131309 | AJ33: 86.468861 | AK33: 85.945037 | AL33: 85.953213
C34: HN, wt% | D34: 9.7430342 | E34: 9.7430342 | F34: 9.7430342 | G34: 9.7430342 | H34: 9.7430342 | I34: 9.7430342 | J34: 9.7430342 | K34: 9.7430342 | L34: 9.7430342 | M34: 9.7430342 | N34: 9.7430342 | P34: 11.383128 | Q34: 11.202802 | R34: 11.341241 | S34: 11.376992 | T34: 11.160334 | U34: 11.284513 | V34: 11.240795 | W34: 11.146251 | X34: 11.152174 | Y34: 11.288187 | Z34: 11.001669 | AB34: 13.200694 | AC34: 13.162319 | AD34: 13.465152 | AE34: 13.859226 | AF34: 13.759806 | AG34: 13.620937 | AH34: 13.760916 | AI34: 13.580406 | AJ34: 13.21804 | AK34: 13.761622 | AL34: 13.71832
C35: SN, wt | D35: ='MEBU HPS DAILY'!$G$32 -> 5.9544474 | E35: ='MEBU HPS DAILY'!$G$32 -> 5.9544474 | F35: ='MEBU HPS DAILY'!$G$32 -> 5.9544474 | G35: ='MEBU HPS DAILY'!$G$32 -> 5.9544474 | H35: ='MEBU HPS DAILY'!$G$32 -> 5.9544474 | I35: ='MEBU HPS DAILY'!$G$32 -> 5.9544474 | J35: ='MEBU HPS DAILY'!$G$32 -> 5.9544474 | K35: ='MEBU HPS DAILY'!$G$32 -> 5.9544474 | ... N35: ='MEBU HPS DAILY'!$G$32 -> 5.9544474 | P35: {='MEBU HPS DAILY'!L32:V32} -> 0.82654891 | Q35: 0.96833495 | R35: 1.0826768 | S35: 1.1504144 | T35: 1.2403082 | U35: 1.2997417 | V35: 1.3278684 | W35: 1.2696914 | X35: 1.4037352 | Y35: 1.4132799 | Z35: 1.4264876 | AB35: {='MEBU LTO DAILY'!H32:R32} -> 0.18059929 | AC35: 0.11480955 | AD35: 0.11305163 | AE35: 0.095481106 | AF35: 0.26275455 | AG35: 0.25248967 | AH35: 0.29118329 | AI35: 0.21901758 | AJ35: 0.23909038 | AK35: 0.2388763 | AL35: 0.25255079
AN36: %wt | AZ36: %vol
C37: H2, wt% | D37: 0 | E37: 0 | F37: 0 | G37: 0 | H37: 0 | I37: 0 | J37: 0 | K37: 0 | L37: 0 | M37: 0 | N37: 0 | P37: 0 | Q37: 0 | R37: 0 | S37: 0 | T37: 0 | U37: 0 | V37: 0 | W37: 0 | X37: 0 | Y37: 0 | Z37: 0 | AB37: 0 | AC37: 0 | AD37: 0 | AE37: 0 | AF37: 0 | AG37: 0 | AH37: 0 | AI37: 0 | AJ37: 0 | AK37: 0 | AL37: 0 | AN37: {='MEBU HPS DAILY'!L101:L107} -> 27.4 | AO37: {='MEBU HPS DAILY'!M101:M107} -> 40.4 | AP37: {='MEBU HPS DAILY'!N101:N107} -> 42.7 | AQ37: {='MEBU HPS DAILY'!O101:O107} -> 41 | AR37: {='MEBU HPS DAILY'!P101:P107} -> 44.9 | AS37: {='MEBU HPS DAILY'!Q101:Q107} -> 42.6 | AT37: {='MEBU HPS DAILY'!R101:R107} -> 42.6 | AU37: {='MEBU HPS DAILY'!S101:S107} -> 41 | ... AX37: {='MEBU HPS DAILY'!V101:V107} -> 41.8 | AZ37: {='MEBU HPS DAILY'!L89:L95} -> 3.5 | BA37: {='MEBU HPS DAILY'!M89:M95} -> 13 | BB37: {='MEBU HPS DAILY'!N89:N95} -> 27.5 | BC37: {='MEBU HPS DAILY'!O89:O95} -> 37.6 | BD37: {='MEBU HPS DAILY'!P89:P95} -> 31.2 | BE37: {='MEBU HPS DAILY'!Q89:Q95} -> 19.2 | BF37: {='MEBU HPS DAILY'!R89:R95} -> 19.2 | BG37: {='MEBU HPS DAILY'!S89:S95} -> 14.2 | ... BJ37: {='MEBU HPS DAILY'!V89:V95} -> 6.2 | BL37: H2, wt%
C38: CH4, wt% | D38: 0 | E38: 0 | F38: 0 | G38: 0 | H38: 0 | I38: 0 | J38: 0 | K38: 0 | L38: 0 | M38: 0 | N38: 0 | P38: 0 | Q38: 0 | R38: 0 | S38: 0 | T38: 0 | U38: 0 | V38: 0 | W38: 0 | X38: 0 | Y38: 0 | Z38: 0 | AB38: 0 | AC38: 0 | AD38: 0 | AE38: 0 | AF38: 0 | AG38: 0 | AH38: 0 | AI38: 0 | AJ38: 0 | AK38: 0 | AL38: 0 | AN38: 10.3 | AO38: 14.2 | AP38: 14.3 | AQ38: 13.3 | AR38: 14 | AS38: 13.2 | AT38: 13.2 | AU38: 14.3 | AV38: 14.3 | AW38: 15.3 | AX38: 14.6 | AZ38: 0.3 | BA38: 0.2 | BB38: 1.2 | BC38: 1.6 | BD38: 1.9 | BE38: 1.5 | BF38: 1.5 | BG38: 1.4 | BH38: 1 | BI38: 0.9 | BJ38: 0.8 | BL38: CH4, wt%
C39: C2H6, wt% | D39: 0 | E39: 0 | F39: 0 | G39: 0 | H39: 0 | I39: 0 | J39: 0 | K39: 0 | L39: 0 | M39: 0 | N39: 0 | P39: 0 | Q39: 0 | R39: 0 | S39: 0 | T39: 0 | U39: 0 | V39: 0 | W39: 0 | X39: 0 | Y39: 0 | Z39: 0 | AB39: 0 | AC39: 0 | AD39: 0 | AE39: 0 | AF39: 0 | AG39: 0 | AH39: 0 | AI39: 0 | AJ39: 0 | AK39: 0 | AL39: 0 | AN39: 8.3 | AO39: 11.3 | AP39: 11 | AQ39: 10.5 | AR39: 11.4 | AS39: 10.6 | AT39: 10.6 | AU39: 11.3 | AV39: 11.3 | AW39: 12 | AX39: 11.4 | AZ39: 0 | BA39: 0.1 | BB39: 0.4 | BC39: 0.8 | BD39: 1.1 | BE39: 1.3 | BF39: 1.3 | BG39: 1.6 | BH39: 1.3 | BI39: 1.3 | BJ39: 1.3 | BL39: C2H6, wt%
C40: C3H8, wt% | D40: 0 | E40: 0 | F40: 0 | G40: 0 | H40: 0 | I40: 0 | J40: 0 | K40: 0 | L40: 0 | M40: 0 | N40: 0 | P40: 0 | Q40: 0 | R40: 0 | S40: 0 | T40: 0 | U40: 0 | V40: 0 | W40: 0 | X40: 0 | Y40: 0 | Z40: 0 | AB40: 0 | AC40: 0 | AD40: 0 | AE40: 0 | AF40: 0 | AG40: 0 | AH40: 0 | AI40: 0 | AJ40: 0 | AK40: 0 | AL40: 0 | AN40: 14.3 | AO40: 15.4 | AP40: 14.2 | AQ40: 14.7 | AR40: 15.3 | AS40: 15.8 | AT40: 15.8 | AU40: 15 | AV40: 14 | AW40: 13.6 | AX40: 14.1 | AZ40: 0.8 | BA40: 0.3 | BB40: 2.6 | BC40: 0.8 | BD40: 1.3 | BE40: 2 | BF40: 2 | BG40: 1.7 | BH40: 2.3 | BI40: 2.3 | BJ40: 2.3 | BL40: C3H8, wt%
C41: C4H10, wt% | D41: 0 | E41: 0 | F41: 0 | G41: 0 | H41: 0 | I41: 0 | J41: 0 | K41: 0 | L41: 0 | M41: 0 | N41: 0 | P41: 0 | Q41: 0 | R41: 0 | S41: 0 | T41: 0 | U41: 0 | V41: 0 | W41: 0 | X41: 0 | Y41: 0 | Z41: 0 | AB41: 0 | AC41: 0 | AD41: 0 | AE41: 0 | AF41: 0 | AG41: 0 | AH41: 0 | AI41: 0 | AJ41: 0 | AK41: 0 | AL41: 0 | AN41: 8.8 | AO41: 5.1 | AP41: 4.6 | AQ41: 5.5 | AR41: 4.8 | AS41: 5.7 | AT41: 5.7 | AU41: 5.1 | AV41: 4.9 | AW41: 4.2 | AX41: 4.9 | AZ41: 1.6 | BA41: 0.4 | BB41: 2.3 | BC41: 0.3 | BD41: 0.4 | BE41: 0.8 | BF41: 0.8 | BG41: 0.5 | BH41: 1 | BI41: 1 | BJ41: 1 | BL41: C4H10, wt%
C42: C5H12, wt% | D42: 0 | E42: 0 | F42: 0 | G42: 0 | H42: 0 | I42: 0 | J42: 0 | K42: 0 | L42: 0 | M42: 0 | N42: 0 | P42: 0 | Q42: 0 | R42: 0 | S42: 0 | T42: 0 | U42: 0 | V42: 0 | W42: 0 | X42: 0 | Y42: 0 | Z42: 0 | AB42: 0 | AC42: 0 | AD42: 0 | AE42: 0 | AF42: 0 | AG42: 0 | AH42: 0 | AI42: 0 | AJ42: 0 | AK42: 0 | AL42: 0 | AN42: 10.6 | AO42: 6.9 | AP42: 8 | AQ42: 9.2 | AR42: 6.3 | AS42: 8.9 | AT42: 8.9 | AU42: 8.4 | AV42: 7.2 | AW42: 7.1 | AX42: 8.7 | AZ42: 0 | BA42: 0.4 | BB42: 1.3 | BC42: 0.5 | BD42: 0.7 | BE42: 1.1 | BF42: 1.1 | BG42: 0.3 | BH42: 0.6 | BI42: 1.4 | BJ42: 1.5 | BL42: C5H12, wt%
C43: C6H14 plus, wt% | D43: 0 | E43: 0 | F43: 0 | G43: 0 | H43: 0 | I43: 0 | J43: 0 | K43: 0 | L43: 0 | M43: 0 | N43: 0 | P43: 0 | Q43: 0 | R43: 0 | S43: 0 | T43: 0 | U43: 0 | V43: 0 | W43: 0 | X43: 0 | Y43: 0 | Z43: 0 | AB43: 0 | AC43: 0 | AD43: 0 | AE43: 0 | AF43: 0 | AG43: 0 | AH43: 0 | AI43: 0 | AJ43: 0 | AK43: 0 | AL43: 0 | AN43: 11.3 | AO43: 4.3 | AP43: 4.6 | AQ43: 5 | AR43: 2.3 | AS43: 2.7 | AT43: 2.7 | AU43: 4.6 | AV43: 3.5 | AW43: 3.8 | AX43: 4.2 | AZ43: 0.9 | BA43: 0.8 | BB43: 2.7 | BC43: 0.9 | BD43: 0.5 | BE43: 0.4 | BF43: 0.4 | BG43: 0.3 | BH43: 0.4 | BI43: 0.3 | BJ43: 0.4 | BL43: C6H14 plus, wt%
C45: Flow | D45: VR | P45: HPS | AB45: LTO | AN45: High gas | AZ45: Low gas
C46: Accumulation, g | E46: 2330 | F46: 4321 | G46: 4368 | H46: 4335 | I46: 4321 | J46: 4312 | K46: 1949 | L46: 0 | M46: 0 | Q46: 1593 | R46: 3328 | S46: 3320 | T46: 3330 | U46: 3322 | V46: 3324 | W46: 1544 | X46: 0 | Y46: 0 | AC46: 218 | AD46: 250 | AE46: 519 | AF46: 506 | AG46: 494 | AH46: 512 | AI46: 218 | AO46: 105.09 | AP46: 212.87 | AQ46: 351.93 | AR46: 356.9 | AS46: 356.2 | AT46: 359.3 | AU46: =164.1 -> 164.1 | AV46: 0 | AW46: 0 | AY46: Litre | BA46: 661.22 | BB46: 864.7 | BC46: 67.3 | BD46: =60.1 -> 60.1 | BE46: 56.4 | BF46: 56.2 | BG46: =27.9 -> 27.9 | BH46: 0 | BI46: 0
C47: rate, g/h | D47: =D46/12 -> 0 | E47: =E46/12 -> 194.16667 | F47: =F46/23 -> 187.86957 | G47: =G46/23.5 -> 185.87234 | H47: =H$46/23.5 -> 184.46809 | I47: =I$46/23.5 -> 183.87234 | J47: =J$46/23.5 -> 183.48936 | K47: =K$46/10.5 -> 185.61905 | L47: =L$46/23.5 -> 0 | M47: =M$46/23.5 -> 0 | N47: =N$46/23.5 -> 0 | P47: =P46/12 -> 0 | Q47: =Q46/12 -> 132.75 | R47: =R46/23 -> 144.69565 | S47: =S46/23.5 -> 141.2766 | T47: =T46/23.5 -> 141.70213 | U47: =U46/23.5 -> 141.3617 | V47: =V46/23.5 -> 141.44681 | W47: =W46/10.5 -> 147.04762 | X47: =X46/23.5 -> 0 | Y47: =Y46/23.5 -> 0 | Z47: =Z46/23.5 -> 0 | AB47: =AB46/23 -> 0 | AC47: =AD46/23 -> 10.869565 | AD47: =AE46/23.5 -> 22.085106 | AE47: =AE46/23.5 -> 22.085106 | AF47: =AF46/23.5 -> 21.531915 | AG47: =AG46/23.5 -> 21.021277 | AH47: =AH46/23.5 -> 21.787234 | AI47: =AI46/10.5 -> 20.761905 | AJ47: =AJ46/23.5 -> 0 | AK47: =AK46/23.5 -> 0 | AL47: =AL46/23.5 -> 0 | AN47: =AN46/12 -> 0 | AO47: =AO46/12 -> 8.7575 | AP47: =AP46/23 -> 9.2552174 | AQ47: =AQ46/23.5 -> 14.975745 | AR47: =AR46/23.5 -> 15.187234 | AS47: =AS46/23.5 -> 15.157447 | AT47: =AT46/23.5 -> 15.289362 | AU47: =AU46/10.5 -> 15.628571 | AV47: =AV46/23.5 -> 0 | AW47: =AW46/23.5 -> 0 | AX47: =AX46/23.5 -> 0 | AY47: L/hr | AZ47: =AZ46/12 -> 0 | BA47: =BA46/12 -> 55.101667 | BB47: =BB46/23 -> 37.595652 | BC47: =BC46/23.5 -> 2.8638298 | BD47: =BD46/23.5 -> 2.5574468 | BE47: =BE46/23.5 -> 2.4 | BF47: =BF46/23.5 -> 2.3914894 | BG47: =BG46/10.5 -> 2.6571429 | BH47: =BH46/23.5 -> 0 | BI47: =BI46/23.5 -> 0 | BJ47: =BJ46/23.5 -> 0
C49: IBP-90, g/h | D49: =D7*D$47/100 -> 0 | E49: =E7*E$47/100 -> 0 | F49: =F7*F$47/100 -> 0 | G49: =G7*G$47/100 -> 0 | H49: =H7*H$47/100 -> 0 | I49: =I7*I$47/100 -> 0 | J49: =J7*J$47/100 -> 0 | K49: =K7*K$47/100 -> 0 | ... N49: =N7*N$47/100 -> 0 | P49: =P$47*P7/100 -> 0 | Q49: =Q$47*Q7/100 -> 0.55755 | R49: =R$47*R7/100 -> 0.54984348 | S49: =S$47*S7/100 -> 0.56510638 | T49: =T$47*T7/100 -> 0.094940426 | U49: =U$47*U7/100 -> 0 | V49: =V$47*V7/100 -> 0.57993191 | W49: =W$47*W7/100 -> 0.99992381 | ... Z49: =Z$47*Z7/100 -> 0 | AB49: =AB$47*AB7/100 -> 0 | AC49: =AC$47*AC7/100 -> 0.27173913 | AD49: =AD$47*AD7/100 -> 0.77297872 | AE49: =AE$47*AE7/100 -> 2.6502128 | AF49: =AF$47*AF7/100 -> 2.5838298 | AG49: =AG$47*AG7/100 -> 2.5225532 | AH49: =AH$47*AH7/100 -> 2.7234043 | AI49: =AI$47*AI7/100 -> 2.387619 | ... AL49: =AL$47*AL7/100 -> 0
...

Sheet CrkConv

Sheet Yield

Sheet MetConv(Ni+V)

Sheet McrConv

Sheet Overall Yield

Sheet SedM

Sheet Prediction
D2: Experiment (MEBU Experiment) | G2: Case | N2: Case | O2: 1 | P2: 2 | Q2: 3
N3: %CrkConv
C4: Commercial RHCU LHSV, hr-1 | D4: 0.23 | G4: N | H4: LHSV | I4: {[100/(100-X)]^1/N} -1 | J4: e^[Ea/(RT)] | K4: = | L4: k0 | N4: Temp, degC
C5: MEBU Correction factor | D5: 1.46 | G5: =D11 -> 3 | H5: =D6 -> 0.3358 | I5: =(100/(100-G8))^(1/G5)-1 -> 0.51567186 | J5: =EXP($D$22/($D$23*H8)) -> 1.0974018e+14 | L5: =G5*H5*I5*J5 -> 5.7008689e+13
C6: MEB LHSV, hr-1 | D6: =D$4*D$5 -> 0.3358 | L6: =D26 -> 6.8639257e+13
C7: MEBU Reactor Volume, mL | D7: 186 | G7: X, %CrkConv | H7: T, K | I7: T, degC
C8: Rx1 Avg. Temp, degC | D8: 423.54 | G8: 71.28 | H8: =I8+273.15+4 -> 700.52 | I8: =D20 -> 423.37
C9: Rx2 Avg. Temp, degC | D9: 423.2
C10: Rx3 Avg. Temp, degC | D10: 423.37
C11: No. of Rx, N | D11: 3
C12: X, %CrkConv | D12: 71.28
C13: Krxn | D13: =((100/(100-D$12))^(1/D$11)-1)*D$6*D$11 -> 0.51948783
C14: k0 | D14: =D$13*EXP(D$22/(D$23*D$21)) -> 6.8639257e+13
C16: 100/(100-%CrkConv) | D16: =100/(100-D$12) -> 3.4818942
C17: 100/(100-%CrkConv)^1/N | D17: =D$16^(1/D$11) -> 1.5156719
C18: 100/(100-%CrkConv)^1/N-1 | D18: =D$17-1 -> 0.51567186
C19: Krxn | D19: =D$11*D$6*D$18 -> 0.51948783
C20: Avg. Temp, degC | D20: =AVERAGE(D8:D10) -> 423.37
C21: Temp, K | D21: =D$20+273.15 -> 696.52
C22: Ea, cal.mol-1 | D22: 45000
C23: R, cal.mol-1.K-1 | D23: 1.987
C24: Ea/(RT) | D24: =D$22/(D$23*D$21) -> 32.514798
C25: e^(Ea/RT) | D25: =EXP(D$24) -> 1.3212871e+14
C26: k0 | D26: =D$25*D$19 -> 6.8639257e+13

Sheet MEBU HPS DAILY
D1: RHCU Pilot Plant Laboratory Worksheet
D2: Batch Name : | E2: SR ABQ3358 ACCEPTANCE TEST
D3: Date : | E3: 14-25/12/2024 | L3: NOTE : ALL OF HT SIMDIST RESULTS ARE FROM GC-HT SIMDIST AT MAINLAB
D4: Note : | E4: MEBU ACCEPTANCE TEST | H4: CATALYST AGING | L4: CRACKING EXPERIMENT
H5: IN 11:50 AM OUT 17:30 AM | I5: IN 09:00 AM OUT 17:00 AM | J5: IN 08.08 OUT 18.00 | K5: IN OUT 07.15 | L5: DAY1 | M5: DAY2 | N5: DAY3 | O5: DAY4 | P5: DAY5 | Q5: DAY6 | R5: DAY7 | S5: DAY8 | T5: DAY9 | U5: DAY10 | V5: DAY11
H6: 14/12/24 | I6: 15/12/24 | J6: 16/12/24 | K6: 17/12/24 | L6: 18/12/24 | M6: 19/12/24 | N6: 20/12/24 | O6: 21/12/24 | P6: 22/12/24 | Q6: 23/12/24 | R6: 24/12/24 | S6: 25/12/24 | T6: 26/12/24 | U6: 27/12/24 | V6: 28/12/24
D7: Properties | E7: Method | F7: Unit | G7: SR ABQ3358 | H7: HPS | I7: HPS | J7: HPS | K7: HPS | L7: HPS | M7: HPS | N7: HPS | O7: HPS | P7: HPS | Q7: HPS | R7: HPS | S7: HPS | T7: HPS | U7: HPS | V7: HPS
D8: Ratio | E8: - | F8: %wt. | G8: 100
D9: Weight | E9: - | F9: kg
D10: Density | E10: ASTM D4052 | F10: kg/L | H10: 0.9801 | I10: 0.9827 | J10: 0.9847 | K10: 0.9851 | L10: 0.9423 | M10: 0.9446 | N10: 0.9491 | O10: 0.9511 | P10: 0.9537 | Q10: 0.9546 | R10: 0.9529 | S10: 0.954 | T10: 0.9536 | U10: 0.9549 | V10: 0.9555
D11: Relative Density@25/25 oC | E11: ASTM D70 | F11: - | G11: 1.08
D12: Viscosity @ -20 oC | E12: ASTM D445 | F12: cSt.
D13: Viscosity @ 40 oC
D14: Viscosity @ 70 oC
D15: Viscosity @ 100 oC
D16: Viscosity @ 150 oC
D17: V50
D18: Sulfur | E18: ASTM D4294 | F18: %wt | G18: 5.986 | H18: 2.03 | I18: 2.109 | J18: 2.188 | K18: 2.22 | L18: 0.832 | M18: 0.975 | N18: 1.09 | O18: 1.155 | P18: 1.246 | Q18: 1.306 | R18: 1.338 | S18: 1.28 | T18: 1.418 | U18: 1.427 | V18: 1.419
E19: ASTM D2622 | F19: %wt
F20: PPMw
D21: Total Nitrogen | E21: ASTM D4629 | F21: PPMw
E22: ASTM D5762 | F22: PPMw | G22: 3301 | H22: 2654.7 | I22: 2696.13 | J22: 2750.42 | K22: 2720.18 | L22: 1961.59 | M22: 2158.78 | N22: 2271.88 | O22: 2366.33 | P22: 2509.62 | Q22: 2583.09 | R22: 2675.49 | S22: 2722.97 | T22: 2796.89 | U22: 2761.06 | V22: 2810.71
B23: 0.4519 | F23: %wt | G23: 0.3301 | H23: =H22/10000 -> 0.26547 | I23: =I22/10000 -> 0.269613 | J23: =J22/10000 -> 0.275042 | K23: =K22/10000 -> 0.272018 | L23: 0.1962 | M23: =M22/10000 -> 0.215878 | N23: =N22/10000 -> 0.227188 | O23: =O22/10000 -> 0.236633 | P23: =P22/10000 -> 0.250962 | Q23: =Q22/10000 -> 0.258309 | R23: =R22/10000 -> 0.267549 | S23: =S22/10000 -> 0.272297 | T23: =T22/10000 -> 0.279689 | ... V23: =V22/10000 -> 0.281071
D24: CHN | E24: ASTM D5291 | F24: %wt
D25: Carbon | G25: 84.31 | H25: 87.03 | I25: 87.13 | J25: 87.21 | K25: 87.15 | L25: 88.11 | M25: 88.14 | N25: 87.88 | O25: 87.49 | P25: 87.66 | Q25: 87.51 | R25: 87.78 | S25: 87.97 | T25: 88.01 | U25: 87.81 | V25: 86.8
D26: Hydrogen | G26: 9.782 | H26: 10.89 | I26: 10.87 | J26: 10.92 | K26: 10.88 | L26: 11.45 | M26: 11.27 | N26: 11.41 | O26: 11.41 | P26: 11.2 | Q26: 11.33 | R26: 11.32 | S26: 11.23 | T26: 11.26 | U26: 11.39 | V26: 10.94
D27: Nitrogen | G27: 0.4519 | H27: 0.35 | I27: 0.37 | J27: 0.3648 | K27: 0.3653 | L27: 0.2675 | M27: 0.3033 | N27: 0.2964 | O27: 0.3436 | P27: 0.3529 | Q27: 0.3355 | R27: 0.325 | S27: 0.3319 | T27: 0.3282 | U27: 0.3438 | V27: 0.3161
D28: CHNS | G28: =(G25+G26+G27+G18) -> 100.5299 | H28: =(H25+H26+H27+H18) -> 100.3 | I28: =(I25+I26+I27+I18) -> 100.479 | J28: =(J25+J26+J27+J18) -> 100.6828 | K28: =(K25+K26+K27+K18) -> 100.6153 | L28: =(L25+L26+L27+L18) -> 100.6595 | M28: =(M25+M26+M27+M18) -> 100.6883 | N28: =(N25+N26+N27+N18) -> 100.6764 | ... V28: =(V25+V26+V27+V18) -> 99.4751
D29: CN | G29: =(100-G31-G32)/(1+(G26/G25)) -> 83.974158 | H29: =(100-H31-H32)/(1+(H26/H25)) -> 86.844595 | I29: =(100-I31-I32)/(1+(I26/I25)) -> 86.803464 | J29: =(100-J31-J32)/(1+(J26/J25)) -> 86.697797 | K29: =(100-K31-K32)/(1+(K26/K25)) -> 86.699467 | L29: =(100-L31-L32)/(1+(L26/L25)) -> 87.595408 | M29: =(100-M31-M32)/(1+(M26/M25)) -> 87.614461 | N29: =(100-N31-N32)/(1+(N26/N25)) -> 87.35042 | ... V29: =(100-V31-V32)/(1+(V26/V25)) -> 87.28929
D30: HN | F30: %wt | G30: =G29*(G26/G25) -> 9.7430342 | H30: =H29*(H26/H25) -> 10.8668 | I30: =I29*(I26/I25) -> 10.829263 | J30: =J29*(J26/J25) -> 10.855865 | K30: =K29*(K26/K25) -> 10.823754 | L30: =L29*(L26/L25) -> 11.383128 | M30: =M29*(M26/M25) -> 11.202802 | N30: =N29*(N26/N25) -> 11.341241 | ... V30: =V29*(V26/V25) -> 11.001669
D31: NN | G31: =G23*100/G28 -> 0.32836002 | H31: =H23*100/H28 -> 0.26467597 | I31: =I23*100/I28 -> 0.26832771 | J31: =J23*100/J28 -> 0.27317675 | K31: =K23*100/K28 -> 0.27035451 | L31: =L23*100/L28 -> 0.19491454 | M31: =M23*100/M28 -> 0.21440227 | N31: =N23*100/N28 -> 0.22566162 | ... V31: =V23*100/V28 -> 0.28255413
D32: SN | G32: =G18*100/G28 -> 5.9544474 | H32: =H18*100/H28 -> 2.0239282 | I32: =I18*100/I28 -> 2.098946 | J32: =J18*100/J28 -> 2.1731617 | K32: =K18*100/K28 -> 2.2064239 | L32: =L18*100/L28 -> 0.82654891 | M32: =M18*100/M28 -> 0.96833495 | N32: =N18*100/N28 -> 1.0826768 | ... V32: =V18*100/V28 -> 1.4264876
D33: HN/CN | G33: =G30/G29 -> 0.1160242 | H33: =H30/H29 -> 0.12512927 | I33: =I30/I29 -> 0.12475611 | J33: =J30/J29 -> 0.125215 | K33: =K30/K29 -> 0.12484223 | L33: =L30/L29 -> 0.1299512 | M33: =M30/M29 -> 0.12786476 | N33: =N30/N29 -> 0.12983614 | ... V33: =V30/V29 -> 0.12603687
D34: C | G34: =G25*100/G28 -> 83.865596 | H34: =H25*100/H28 -> 86.769691 | I34: =I25*100/I28 -> 86.714637 | J34: =J25*100/J28 -> 86.618568 | K34: =K25*100/K28 -> 86.617045 | L34: =L25*100/L28 -> 87.532722 | M34: =M25*100/M28 -> 87.53748 | N34: =N25*100/N28 -> 87.289573 | ... P34: =P25*100/P28 -> 87.259566 | Q34: #DIV/0! | R34: #DIV/0! | S34: #DIV/0! | T34: #DIV/0! | U34: #DIV/0! | V34: #DIV/0!
D35: H | G35: =G26*100/G28 -> 9.7304384 | H35: =H26*100/H28 -> 10.857428 | I35: =I26*100/I28 -> 10.818181 | J35: =J26*100/J28 -> 10.845944 | K35: =K26*100/K28 -> 10.813465 | L35: =L26*100/L28 -> 11.374982 | M35: =M26*100/M28 -> 11.192959 | N35: =N26*100/N28 -> 11.333341 | ... P35: =P26*100/P28 -> 11.148838 | Q35: #DIV/0! | R35: #DIV/0! | S35: #DIV/0! | T35: #DIV/0! | U35: #DIV/0! | V35: #DIV/0!
D36: N | G36: =G27*100/G28 -> 0.449518 | H36: =H27*100/H28 -> 0.34895314 | I36: =I27*100/I28 -> 0.36823615 | J36: =J27*100/J28 -> 0.36232604 | K36: =K27*100/K28 -> 0.36306605 | L36: =L27*100/L28 -> 0.2657474 | M36: =M27*100/M28 -> 0.30122666 | N36: =N27*100/N28 -> 0.29440862 | ... P36: =P27*100/P28 -> 0.35128794 | Q36: #DIV/0! | R36: #DIV/0! | S36: #DIV/0! | T36: #DIV/0! | U36: #DIV/0! | V36: #DIV/0!
D37: S | G37: =G18*100/G28 -> 5.9544474 | H37: =H18*100/H28 -> 2.0239282 | I37: =I18*100/I28 -> 2.098946 | J37: =J18*100/J28 -> 2.1731617 | K37: =K18*100/K28 -> 2.2064239 | L37: =L18*100/L28 -> 0.82654891 | M37: =M18*100/M28 -> 0.96833495 | N37: =N18*100/N28 -> 1.0826768 | ... P37: =P18*100/P28 -> 1.2403082 | Q37: #DIV/0! | R37: #DIV/0! | S37: #DIV/0! | T37: #DIV/0! | U37: #DIV/0! | V37: #DIV/0!
D38: H/C | G38: =G35/G34 -> 0.1160242 | H38: =H35/H34 -> 0.12512927 | I38: =I35/I34 -> 0.12475611 | J38: =J35/J34 -> 0.125215 | K38: =K35/K34 -> 0.12484223 | L38: =L35/L34 -> 0.1299512 | M38: =M35/M34 -> 0.12786476 | N38: =N35/N34 -> 0.12983614 | ... P38: =P35/P34 -> 0.12776637 | Q38: #DIV/0! | R38: #DIV/0! | S38: #DIV/0! | T38: #DIV/0! | U38: #DIV/0! | V38: #DIV/0!
D39: ICP | E39: ASTM D7691 UOP 389 | F39: PPMw
D40: Nickle (Ni) | G40: 73.4 | H40: 19.41 | I40: 21.28 | J40: 21.3 | K40: 21.36 | L40: 4.56 | M40: 4.83 | N40: 6.31 | O40: 6.74 | P40: 7.68 | Q40: 8.52 | R40: 9.16 | S40: 8.95 | T40: 9.61 | U40: 9.66 | V40: 10.08
...

Sheet MEBU LTO DAILY
D1: RHCU Pilot Plant Laboratory Worksheet
D2: Batch Name : | E2: SR ABQ3358 ACCEPTANCE TEST
D3: Date : | E3: 14-25/12/2024
D4: Note : | E4: MEBU ACCEPTANCE TEST | H4: CRACKING EXPERIMENT
H5: DAY1 (Aging Day4) | I5: DAY2 | J5: DAY3 | K5: DAY4 | L5: DAY5 | M5: DAY6 | N5: DAY7 | O5: DAY8 | P5: DAY9 | Q5: DAY10 | R5: DAY11
H6: 16-17/12/24 | I6: 19/12/24 | J6: 20/12/24 | K6: 21/12/24 | L6: 22/12/24 | M6: 23/12/24 | N6: 24/12/24 | O6: 25/12/24 | P6: 26/12/24 | Q6: 27/12/24 | R6: 28/12/24
D7: Properties | E7: Method | F7: Unit | G7: SR ABQ3358 | H7: LTO | I7: LTO | J7: LTO | K7: LTO | L7: LTO | M7: LTO | N7: LTO | O7: LTO | P7: LTO | Q7: LTO | R7: LTO
D8: Ratio | E8: - | F8: %wt. | G8: 100
D9: Weight | E9: - | F9: kg
D10: Density | E10: ASTM D4052 | F10: kg/L | H10: 0.8194 | I10: 0.8168 | J10: 0.8144 | K10: 0.7945 | L10: 0.7903 | M10: 0.7889 | N10: 0.7883 | O10: 0.7912 | P10: 0.7887 | Q10: 0.7879 | R10: 0.788
D11: Relative Density@25/25 oC | E11: ASTM D70 | F11: - | G11: 1.08
D12: Viscosity @ -20 oC | E12: ASTM D445 | F12: cSt.
D13: Viscosity @ 40 oC
D14: Viscosity @ 70 oC
D15: Viscosity @ 100 oC
D16: Viscosity @ 150 oC
D17: V50
D18: Sulfur | E18: ASTM D4294 | F18: %wt | G18: 5.986 | H18: 0.181 | I18: 0.1149 | J18: 0.113 | K18: 0.0934 | L18: 0.259 | M18: 0.2507 | N18: 0.2867 | O18: 0.2153 | P18: 0.234 | Q18: 0.2385 | R18: 0.2482
E19: ASTM D2622 | F19: %wt
F20: PPMw
D21: Total Nitrogen | E21: ASTM D4629 | F21: PPMw
E22: ASTM D5762 | F22: PPMw | G22: 3301 | H22: 810.33 | I22: 734.92 | J22: 787.23 | K22: 654.92 | L22: 689.77 | M22: 683.6 | N22: 705.6 | O22: 680.92 | P22: 724.33 | Q22: 543.79 | R22: 746.08
B23: 0.4519 | F23: %wt | G23: 0.3301 | H23: 0.081 | I23: =I22/10000 -> 0.073492 | J23: =J22/10000 -> 0.078723 | K23: =K22/10000 -> 0.065492 | L23: =L22/10000 -> 0.068977 | M23: =M22/10000 -> 0.06836 | N23: =N22/10000 -> 0.07056 | O23: =O22/10000 -> 0.068092 | P23: =P22/10000 -> 0.072433 | ... R23: =R22/10000 -> 0.074608
D24: CHN | E24: ASTM D5291 | F24: %wt
D25: Carbon | G25: 84.31 | H25: 86.73 | I25: 86.7 | J25: 86.31 | K25: 84.06 | L25: 84.66 | M25: 85.42 | N25: 84.56 | O25: 84.67 | P25: 84.65 | Q25: 85.81 | R25: 84.46
D26: Hydrogen | G26: 9.782 | H26: 13.23 | I26: 13.17 | J26: 13.46 | K26: 13.55 | L26: 13.56 | M26: 13.52 | N26: 13.55 | O26: 13.35 | P26: 12.94 | Q26: 13.74 | R26: 13.48
D27: Nitrogen | G27: 0.4519 | H27: 0.08088 | I27: 0.09388 | J27: 0.07133 | K27: 0.117 | L27: 0.09208 | M27: 0.10049 | N27: 0.06362 | O27: 0.06731 | P27: 0.04694 | Q27: 0.05397 | R27: 0.08906
D28: CHNS | G28: =(G25+G26+G27+G18) -> 100.5299 | H28: =(H25+H26+H27+H18) -> 100.22188 | I28: =(I25+I26+I27+I18) -> 100.07878 | J28: =(J25+J26+J27+J18) -> 99.95433 | K28: =(K25+K26+K27+K18) -> 97.8204 | L28: =(L25+L26+L27+L18) -> 98.57108 | M28: =(M25+M26+M27+M18) -> 99.29119 | N28: =(N25+N26+N27+N18) -> 98.46032 | ... R28: =(R25+R26+R27+R18) -> 98.27726
D29: CN | G29: =(100-G31-G32)/(1+(G26/G25)) -> 83.974158 | H29: =(100-H31-H32)/(1+(H26/H25)) -> 86.537886 | I29: =(100-I31-I32)/(1+(I26/I25)) -> 86.649437 | J29: =(100-J31-J32)/(1+(J26/J25)) -> 86.343037 | K29: =(100-K31-K32)/(1+(K26/K25)) -> 85.978342 | L29: =(100-L31-L32)/(1+(L26/L25)) -> 85.907462 | M29: =(100-M31-M32)/(1+(M26/M25)) -> 86.057725 | N29: =(100-N31-N32)/(1+(N26/N25)) -> 85.876238 | ... R29: =(100-R31-R32)/(1+(R26/R25)) -> 85.953213
D30: HN | F30: %wt | G30: =G29*(G26/G25) -> 9.7430342 | H30: =H29*(H26/H25) -> 13.200694 | I30: =I29*(I26/I25) -> 13.162319 | J30: =J29*(J26/J25) -> 13.465152 | K30: =K29*(K26/K25) -> 13.859226 | L30: =L29*(L26/L25) -> 13.759806 | M30: =M29*(M26/M25) -> 13.620937 | N30: =N29*(N26/N25) -> 13.760916 | ... R30: =R29*(R26/R25) -> 13.71832
D31: NN | G31: =G23*100/G28 -> 0.32836002 | H31: =H23*100/H28 -> 0.080820675 | I31: =I23*100/I28 -> 0.073434149 | J31: =J23*100/J28 -> 0.078758969 | K31: =K23*100/K28 -> 0.06695127 | L31: =L23*100/L28 -> 0.069976914 | M31: =M23*100/M28 -> 0.068848002 | N31: =N23*100/N28 -> 0.071663387 | ... R31: =R23*100/R28 -> 0.075915832
D32: SN | G32: =G18*100/G28 -> 5.9544474 | H32: =H18*100/H28 -> 0.18059929 | I32: =I18*100/I28 -> 0.11480955 | J32: =J18*100/J28 -> 0.11305163 | K32: =K18*100/K28 -> 0.095481106 | L32: =L18*100/L28 -> 0.26275455 | M32: =M18*100/M28 -> 0.25248967 | N32: =N18*100/N28 -> 0.29118329 | ... R32: =R18*100/R28 -> 0.25255079
D33: HN/CN | G33: =G30/G29 -> 0.1160242 | H33: =H30/H29 -> 0.15254237 | I33: =I30/I29 -> 0.15190311 | J33: =J30/J29 -> 0.15594948 | K33: =K30/K29 -> 0.16119438 | L33: =L30/L29 -> 0.16017009 | M33: =M30/M29 -> 0.15827675 | N33: =N30/N29 -> 0.16024125 | ... R33: =R30/R29 -> 0.15960218
D34: C | G34: =G25*100/G28 -> 83.865596 | H34: =H25*100/H28 -> 86.53799 | I34: =I25*100/I28 -> 86.631752 | J34: =J25*100/J28 -> 86.349436 | K34: =K25*100/K28 -> 85.932996 | L34: =L25*100/L28 -> 85.88726 | M34: =M25*100/M28 -> 86.029788 | N34: =N25*100/N28 -> 85.882313 | ... R34: =R25*100/R28 -> 85.940532
D35: H | G35: =G26*100/G28 -> 9.7304384 | H35: =H26*100/H28 -> 13.20071 | I35: =I26*100/I28 -> 13.159633 | J35: =J26*100/J28 -> 13.46615 | K35: =K26*100/K28 -> 13.851916 | L35: =L26*100/L28 -> 13.75657 | M35: =M26*100/M28 -> 13.616515 | N35: =N26*100/N28 -> 13.761889 | ... R35: =R26*100/R28 -> 13.716296
D36: N | G36: =G27*100/G28 -> 0.449518 | H36: =H27*100/H28 -> 0.080700941 | I36: =I27*100/I28 -> 0.0938061 | J36: =J27*100/J28 -> 0.071362591 | K36: =K27*100/K28 -> 0.11960695 | L36: =L27*100/L28 -> 0.093414823 | M36: =M27*100/M28 -> 0.10120737 | N36: =N27*100/N28 -> 0.064614862 | ... R36: =R27*100/R28 -> 0.090621167
D37: S | G37: =G18*100/G28 -> 5.9544474 | H37: =H18*100/H28 -> 0.18059929 | I37: =I18*100/I28 -> 0.11480955 | J37: =J18*100/J28 -> 0.11305163 | K37: =K18*100/K28 -> 0.095481106 | L37: =L18*100/L28 -> 0.26275455 | M37: =M18*100/M28 -> 0.25248967 | N37: =N18*100/N28 -> 0.29118329 | ... R37: =R18*100/R28 -> 0.25255079
D38: H/C | G38: =G35/G34 -> 0.1160242 | H38: =H35/H34 -> 0.15254237 | I38: =I35/I34 -> 0.15190311 | J38: =J35/J34 -> 0.15594948 | K38: =K35/K34 -> 0.16119438 | L38: =L35/L34 -> 0.16017009 | M38: =M35/M34 -> 0.15827675 | N38: =N35/N34 -> 0.16024125 | ... R38: =R35/R34 -> 0.15960218
D39: Simdist | E39: ASTM D2887 ASTM D7169 | F39: deg.C
D40: IBP | G40: 376 | H40: 55.1 | I40: ='MEBU HPS LTO DAILY Graph'!E123 -> 36.8 | J40: ='MEBU HPS LTO DAILY Graph'!F123 -> 36.5 | K40: ='MEBU HPS LTO DAILY Graph'!G123 -> 11.3 | L40: ='MEBU HPS LTO DAILY Graph'!H123 -> 11.1 | M40: ='MEBU HPS LTO DAILY Graph'!I123 -> 11.5 | N40: ='MEBU HPS LTO DAILY Graph'!J123 -> 11.2 | O40: ='MEBU HPS LTO DAILY Graph'!K123 -> 11.7 | P40: ='MEBU HPS LTO DAILY Graph'!L123 -> 11.3 | ... R40: ='MEBU HPS LTO DAILY Graph'!N123 -> 11.4
...

Sheet MEBU HPS LTO DAILY Graph
D1: RHCU Pilot Plant Laboratory Worksheet
D2: Batch Name : | H2: SR ABQ3358 ACCEPTANCE TEST
D3: Date : | H3: 14-25/12/2024
D4: Note : | H4: MEBU ACCEPTANCE TEST
G14: FEED | H14: IN 11:00 AM OUT 17:30 AM | I14: IN 00:00 AM OUT 02:00 AM | J14: IN 09:00 AM OUT 17:00 AM | K14: IN 22:00 PM OUT 04:00 AM | L14: IN 8:00 AM OUT 8:00 PM | M14: IN OUT 07.15 | N14: DAY1 | O14: DAY2 | P14: DAY3 | Q14: DAY4 | R14: DAY5 | S14: DAY6 | T14: DAY7 | U14: DAY8 | V14: DAY9 | W14: DAY10 | X14: DAY11
D15: HPS | G15: ABQ3358 | H15: 14 | I15: 14-15 | J15: 15 | K15: 15-16 | L15: 16 | M15: 16-17
D16: SIMDIST | E16: 500 | F16: 560 | G16: FEED | H16: 141224 | I16: 151224 | J16: 151224 | K16: 161224 | L16: 171224 | M16: 171224 | N16: 181224 | O16: 191224 | P16: 201224 | Q16: 211224 | R16: 221224 | S16: 231224 | T16: 241224 | U16: 251224 | V16: 261224 | W16: 271224 | X16: 281224
D17: 0 | E17: 500 | F17: 560 | G17: 375.98 | H17: 161 | I17: 159 | J17: 162 | K17: 167 | L17: 163 | M17: 166 | O17: 94.4 | P17: 97.26 | Q17: 95.55 | R17: 99.9 | S17: 162 | T17: 94.68 | U17: 85.31 | V17: 83.48 | W17: 83.78 | X17: 69
D18: 1 | E18: 500 | F18: 560 | G18: 402 | H18: 190 | I18: 187 | J18: 190 | K18: 197 | L18: 195 | M18: 197 | O18: 119.27 | P18: 122.15 | Q18: 121.33 | R18: 127.72 | S18: 172.5 | T18: 120.64 | U18: 104.12 | V18: 100.6 | W18: 103.64 | X18: 83
D19: 2 | E19: 500 | F19: 560 | G19: 422 | H19: 231 | I19: 229 | J19: 229 | K19: 236 | L19: 237 | M19: 240 | O19: 148.83 | P19: 154.14 | Q19: 152.68 | R19: 158.43 | S19: 190.5 | T19: 150.78 | U19: 139.81 | V19: 139.77 | W19: 139.93 | X19: 138
D20: 3 | E20: 500 | F20: 560 | G20: 462 | H20: 261 | I20: 261 | J20: 259 | K20: 266 | L20: 270 | M20: 271 | O20: 170.14 | P20: 173.44 | Q20: 172.57 | R20: 177.31 | S20: 204.5 | T20: 171.13 | U20: 162.65 | V20: 163.13 | W20: 163 | X20: 162
D21: 4 | E21: 500 | F21: 560 | G21: 489 | H21: 285 | I21: 288 | J21: 284 | K21: 290 | L21: 297 | M21: 298 | O21: 185.01 | P21: 190.25 | Q21: 189.45 | R21: 194.12 | S21: 217.5 | T21: 186.47 | U21: 180.23 | V21: 181.27 | W21: 180.54 | X21: 179
D22: 5 | E22: 500 | F22: 560 | G22: 510 | H22: 306 | I22: 309 | J22: 304 | K22: 310 | L22: 318 | M22: 318 | O22: 199.54 | P22: 203.42 | Q22: 203.23 | R22: 207.74 | S22: 229 | T22: 201.61 | U22: 195.08 | V22: 197.13 | W22: 195.45 | X22: 194
D23: 6 | E23: 500 | F23: 560 | G23: 518 | H23: 323 | I23: 328 | J23: 321 | K23: 327 | L23: 337 | M23: 336 | O23: 211.85 | P23: 215.86 | Q23: 215.87 | R23: 220.1 | S23: 240 | T23: 214.77 | U23: 207.75 | V23: 209.1 | W23: 208.08 | X23: 207
D24: 7 | E24: 500 | F24: 560 | G24: 525 | H24: 339 | I24: 344 | J24: 337 | K24: 342 | L24: 353 | M24: 352 | O24: 222.31 | P24: 226.8 | Q24: 226.97 | R24: 231.49 | S24: 251 | T24: 226.44 | U24: 219.36 | V24: 220.51 | W24: 219.63 | X24: 218
D25: 8 | E25: 500 | F25: 560 | G25: 533 | H25: 353 | I25: 359 | J25: 351 | K25: 355 | L25: 368 | M25: 367 | O25: 232.37 | P25: 236.7 | Q25: 237.07 | R25: 241.99 | S25: 260 | T25: 236.98 | U25: 230.14 | V25: 231.51 | W25: 230.41 | X25: 229
D26: 9 | E26: 500 | F26: 560 | G26: 538 | H26: 366 | I26: 373 | J26: 364 | K26: 369 | L26: 382 | M26: 380 | O26: 242.16 | P26: 247.63 | Q26: 248.03 | R26: 251.72 | S26: 269 | T26: 248.45 | U26: 239.76 | V26: 241.52 | W26: 239.97 | X26: 239
D27: 10 | E27: 500 | F27: 560 | G27: 543.5 | H27: 378 | I27: 386 | J27: 376 | K27: 380 | L27: 394 | M27: 392 | O27: 251.34 | P27: 256.39 | Q27: 256.96 | R27: 260.96 | S27: 277.5 | T27: 257.93 | U27: 249.77 | V27: 251.17 | W27: 249.92 | X27: 249
D28: 11 | E28: 500 | F28: 560 | G28: 548 | H28: 389 | I28: 398 | J28: 387 | K28: 391 | L28: 407 | M28: 404 | O28: 259.73 | P28: 265.21 | Q28: 265.81 | R28: 269.26 | S28: 285.5 | T28: 267.47 | U28: 258.4 | V28: 259.89 | W28: 258.45 | X28: 257
... D77: 60 | E77: 500 | F77: 560 | G77: 705 | H77: 661 | I77: 701 | J77: 657 | K77: 657 | L77: 719 | M77: 698 | O77: 506.8 | P77: 517.64 | Q77: 517.64 | R77: 519.87 | S77: 534 | T77: 527.08 | U77: 509.77 | V77: 514.64 | W77: 506.44 | X77: 526
D78: 61 | E78: 500 | F78: 560 | G78: 708 | H78: 668 | I78: 709 | J78: 662 | K78: 663 | M78: 706 | O78: 511.15 | P78: 522.02 | Q78: 522.02 | R78: 524.19 | S78: 538 | T78: 531.42 | U78: 514.28 | V78: 519.26 | W78: 510.89 | X78: 531
D79: 62 | E79: 500 | F79: 560 | G79: 713 | H79: 674 | I79: 720 | J79: 669 | K79: 670 | M79: 716 | O79: 515.47 | P79: 526.29 | Q79: 526.29 | R79: 528.41 | S79: 542.5 | T79: 535.75 | U79: 518.82 | V79: 523.82 | W79: 515.32 | X79: 536
D80: 63 | E80: 500 | F80: 560 | G80: 718 | H80: 682 | J80: 675 | K80: 677 | O80: 519.83 | P80: 530.56 | Q80: 530.56 | R80: 532.6 | S80: 546.5 | T80: 540.06 | U80: 523.32 | V80: 528.27 | W80: 519.79 | X80: 541
D81: 64 | E81: 500 | F81: 560 | G81: 720 | H81: 690 | J81: 683 | K81: 685 | O81: 524.13 | P81: 534.79 | Q81: 534.79 | R81: 536.81 | S81: 551 | T81: 544.33 | U81: 527.71 | V81: 532.73 | W81: 524.22 | X81: 546
D82: 65 | E82: 500 | F82: 560 | H82: 697 | J82: 690 | K82: 692 | O82: 528.32 | P82: 539.03 | Q82: 539.03 | R82: 540.99 | S82: 555 | T82: 548.63 | U82: 532.12 | V82: 537.22 | W82: 528.56 | X82: 551
D83: 66 | E83: 500 | F83: 560 | H83: 706 | J83: 696 | K83: 700 | O83: 532.51 | P83: 543.24 | Q83: 543.24 | R83: 545.16 | S83: 559 | T83: 552.94 | U83: 536.55 | V83: 541.7 | W83: 532.89 | X83: 556
D84: 67 | E84: 500 | F84: 560 | H84: 717 | J84: 703 | K84: 709 | O84: 536.73 | P84: 547.48 | Q84: 547.48 | R84: 549.34 | S84: 563 | T84: 557.16 | U84: 540.97 | V84: 546.18 | W84: 537.25 | X84: 561
D85: 68 | E85: 500 | F85: 560 | J85: 711 | K85: 719 | O85: 540.93 | P85: 551.72 | Q85: 551.72 | R85: 553.52 | S85: 567 | T85: 561.2 | U85: 545.39 | V85: 550.7 | W85: 541.62 | X85: 566
D86: 69 | E86: 500 | F86: 560 | J86: 719 | O86: 545.11 | P86: 555.95 | Q86: 555.95 | R86: 557.6 | S86: 571 | T86: 565.26 | U86: 549.86 | V86: 555.23 | W86: 545.98 | X86: 570
D87: 70 | E87: 500 | F87: 560 | O87: 549.33 | P87: 559.92 | Q87: 559.92 | R87: 561.54 | S87: 575 | T87: 569.39 | U87: 554.34 | V87: 559.54 | W87: 550.36 | X87: 575
D88: 71 | E88: 500 | F88: 560 | O88: 553.56 | P88: 563.94 | Q88: 563.94 | R88: 565.5 | S88: 579.5 | T88: 573.6 | U88: 558.66 | V88: 563.86 | W88: 554.78 | X88: 580
D89: 72 | E89: 500 | F89: 560 | O89: 557.68 | P89: 568.01 | Q89: 568.01 | R89: 569.53 | S89: 584 | T89: 577.98 | U89: 562.95 | V89: 568.25 | W89: 558.99 | X89: 586
D90: 73 | E90: 500 | F90: 560 | O90: 561.69 | P90: 572.16 | Q90: 572.16 | R90: 573.63 | S90: 588.5 | T90: 582.52 | U90: 567.29 | V90: 572.75 | W90: 563.2 | X90: 591
D91: 74 | E91: 500 | F91: 560 | O91: 565.72 | P91: 576.43 | Q91: 576.43 | R91: 577.9 | S91: 593 | T91: 587.01 | U91: 571.73 | V91: 577.43 | W91: 567.47 | X91: 597
D92: 75 | E92: 500 | F92: 560 | O92: 569.84 | P92: 580.87 | Q92: 580.87 | R92: 582.31 | S92: 597.5 | T92: 591.57 | U92: 576.32 | V92: 582.31 | W92: 571.82 | X92: 603
D93: 76 | E93: 500 | F93: 560 | O93: 574.05 | P93: 585.37 | Q93: 585.37 | R93: 586.69 | S93: 602.5 | T93: 596.33 | U93: 581.13 | V93: 587.16 | W93: 576.33 | X93: 609
D94: 77 | E94: 500 | F94: 560 | O94: 578.45 | P94: 589.85 | Q94: 589.85 | R94: 591.15 | S94: 608 | T94: 601.33 | U94: 585.99 | V94: 592.15 | W94: 581.04 | X94: 616
D95: 78 | E95: 500 | F95: 560 | O95: 583 | P95: 594.52 | Q95: 594.52 | R95: 595.76 | S95: 613.5 | T95: 606.67 | U95: 590.9 | V95: 597.35 | W95: 585.79 | X95: 623
D96: 79 | E96: 500 | F96: 560 | O96: 587.49 | P96: 599.4 | Q96: 599.4 | R96: 600.59 | S96: 619 | T96: 612.23 | U96: 596.02 | V96: 602.91 | W96: 590.59 | X96: 630
D97: 80 | E97: 500 | F97: 560 | O97: 592.11 | P97: 604.59 | Q97: 604.59 | R97: 605.76 | S97: 625 | T97: 618.02 | U97: 601.44 | V97: 608.82 | W97: 595.58 | X97: 638
...

Sheet ISV
D1: RHCU Pilot Plant Laboratory Worksheet
D2: Batch Name : | E2: SR ABQ3358 ACCEPTANCE TEST
D3: Date : | E3: 14-25/12/2024
D4: Note : | E4: MEBU ACCEPTANCE TEST | H4: SAMPLE INVESTIGATION
H5: Lab test 251224 | I5: Lab test 251224 | J5: Lab test 261224 | K5: Lab test 271224
H6: 241224 | I6: 241224 | J6: 251224 | K6: 261224
D7: Properties | E7: Method | F7: Unit | G7: SR ABQ3358 | H7: ISV | I7: ISV+HPS+RX | J7: ISV | K7: ISV
D8: ICP | E8: ASTM D7691 UOP 389 | F8: PPMw
D9: Nickle (Ni) | G9: 73.4 | H9: 309.79 | I9: 350.77 | J9: 571.3 | K9: 90.29 | O9: 241224 | P9: 241224 | Q9: 251224 | R9: 261224
D10: Vanadium (V) | G10: 238.34 | H10: 774.81 | I10: 1061.13 | J10: 1574.5 | K10: 255.56
D11: Sodium (Na) | G11: 26.05 | H11: 2254.55 | I11: 130.3 | J11: 196.85 | K11: 36.51 | O11: ISV1 | P11: ISV1+HPS+RX | Q11: ISV2 | R11: ISV3
D12: Calcium (Ca) | G12: 14.22 | H12: 61.04 | I12: 31.41 | J12: 37.14 | K12: 2.31 | N12: 0 | O12: 165.07 | P12: 98.16 | Q12: 157 | R12: 182
D13: Iron (Fe) | G13: 19.4 | H13: 1501.29 | I13: 571.87 | J13: 746.91 | K13: 80.3 | N13: 1 | O13: 193.11 | P13: 135.27 | Q13: 186 | R13: 207
D14: Ni | G14: - | H14: 73.555858 | I14: =100-((I9/$G$9)*100) -> -377.88828 | J14: =100-((J9/$G$9)*100) -> -678.33787 | K14: =100-((K9/$G$9)*100) -> -23.010899 | N14: 2 | O14: 249.62 | P14: 171.91 | Q14: 220 | R14: 235
D15: V | E15: HDM Conversion | F15: % | G15: - | H15: 88.709407 | I15: =100-((I10/G10)*100) -> -345.21692 | J15: =100-((J10/$G$10)*100) -> -560.61089 | K15: =100-((K10/$G$10)*100) -> -7.2249727 | N15: 3 | O15: 285.27 | P15: 199.61 | Q15: 245 | R15: 255
D16: Ni+V | G16: - | H16: 85.141464 | I16: =100-(((I9+I10)/($G$9+$G$10))*100) -> -352.90948 | J16: =100-(((J9+J10)/($G$9+$G$10))*100) -> -588.33002 | K16: =100-(((K9+K10)/($G$9+$G$10))*100) -> -10.94181 | N16: 4 | O16: 312.19 | P16: 222.95 | Q16: 264 | R16: 271
D17: Simdist | E17: ASTM D2887 ASTM D7169 | F17: deg.C | N17: 5 | O17: 332.77 | P17: 243.6 | Q17: 283 | R17: 286
D18: IBP | G18: 376 | H18: =O12 -> 165.07 | I18: =P12 -> 98.16 | J18: =Q12 -> 157 | K18: =R12 -> 182 | N18: 6 | O18: 349.13 | P18: 261.6 | Q18: 299 | R18: 300
D19: 5 | G19: 510 | H19: =O17 -> 332.77 | I19: =P17 -> 243.6 | J19: =Q17 -> 283 | K19: =R17 -> 286 | N19: 7 | O19: 361.65 | P19: 277.99 | Q19: 313 | R19: 313
D20: 10 | G20: 543.5 | H20: =O22 -> 388.41 | I20: =P22 -> 319.3 | J20: =Q22 -> 351 | K20: =R22 -> 347 | N20: 8 | O20: 372.05 | P20: 293.27 | Q20: 327 | R20: 325
D21: 20 | G21: 578 | H21: =O32 -> 443.68 | I21: =P32 -> 412.74 | J21: =Q32 -> 442 | K21: =R32 -> 432 | N21: 9 | O21: 380.52 | P21: 306.78 | Q21: 339 | R21: 336
D22: 30 | G22: 606 | H22: =O42 -> 495.08 | I22: =P42 -> 483.79 | J22: =Q42 -> 514 | K22: =R42 -> 502 | N22: 10 | O22: 388.41 | P22: 319.3 | Q22: 351 | R22: 347
D23: 40 | G23: 635 | H23: =O52 -> 545.3 | I23: =P52 -> 535.23 | J23: =Q52 -> 563 | K23: =R52 -> 551 | N23: 11 | O23: 395.16 | P23: 331.31 | Q23: 361 | R23: 357
D24: 50 | G24: 667 | H24: =O62 -> 585.47 | I24: =P62 -> 570.67 | J24: =Q62 -> 601 | K24: =R62 -> 586 | N24: 12 | O24: 401.24 | P24: 342.52 | Q24: 372 | R24: 367
D25: 60 | G25: 705 | H25: =O72 -> 626.85 | I25: =P72 -> 603.2 | J25: =Q72 -> 646 | K25: =R72 -> 622 | N25: 13 | O25: 407.47 | P25: 353.26 | Q25: 382 | R25: 376
D26: 70 | H26: =O82 -> 680.07 | I26: =P82 -> 641.77 | J26: =Q82 -> 0 | K26: =R82 -> 668 | N26: 14 | O26: 412.88 | P26: 362.67 | Q26: 391 | R26: 385
D27: 80 | I27: =P92 -> 693.72 | J27: =Q92 -> 0 | K27: =R92 -> 0 | N27: 15 | O27: 418.47 | P27: 372.04 | Q27: 400 | R27: 393
D28: 90 | N28: 16 | O28: 423.55 | P28: 380.63 | Q28: 409 | R28: 401
D29: 95 | N29: 17 | O29: 428.62 | P29: 389.14 | Q29: 417 | R29: 409
D30: FBP | E30: Conversion | G30: <560 = 14.1% | H30: =SUM(H32:H37)-SUM($G$36:$G$37) -> 29.37 | I30: =SUM(I32:I37)-SUM($G$36:$G$37) -> 32.61 | J30: =SUM(J32:J37)-SUM($G$36:$G$37) -> 25.083 | K30: =SUM(K32:K37)-SUM($G$36:$G$37) -> 28.167 | N30: 18 | O30: 433.72 | P30: 397.36 | Q30: 425 | R30: 417
D31: CUT POINTS | N31: 19 | O31: 438.58 | P31: 405.09 | Q31: 434 | R31: 425
D32: IBP-90 | E32: ASTM D2887 ASTM D7169 | F32: %wt | G32: 0 | H32: 0 | I32: 0.41 | J32: 0.07 | K32: 0.004 | N32: 20 | O32: 443.68 | P32: 412.74 | Q32: 442 | R32: 432
D33: 90-160 | G33: 0 | H33: 0.36 | I33: 1.19 | J33: 0.468 | K33: 0.215 | N33: 21 | O33: 448.44 | P33: 420.29 | Q33: 450 | R33: 440
D34: 160-250 | G34: 0 | H34: 1.65 | I34: 3.73 | J34: 2.692 | K34: 2.462 | N34: 22 | O34: 453.69 | P34: 427.78 | Q34: 458 | R34: 447
D35: 250-360 | G35: 0 | H35: 4.84 | I35: 8.36 | J35: 7.638 | K35: 8.612 | N35: 23 | O35: 458.6 | P35: 435.28 | Q35: 465 | R35: 455
D36: 360-500 | G36: 4.17 | H36: 24.07 | I36: 18.97 | J36: 16.871 | K36: 18.307 | N36: 24 | O36: 463.69 | P36: 442.62 | Q36: 473 | R36: 462
D37: 500-560 | G37: =14.05-G36 -> 9.88 | H37: 12.5 | I37: 14 | J37: 11.394 | K37: 12.617 | N37: 25 | O37: 468.87 | P37: 449.81 | Q37: 480 | R37: 469
D38: 560+ | G38: =100-SUM(G32:G37) -> 85.95 | H38: =100-SUM(H32:H37) -> 56.58 | I38: =100-SUM(I32:I37) -> 53.34 | J38: =100-SUM(J32:J37) -> 60.867 | K38: =100-SUM(K32:K37) -> 57.783 | N38: 26 | O38: 473.86 | P38: 457.02 | Q38: 488 | R38: 476
D39: TOTAL | G39: =SUM(G32:G38) -> 100 | H39: =SUM(H32:H38) -> 100 | I39: =SUM(I32:I38) -> 100 | J39: =SUM(J32:J38) -> 100 | K39: =SUM(K32:K38) -> 100 | N39: 27 | O39: 479.08 | P39: 464.02 | Q39: 495 | R39: 483
N40: 28 | O40: 484.39 | P40: 470.82 | Q40: 502 | R40: 490
...

Sheet Ref- MEBU Acceptance
B2: VR Feedstock Property | I2: Input required | T2: Catalyst | Y2: Total ISV: 20-30 g/d(24hr)
B3: 560 degC minus content, wt% | D3: 14 | G3: MEBU Reactor Volume | I3: 186 | J3: mL | T3: Rx | U3: Rx2 | V3: Rx3 | Z3: 1-1.5 g/hr
B4: Metal | C4: Ni, ppm | D4: 73.4 | G4: VR density | I4: 1.057 | J4: g/mL | T4: DC2700, g | U4: DC2174-02, g | V4: GR-823G, g
C5: V, ppm | D5: 238.34 | G5: VR volumetric flow rate | I5: =I3*I9*3 -> 187.488 | J5: mL/hr | T5: 58.0025 | U5: 68.4505 | V5: 63.2606 | Z5: 7 days --> 2 days (No need to analyse) + 5 days (analysis)
C6: Fe, ppm | D6: 19.4 | G6: VR mass flow rate | I6: =I5*I4 -> 198.17482 | J6: g/hr
B7: MCRT, wt% | D7: 26.05 | G7: Target Temp, Rx1/2/3 | I7: 422.8 | J7: degC
B8: C5 Asph, wt% | D8: 21.02 | G8: Target Pressure | I8: =2550/14.5 -> 175.86207 | J8: barg
B9: C7 Asph, wt% | D9: 12.86 | G9: MEBU LHSV | I9: 0.336 | J9: hr-1
B10: Impurity | C10: S, wt% | D10: 5.986 | G10: LCF LHSV | I10: =I9/1.46 -> 0.23013699 | J10: hr-1
C11: N, wt% | D11: 0.4519 | S11: MEBU Product
B12: CN | D12: 83.87
B13: HN | D13: 9.73
D14: VR Feedstock | S14: HPS | BD14: LTO | CC14: High Gas | CZ14: Low Gas
D15: VR feed of 24 hrs, g | E15: VR feed rate, g/hr | F15: Content of 560 degC minus, g/hr | G15: Content of 560 degC plus, g/hr | H15: Metal Content | K15: CN | L15: HN | M15: MCRT content, g/hr | N15: C5 Asphaltene | O15: C7 Asphaltene | P15: Impurity | S15: HPS product of 24 hrs, g | T15: HPS rate, g/hr | U15: Boiling Cuts from HT Simdist, wt% | AB15: Product rate of HPS at cut points, g/hr | AI15: Metal, ppm | AL15: Metal, rate | AO15: MCRT, wt% | AP15: MCRT rate, g/hr | AQ15: CN | AR15: HN | AS15: CN | AT15: HN | AU15: C5 Asphaltene | AW15: C7 Asphaltene | AY15: Impurity (SN, NN) | BA15: Impurity rate | BD15: LTO product of 24 hrs, g | BE15: LTO rate, g/hr | BF15: LTO Boiling Cuts from LT Simdist, wt% | BM15: LTO Product rate of HPS at cut points, g/hr | BT15: CN | BU15: HN | BV15: CN | BW15: HN | BX15: Impurity | BZ15: Impurity rate | CC15: High Gas of 24 hrs, g (FQT-1124) | CD15: High Gas rate, g/hr | CE15: Break down gas composition, High Gas | CL15: Break down gas flow rate, High Gas | CZ15: Low Gas of 24 hrs, Ltr (FQT-1123) | DA15: Low Gas rate, Ltr/hr | DB15: Break down gas composition, Low gas * Low gas also contains H2 | DH15: Break down gas volumetric flow rate, Low gas | DN15: Mass flow rate, Low gas | EA15: Thermal Conversion, % | EC15: Catalytic Conversion | EJ15: MCRT conversion | EK15: Total MOC (Ni+V) (24 hrs) gram (g) | EL15: Accumulative MOC gram (g) | EM15: MoC (Ni+V) | EP15: S converted (g/hr) | EQ15: N converted (g/hr) | ER15: As is yield (Rate strem / VR feed rate) | FV15: C closure = (CN HPS + CN LTO +C high gas + C low gas)/CN/VR | FY15: Total HN in Product/ (HPS+LTO+Low gas + High Gas) - Total HN in feed/VR | FZ15: H2 Consumption/ VR feed rate
B16: Date | C16: Day | H16: Ni, g/hr | I16: V, g/hr | J16: Fe, g/hr | K16: g/hr | L16: g/hr | N16: g/hr | O16: g/hr | P16: S, g/hr | Q16: N, g/hr | U16: IBP-90 | V16: 90-160 | W16: 160-250 | X16: 250-360 | Y16: 360-500 | Z16: 500-560 | AA16: 560 degC plus | AB16: IBP-90 | AC16: 90-160 | AD16: 160-250 | AE16: 250-360 | AF16: 360-500 | AG16: 500-560 | AH16: 560 degC plus | AI16: Ni, ppm | AJ16: V, ppm | AK16: Fe, ppm | AL16: Ni, g/hr | AM16: V, g/hr | AN16: Fe, g/hr | AS16: g/hr | AT16: g/hr | AU16: wt% | AV16: rate, g/hr | AW16: wt% | AX16: rate, g/hr | AY16: S, wt% | AZ16: N, wt% | BA16: S, g/hr | BB16: N, g/hr | BF16: IBP-90 | BG16: 90-160 | BH16: 160-250 | BI16: 250-360 | BJ16: 360-500 | BK16: 500-560 | BL16: 560 plus | BM16: IBP-90 | BN16: 90-160 | BO16: 160-250 | BP16: 250-360 | BQ16: 360-500 | BR16: 500-560 | BS16: 560 plus | BV16: g/hr | BW16: g/hr | BX16: S, wt% | BY16: N, wt% | BZ16: S, g/hr | CA16: N, g/hr | CE16: H2, wt% | CF16: C1, wt% | CG16: C2, wt% | CH16: C3, wt% | CI16: C4, wt% | CJ16: C5, wt% | CK16: C6, wt% | CL16: H2, g/hr | CM16: C1, g/hr | CN16: C1 rate | CO16: C2, g/hr | CP16: C2 rate | CQ16: C3, g/hr | CR16: C3 rate | CS16: C4, g/hr | CT16: C4 rate | CU16: C5, g/hr | CV16: C5 rate | CW16: C6 plus, g/hr | CX16: C6 rate | DB16: C1, v% | DC16: C2, v% | DD16: C3, v% | DE16: C4, v% | DF16: C5, v% | DG16: C6, v% | DH16: C1, v/hr | DI16: C2, v/hr | DJ16: C3, v/hr | DK16: C4, v/hr | DL16: C5, v/hr | DM16: C6, v/hr | DN16: C1, g/hr | DO16: C2, g/hr | DP16: C3, g/hr | DQ16: C4,g/hr | DR16: C5, g/hr | DS16: C6, g/hr | DT16: C1C, g/hr | DU16: C2C, g/hr | DV16: C3C, g/hr | DW16: C4C,g/hr | DX16: C5C, g/hr | DY16: C6C, g/hr | EC16: C5 Asph Conv % | ED16: C7 Asph Conv % | EE16: Ni,% | EF16: V, % | EG16: Fe, % | EH16: S conv, % | EI16: N conv, % | EM16: Rx1 (70%), g | EN16: Rx2(20%), g | EO16: Rx3(10%), g | ER16: C1/CH4, wt% | ES16: C, wt% | ET16: H, wt% | EU16: C2/C2H6, wt% | EV16: C | EW16: H | EX16: C3, wt% | EY16: C | EZ16: H | FA16: C4, wt% | FB16: C | FC16: H | FD16: C5, wt% | FE16: C | FF16: H | FG16: C6, wt% | FH16: C | FI16: H | FJ16: H2S, wt% | FK16: H | FL16: NH3, wt% * | FM16: H | FN16: RT-90, wt% | FO16: 90-160, wt% | FP16: 160-250, wt% | FQ16: 250-360, wt% | FR16: 360-500, wt% | FS16: <=500, wt% | FT16: 500-560, wt% | FU16: 560 plus, wt% | FX16: Corrected Yield = As is yield / C Closure (<=500 ) | FY16: H2 Consumption, g/hr | GA16: Day
