Workbook
Name AllottedFunds: #REF!
Name ColumnTitle2: #REF!
Name ColumnTitleRegion1..D4.2: #REF!
Name FundsRemaining: INDEX(#REF!,ROWS(#REF!),1)
Name FundsRemainingLabel: #REF!
Name FundsUsed: #REF!
Name FundsUsedLabel: #REF!
Name RowTitleRegion1..C11: #REF!
Name Title1: #REF!

Sheet Lab Results Summary
D157: MEBU25001 | E157: D1 | F157: D2 | G157: D3 | H157: D4 | I157: MEBU25002 | J157: D1 | K157: D2 | L157: D3 | M157: D4
D158: 560+ | E158: 60.116 | F158: 63.283 | G158: 61.009 | H158: 61.402 | I158: 560+ | J158: 59.673 | K158: 58.045 | L158: 59.301 | M158: 59.834
D159: Crk Conv | E159: 38.617032 | F159: 36.96046 | G159: 39.346284 | H159: 39.106101 | I159: Crk Conv | J159: 39.752164 | K159: 39.57554 | L159: 38.201039 | M159: 38.194675
D160: S | E160: 2.34 | F160: 2.27 | G160: 2.334 | H160: 2.366 | I160: S | J160: 2.16 | K160: 2.314 | L160: 2.34 | M160: 2.341
D161: S Conv | E161: 64.498988 | F161: 66.260538 | G161: 65.200068 | H161: 65.178078 | I161: S Conv | J161: 67.617687 | K161: 64.246704 | L161: 63.811026 | M161: 64.098664
D162: N | E162: 0.3786 | F162: 0.3837 | G162: 0.354 | H162: 0.3816 | I162: N | J162: 0.38516 | K162: 0.401935 | L162: 0.4099 | M162: 0.425045
D163: N Conv | E163: 38.689882 | F163: 39.321935 | G163: 43.437155 | H163: 39.672386 | I163: N Conv | J163: 38.243114 | K163: 33.529646 | L163: 32.081084 | M163: 30.166695
D164: Ni+v | E164: 61.02 | F164: 57.33 | G164: 56.83 | H164: 55.54 | I164: Ni+v | J164: 44.36 | K164: 51.76 | L164: 56.54 | M164: 56.51
D165: Ni+V Conv | E165: 78.07227 | F165: 79.901132 | G165: 80.11595 | H165: 80.615223 | I165: Ni+V Conv | J165: 84.237729 | K165: 81.03705 | L165: 79.263348 | M165: 79.456859
D166: MCR | E166: 14.8 | F166: 14.57 | G166: 14.55 | H166: 14.7 | I166: MCR | J166: 14.1 | K166: 14.67 | L166: 14.73 | M166: 14.91
D167: MCR Conv | E167: 47.705683 | F167: 49.620881 | G167: 49.683198 | H167: 49.651262 | I167: MCR Conv | J167: 50.834248 | K167: 47.257821 | L167: 46.984618 | M167: 46.809325
D168: C7 | E168: 4.6 | F168: 4.3 | G168: 4.4 | H168: 4.5 | I168: C7 | J168: 3.65 | K168: 4.173 | L168: 4.238 | M168: 4.83
D169: C7 Conv | E169: 65.846695 | F169: 68.717064 | G169: 67.954365 | H169: 67.635477 | I169: C7 Conv | J169: 73.274743 | K169: 68.496284 | L169: 67.97084 | M169: 63.818178
D171: ART
D172: MCR Conv | E172: 56 | F172: 50 | G172: 49 | H172: 48

Sheet LTO DAILY
D1: RHCU Pilot Plant Laboratory Worksheet
D2: Batch Name : | E2: MEBU2026'01
D3: Date : | H3: CATALYST AGING | L3: CRACKING EXPERIMENT
D4: Note : | E4: Repeat Acceptance test | H4: ABQ3358 | L4: ABQ3358 (No3+No5)
G5: Day on stream | H5: 1 | I5: 2 | J5: 3 | K5: 4 | L5: 5 | M5: 6 | N5: 7 | O5: 8 | P5: 9 | Q5: 10 | R5: 11 | S5: 12 | T5: 13 | U5: 14 | V5: 15 | W5: 16 | X5: 17 | Y5: 18 | Z5: 19 | AA5: 20 | AB5: 21 | AC5: 22 | AD5: 23 | AE5: 24 | AF5: 25 | AG5: 26 | AH5: 27 | AI5: 28 | AL5: 9 | AM5: 10 | AN5: 11
G6: Date | I6: D1.5 | J6: 46086
D7: Properties | E7: Method | F7: Unit | G7: SR ABQ3358 | H7: LTO | I7: LTO | J7: LTO | K7: LTO | L7: LTO | M7: LTO | N7: LTO | O7: LTO | P7: LTO | Q7: LTO | R7: LTO | S7: LTO | T7: LTO | U7: LTO | V7: LTO | W7: LTO | X7: LTO | Y7: LTO | Z7: LTO | AA7: LTO | AB7: LTO | AC7: LTO | AD7: LTO | AE7: LTO | AF7: LTO | AG7: LTO | AH7: LTO | AI7: LTO | AL7: LTO | AM7: LTO | AN7: LTO
D8: Ratio | E8: - | F8: %wt. | G8: 100
D9: API | E9: - | F9: kg | I9: 40.72 | J9: 42 | K9: 42.5 | L9: 40.68 | M9: 42.6 | N9: 40.17 | O9: 41.06 | P9: 40.41 | Q9: 41.09 | R9: 40.41 | S9: 41.33 | T9: 41.15 | AL9: 41.34 | AM9: 39.48 | AN9: 41.09 | AQ9: =AVERAGE(AL9:AM9) -> 40.41
D10: Density | E10: ASTM D4052 | F10: kg/L | I10: 0.8208 | J10: 0.8146 | K10: 0.8124 | L10: 0.821 | M10: 0.812 | N10: 0.8235 | O10: 0.8192 | P10: 0.82235 | Q10: 0.8191 | R10: 0.8223 | S10: 0.8179 | T10: 0.8188 | AL10: 0.8179 | AM10: 0.8268 | AN10: 0.8191 | AQ10: =AVERAGE(AL10:AM10) -> 0.82235
D11: Relative Density@25/25 oC | E11: ASTM D70 | F11: - | AQ11: =AVERAGE(AL11:AM11) -> #DIV/0!
D12: Viscosity @ -20 oC | E12: ASTM D445 | F12: cSt. | AQ12: =AVERAGE(AL12:AM12) -> #DIV/0!
D13: Viscosity @ 40 oC | AQ13: =AVERAGE(AL13:AM13) -> #DIV/0!
D14: Viscosity @ 70 oC | AQ14: =AVERAGE(AL14:AM14) -> #DIV/0!
D15: Viscosity @ 100 oC | AQ15: =AVERAGE(AL15:AM15) -> #DIV/0!
D16: Viscosity @ 150 oC | AQ16: =AVERAGE(AL16:AM16) -> #DIV/0!
D17: V50 | AQ17: =AVERAGE(AL17:AM17) -> #DIV/0!
D18: Sulfur | E18: ASTM D4294 | F18: %wt | G18: 5.986 | I18: 0.164 | J18: 0.172 | K18: 0.157 | L18: 0.13277 | M18: 0.09042 | N18: 0.103 | O18: 0.108 | P18: 0.165665 | Q18: 0.14561 | R18: 0.1367 | S18: 0.12447 | T18: 0.12303 | AL18: 0.10486 | AM18: 0.22647 | AN18: 0.14561 | AQ18: =AVERAGE(AL18:AM18) -> 0.165665
E19: ASTM D2622 | F19: %wt | AQ19: =AVERAGE(AL19:AM19) -> #DIV/0!
F20: PPMw | AQ20: =AVERAGE(AL20:AM20) -> #DIV/0!
D21: Total Nitrogen | E21: ASTM D4629 | F21: PPMw | AQ21: =AVERAGE(AL21:AM21) -> #DIV/0!
E22: ASTM D5762 | F22: PPMw | G22: 3301 | I22: 458.27 | J22: 492 | K22: 543.66 | L22: 558.52 | M22: 474.65 | N22: 548.8 | O22: 547.8 | P22: 558.371 | Q22: 572.94 | R22: 611.99 | S22: 603.89 | T22: 617.06 | AL22: 562.822 | AM22: 553.92 | AN22: 572.94 | AQ22: =AVERAGE(AL22:AM22) -> 558.371
B23: 0.4519 | F23: %wt | G23: 0.3301 | H23: =H22/10000 -> 0 | I23: =I22/10000 -> 0.045827 | J23: =J22/10000 -> 0.0492 | K23: =K22/10000 -> 0.054366 | L23: =L22/10000 -> 0.055852 | M23: =M22/10000 -> 0.047465 | N23: =N22/10000 -> 0.05488 | O23: =O22/10000 -> 0.05478 | ... AI23: =AI22/10000 -> 0 | AL23: =AL22/10000 -> 0.0562822 | AM23: =AM22/10000 -> 0.055392 | AN23: =AN22/10000 -> 0.057294 | AQ23: =AVERAGE(AL23:AM23) -> 0.0558371
D24: CHN | E24: ASTM D5291 | F24: %wt | AQ24: =AVERAGE(AL24:AM24) -> #DIV/0!
D25: Carbon | G25: 84.31 | I25: 86.35 | J25: 87.07 | K25: 86.62 | L25: 87.19 | M25: 86.94 | N25: 87.53 | O25: 87.3 | P25: 88.155 | Q25: 87.48 | R25: 85.86 | S25: 87.48 | T25: 87.87 | AL25: 88.43 | AM25: 87.88 | AN25: 87.48 | AQ25: =AVERAGE(AL25:AM25) -> 88.155
D26: Hydrogen | G26: 9.782 | I26: 13.34 | J26: 13.58 | K26: 13.33 | L26: 13.11 | M26: 13.5 | N26: 13.08 | O26: 13.36 | P26: 13.13 | Q26: 13.26 | R26: 13.23 | S26: 13.26 | T26: 13.28 | AL26: 13.26 | AM26: 13 | AN26: 13.26 | AQ26: =AVERAGE(AL26:AM26) -> 13.13
D27: Nitrogen | G27: 0.4519 | I27: 0.06146 | J27: 0.08 | K27: 0.08968 | L27: 0.08 | M27: 0.01653 | N27: 0.01087 | O27: 0.08 | P27: 0.07994 | Q27: 0.08378 | R27: 0.007312 | S27: 0.08378 | T27: 0.09945 | AL27: 0.0865 | AM27: 0.07338 | AN27: 0.08378 | AQ27: =AVERAGE(AL27:AM27) -> 0.07994
D28: CHNS | G28: =(G25+G26+G27+G18) -> 100.5299 | H28: =H$25+H$26+H$23+H$18 -> 0 | I28: =I$25+I$26+I$23+I$18 -> 99.899827 | J28: =J$25+J$26+J$23+J$18 -> 100.8712 | K28: =K$25+K$26+K$23+K$18 -> 100.16137 | L28: =L$25+L$26+L$23+L$18 -> 100.48862 | M28: =M$25+M$26+M$23+M$18 -> 100.57788 | N28: =N$25+N$26+N$23+N$18 -> 100.76788 | O28: =O$25+O$26+O$23+O$18 -> 100.82278 | ... AI28: =AI$25+AI$26+AI$23+AI$18 -> 0 | AL28: =AL$25+AL$26+AL$23+AL$18 -> 101.85114 | AM28: =AM$25+AM$26+AM$23+AM$18 -> 101.16186 | AN28: =AN$25+AN$26+AN$23+AN$18 -> 100.9429 | AQ28: =AVERAGE(AL28:AM28) -> 101.5065
D29: CN | G29: =(100-G31-G32)/(1+(G26/G25)) -> 83.974158 | H29: =(100-H$31-H$32)/(1+(H$26/H$25)) -> #DIV/0! | I29: =(100-I$31-I$32)/(1+(I$26/I$25)) -> 86.436586 | J29: =(100-J$31-J$32)/(1+(J$26/J$25)) -> 86.317998 | K29: =(100-K$31-K$32)/(1+(K$26/K$25)) -> 86.48045 | L29: =(100-L$31-L$32)/(1+(L$26/L$25)) -> 86.766042 | M29: =(100-M$31-M$32)/(1+(M$26/M$25)) -> 86.440473 | N29: =(100-N$31-N$32)/(1+(N$26/N$25)) -> 86.862996 | O29: =(100-O$31-O$32)/(1+(O$26/O$25)) -> 86.587575 | ... AI29: =(100-AI$31-AI$32)/(1+(AI$26/AI$25)) -> #DIV/0! | AL29: =(100-AL$31-AL$32)/(1+(AL$26/AL$25)) -> 86.822787 | AM29: =(100-AM$31-AM$32)/(1+(AM$26/AM$25)) -> 86.870683 | AN29: =(100-AN$31-AN$32)/(1+(AN$26/AN$25)) -> 86.662852 | AQ29: =AVERAGE(AL29:AM29) -> 86.846735
D30: HN | F30: %wt | G30: =G29*(G26/G25) -> 9.7430342 | H30: =H$29*(H$26/H$25) -> #DIV/0! | I30: =I$29*(I$26/I$25) -> 13.353376 | J30: =J$29*(J$26/J$25) -> 13.462713 | K30: =K$29*(K$26/K$25) -> 13.308525 | L30: =L$29*(L$26/L$25) -> 13.046253 | M30: =M$29*(M$26/M$25) -> 13.422434 | N30: =N$29*(N$26/N$25) -> 12.980327 | O30: =O$29*(O$26/O$25) -> 13.250974 | ... AI30: =AI$29*(AI$26/AI$25) -> #DIV/0! | AL30: =AL$29*(AL$26/AL$25) -> 13.019 | AM30: =AM$29*(AM$26/AM$25) -> 12.850693 | AN30: =AN$29*(AN$26/AN$25) -> 13.136139 | AQ30: =AVERAGE(AL30:AM30) -> 12.934846
D31: NN | G31: =G23*100/G28 -> 0.32836002 | H31: =H$23*100/H$28 -> #DIV/0! | I31: =I$23*100/I$28 -> 0.045872952 | J31: =J$23*100/J$28 -> 0.048775072 | K31: =K$23*100/K$28 -> 0.054278413 | L31: =L$23*100/L$28 -> 0.055580422 | M31: =M$23*100/M$28 -> 0.047192283 | N31: =N$23*100/N$28 -> 0.054461799 | O31: =O$23*100/O$28 -> 0.054332959 | ... AI31: =AI$23*100/AI$28 -> #DIV/0! | AL31: =AL$23*100/AL$28 -> 0.055259272 | AM31: =AM$23*100/AM$28 -> 0.054755813 | AN31: =AN$23*100/AN$28 -> 0.056758819 | AQ31: =AVERAGE(AL31:AM31) -> 0.055007543
D32: SN | G32: =G18*100/G28 -> 5.9544474 | H32: =H$18*100/H$28 -> #DIV/0! | I32: =I$18*100/I$28 -> 0.16416445 | J32: =J$18*100/J$28 -> 0.17051448 | K32: =K$18*100/K$28 -> 0.15674706 | L32: =L$18*100/L$28 -> 0.13212441 | M32: =M$18*100/M$28 -> 0.089900479 | N32: =N$18*100/N$28 -> 0.10221511 | O32: =O$18*100/O$28 -> 0.10711865 | ... AI32: =AI$18*100/AI$28 -> #DIV/0! | AL32: =AL$18*100/AL$28 -> 0.10295417 | AM32: =AM$18*100/AM$28 -> 0.22386895 | AN32: =AN$18*100/AN$28 -> 0.14424986 | AQ32: =AVERAGE(AL32:AM32) -> 0.16341156
D33: HN/CN | G33: =G30/G29 -> 0.1160242 | H33: =H$30/H$29 -> #DIV/0! | I33: =I$30/I$29 -> 0.15448755 | J33: =J$30/J$29 -> 0.15596646 | K33: =K$30/K$29 -> 0.15389056 | L33: =L$30/L$29 -> 0.15036128 | M33: =M$30/M$29 -> 0.1552795 | N33: =N$30/N$29 -> 0.14943448 | O33: =O$30/O$29 -> 0.15303551 | ... AI33: =AI$30/AI$29 -> #DIV/0! | AL33: =AL$30/AL$29 -> 0.14994911 | AM33: =AM$30/AM$29 -> 0.14792899 | AN33: =AN$30/AN$29 -> 0.1515775 | AQ33: =AVERAGE(AL33:AM33) -> 0.14893905
D34: C | G34: =G25*100/G28 -> 83.865596 | AQ34: =AVERAGE(AL34:AM34) -> #DIV/0!
D35: H | G35: =G26*100/G28 -> 9.7304384 | AQ35: =AVERAGE(AL35:AM35) -> #DIV/0!
D36: N | G36: =G27*100/G28 -> 0.449518 | AQ36: =AVERAGE(AL36:AM36) -> #DIV/0!
D37: S | G37: =G18*100/G28 -> 5.9544474 | AQ37: =AVERAGE(AL37:AM37) -> #DIV/0!
D38: H/C | G38: =G35/G34 -> 0.1160242 | AQ38: =AVERAGE(AL38:AM38) -> #DIV/0!
D39: Simdist | E39: ASTM D2887 ASTM D7169 | F39: deg.C | AQ39: =AVERAGE(AL39:AM39) -> #DIV/0!
D40: IBP | G40: 376 | H40: ='HPS LTO DAILY '!H116 -> 0 | I40: ='HPS LTO DAILY '!I116 -> 71.4 | J40: ='HPS LTO DAILY '!J116 -> 39 | K40: ='HPS LTO DAILY '!K116 -> 43.8 | L40: ='HPS LTO DAILY '!L116 -> 69.4 | M40: ='HPS LTO DAILY '!M116 -> 38.7 | N40: ='HPS LTO DAILY '!N116 -> 70.2 | O40: ='HPS LTO DAILY '!O116 -> 55.8 | ... X40: ='HPS LTO DAILY '!X116 -> 0 | Y40: ='HPS LTO DAILY '!AG116 -> 0 | Z40: ='HPS LTO DAILY '!AH116 -> 0 | AA40: ='HPS LTO DAILY '!AI116 -> 0 | AB40: ='HPS LTO DAILY '!AJ116 -> 0 | AC40: ='HPS LTO DAILY '!AK116 -> 0 | AD40: ='HPS LTO DAILY '!AL116 -> 0 | AE40: ='HPS LTO DAILY '!AM116 -> 0 | AF40: ='HPS LTO DAILY '!AN116 -> 0 | ... AI40: ='HPS LTO DAILY '!AQ116 -> 0 | AL40: ='HPS LTO DAILY '!AL116 -> 0 | AM40: ='HPS LTO DAILY '!AM116 -> 0 | AN40: ='HPS LTO DAILY '!AN116 -> 0 | AQ40: =AVERAGE(AL40:AM40) -> 0
...

Sheet ISV
D1: RHCU Pilot Plant Laboratory Worksheet
D2: Batch Name : | E2: MEBU2026'01
D3: Date :
D4: Note : | E4: Repeat Acceptance test | G4: CATALYST AGING | K4: CRACKING EXPERIMENT
G5: ABQ3358 (No3+No5)
G6: 1 | H6: 2 | I6: 3 | J6: 4 | K6: 5 | L6: 6 | M6: 7 | N6: 8 | O6: 9 | P6: 10 | Q6: 11 | R6: 12 | S6: 13 | T6: 14 | U6: 15 | V6: 16 | W6: 17 | X6: 18 | Y6: 19 | Z6: 20 | AA6: 21 | AB6: 22 | AC6: 23 | AD6: 24 | AE6: 25 | AF6: 26 | AG6: 27 | AH6: 28
D8: Properties | E8: Method | F8: Unit | G8: ISV | H8: ISV | I8: ISV | J8: ISV | K8: ISV | L8: ISV | M8: ISV | N8: ISV | O8: ISV | P8: ISV | Q8: ISV | R8: ISV | S8: ISV | T8: ISV | U8: ISV | V8: ISV | W8: ISV | X8: ISV | Y8: ISV | Z8: ISV | AA8: ISV | AB8: ISV | AC8: ISV | AD8: ISV | AE8: ISV | AF8: ISV | AG8: ISV | AH8: ISV
D9: Ratio | E9: - | F9: %wt.
D10: Weight | E10: - | F10: kg
D11: Density | E11: ASTM D4052 | F11: kg/L
D12: Relative Density@25/25 oC | E12: ASTM D70 | F12: -
D13: Viscosity @ -20 oC | E13: ASTM D445 | F13: cSt.
D14: Viscosity @ 40 oC
D15: Viscosity @ 70 oC
D16: Viscosity @ 100 oC
D17: Viscosity @ 150 oC
D18: V50
D19: Sulfur | E19: ASTM D4294 | F19: %wt | H19: 3.638 | K19: 4.25 | L19: 3.539
E20: ASTM D2622 | F20: %wt
F21: PPMw
D22: Total Nitrogen | E22: ASTM D4629 | F22: PPMw
E23: ASTM D5762 | F23: PPMw | K23: 3469
B24: 0.4519 | F24: %wt | G24: =G23/10000 -> 0 | H24: =H23/10000 -> 0 | I24: =I23/10000 -> 0 | J24: =J23/10000 -> 0 | K24: =K23/10000 -> 0.3469 | L24: =L23/10000 -> 0 | M24: =M23/10000 -> 0 | N24: =N23/10000 -> 0 | ... AH24: =AH23/10000 -> 0
D25: CHN | E25: ASTM D5291 | F25: %wt
D26: Carbon | K26: 86.31 | L26: 86.45
D27: Hydrogen | K27: 10.21 | L27: 10.57
D28: Nitrogen | K28: 0.4134 | L28: 0.3469
D29: CHNS | G29: =(G$26+G$27+G$24+G$19) -> 0 | H29: =(H$26+H$27+H$24+H$19) -> 3.638 | I29: =(I$26+I$27+I$24+I$19) -> 0 | J29: =(J$26+J$27+J$24+J$19) -> 0 | K29: =(K$26+K$27+K$24+K$19) -> 101.1169 | L29: =(L$26+L$27+L$24+L$19) -> 100.559 | M29: =(M$26+M$27+M$24+M$19) -> 0 | N29: =(N$26+N$27+N$24+N$19) -> 0 | ... AH29: =(AH$26+AH$27+AH$24+AH$19) -> 0
D30: CN | G30: =(100-G$32-G$33)/(1+(G$27/G$26)) -> #DIV/0! | H30: =(100-H$32-H$33)/(1+(H$27/H$26)) -> #DIV/0! | I30: =(100-I$32-I$33)/(1+(I$27/I$26)) -> #DIV/0! | J30: =(100-J$32-J$33)/(1+(J$27/J$26)) -> #DIV/0! | K30: =(100-K$32-K$33)/(1+(K$27/K$26)) -> 85.356652 | L30: =(100-L$32-L$33)/(1+(L$27/L$26)) -> 85.969431 | M30: =(100-M$32-M$33)/(1+(M$27/M$26)) -> #DIV/0! | N30: =(100-N$32-N$33)/(1+(N$27/N$26)) -> #DIV/0! | ... AH30: =(100-AH$32-AH$33)/(1+(AH$27/AH$26)) -> #DIV/0!
D31: HN | F31: %wt | G31: =G$30*(G$27/G$26) -> #DIV/0! | H31: =H$30*(H$27/H$26) -> #DIV/0! | I31: =I$30*(I$27/I$26) -> #DIV/0! | J31: =J$30*(J$27/J$26) -> #DIV/0! | K31: =K$30*(K$27/K$26) -> 10.097224 | L31: =L$30*(L$27/L$26) -> 10.511242 | M31: =M$30*(M$27/M$26) -> #DIV/0! | N31: =N$30*(N$27/N$26) -> #DIV/0! | ... AH31: =AH$30*(AH$27/AH$26) -> #DIV/0!
D32: NN | G32: =G$24*100/G$29 -> #DIV/0! | H32: =H$24*100/H$29 -> 0 | I32: =I$24*100/I$29 -> #DIV/0! | J32: =J$24*100/J$29 -> #DIV/0! | K32: =K$24*100/K$29 -> 0.34306827 | L32: =L$24*100/L$29 -> 0 | M32: =M$24*100/M$29 -> #DIV/0! | N32: =N$24*100/N$29 -> #DIV/0! | ... AH32: =AH$24*100/AH$29 -> #DIV/0!
D33: SN | G33: =G$19*100/G$29 -> #DIV/0! | H33: =H$19*100/H$29 -> 100 | I33: =I$19*100/I$29 -> #DIV/0! | J33: =J$19*100/J$29 -> #DIV/0! | K33: =K$19*100/K$29 -> 4.2030561 | L33: =L$19*100/L$29 -> 3.519327 | M33: =M$19*100/M$29 -> #DIV/0! | N33: =N$19*100/N$29 -> #DIV/0! | ... AH33: =AH$19*100/AH$29 -> #DIV/0!
D34: HN/CN | G34: =G$31/G$30 -> #DIV/0! | H34: =H$31/H$30 -> #DIV/0! | I34: =I$31/I$30 -> #DIV/0! | J34: =J$31/J$30 -> #DIV/0! | K34: =K$31/K$30 -> 0.11829452 | L34: =L$31/L$30 -> 0.12226721 | M34: =M$31/M$30 -> #DIV/0! | N34: =N$31/N$30 -> #DIV/0! | ... AH34: =AH$31/AH$30 -> #DIV/0!
D35: C
D36: H
D37: N
D38: S
D39: H/C
D40: ICP | E40: ASTM D7691 UOP 389 | F40: PPMw
D41: Nickle (Ni) | H41: 50.42 | K41: 94.75 | L41: 72.69 | Q41: 64.16
...

Sheet HPS DAILY
D1: RHCU Pilot Plant Laboratory Worksheet | BM1: Predict GC
D2: Batch Name : | E2: MEBU2026'01 | BM2: 560+ | BN2: m | BO2: x | BP2: c
D3: Date : | BL3: 24 | BM3: =(BN3*BO3)+BP3 -> 28.750752 | BN3: 630.52 | BO3: 0.9476 | BP3: -568.73
D4: Note : | E4: Repeat Acceptance test | K4: CATALYST AGING | O4: CRACKING EXPERIMENT | BL4: 26 | BM4: =(BN4*BO4)+BP4 -> 31.12576 | BN4: 697.6 | BO4: 0.9476 | BP4: -629.92
K5: ABQ3358 (No3+No5) | S5: Rx-3 Stuck | AN5: ABQ3358 (No3+No5) | BX5: Rx-3 Stuck
J6: Day on stream | K6: 1 | L6: 2 | M6: 3 | N6: 4 | O6: 5 | P6: 6 | Q6: 7 | R6: 8 | S6: 9 | T6: 10 | U6: 11 | V6: 12 | W6: 13 | X6: 14 | Y6: 15 | Z6: 16 | AA6: 17 | AB6: 18 | AC6: 19 | AD6: 20 | AE6: 21 | AF6: 22 | AG6: 23 | AH6: 24 | AI6: 25 | AJ6: 26 | AK6: 27 | AL6: 28 | AN6: 1 | AO6: 1 | AQ6: 1.5 | AR6: 2 | AU6: 3 | AV6: 3 | AW6: 3 | AY6: 4 | AZ6: 4 | BA6: 4 | BD6: 4.5 | BE6: 5 | BI6: D6 | BX6: 9 | BY6: 10 | CA6: 11
J7: Date | K7: Avg 8AM&8PM 24FEB | L7: At 08AM 04 MAR | S7: D9-1+2 | T7: D10 | U7: D11 | AN7: At 08:00 24 FEB | AO7: At 20:00 24 FEB | AR7: At 08AM 04 MAR | AU7: 0.58333333 | AV7: 0.83333333 | AW7: 0.33333333 | AY7: 0.54166667 | AZ7: 0.83333333 | BA7: 0.33333333 | BD7: 0.83333333 | BE7: 0.33333333 | BI7: 0.58333333 | BJ7: 0.33333333 | BN7: 1am | BO7: 8am | BU7: 9-1 | BV7: 9-2 | BX7: 10PM Sample | BY7: 9-2 | CA7: D10
D8: Properties | E8: Method | F8: Unit | G8: VR ABQ3358 | H8: VR ABQ3358 | I8: VR ABQ3358 | J8: VR ABQ3358 | K8: HPS | L8: HPS | M8: HPS | N8: HPS | O8: HPS | P8: HPS | Q8: HPS | R8: HPS | S8: HPS | T8: HPS | U8: HPS | V8: HPS | W8: HPS | X8: HPS | Y8: HPS | Z8: HPS | AA8: HPS | AB8: HPS | AC8: HPS | AD8: HPS | AE8: HPS | AF8: HPS | AG8: HPS | AH8: HPS | AI8: HPS | AJ8: HPS | AK8: HPS | AL8: HPS | AN8: HPS | AO8: HPS | AR8: HPS | AU8: HPS | BN8: D7 | BO8: D7 | BS8: D8 | BU8: D9 | BV8: D9 | BX8: HPS | BY8: HPS | CA8: HPS
D9: Ratio | E9: - | F9: %wt.
D10: API @ 15.6 degC | E10: - | G10: =(141.5/G11)-131.5 -> 2.7250047 | H10: =(141.5/H11)-131.5 -> 2.7250047 | I10: =(141.5/I11)-131.5 -> 2.7250047 | J10: =(141.5/J11)-131.5 -> 2.7250047 | K10: 13.26 | L10: 12.63 | M10: 11.93 | N10: 11.94 | O10: 18.44 | P10: 17.69 | Q10: 17.2 | R10: 16.96 | S10: 16.23 | T10: 16.47 | U10: 16.18 | V10: 16.05 | W10: 16 | AN10: 13.76 | AO10: 13.26 | AR10: 12.63 | AU10: 11.93 | BD10: 16.16 | BE10: 18.44 | BN10: 17.2 | BO10: 17.91 | BX10: 16.23 | BY10: 16.94 | CA10: 16.47
D11: Density @ 15.6 degC | E11: ASTM D4052 | F11: kg/L | G11: 1.0542 | H11: 1.0542 | I11: 1.0542 | J11: 1.0542 | K11: 0.9765 | L11: 0.9808 | M11: 0.9856 | N11: 0.9855 | O11: 0.9428 | P11: 0.9476 | Q11: 0.9501 | R11: 0.9522 | S11: 0.9569 | T11: 0.9563 | U11: 0.9572 | V11: 0.958 | W11: 0.9584 | AN11: 0.9732 | AO11: 0.9765 | AR11: 0.9808 | AU11: 0.9856 | AV11: 0.9855 | AW11: 0.9856 | AY11: 0.9853 | BA11: 0.9855 | BD11: 0.9568 | BE11: 0.9428 | BI11: 0.9464 | BJ11: 0.9476 | BN11: 0.9501 | BO11: 0.9456 | BX11: 0.9569 | BY11: 0.9523 | CA11: 0.9563
D12: Relative Density@25/25 oC | E12: ASTM D70 | F12: - | G12: 1.051 | H12: 1.051 | I12: 1.051 | J12: 1.051
D13: Viscosity @ -20 oC | E13: ASTM D445 | F13: cSt.
D14: Viscosity @ 40 oC
D15: Viscosity @ 70 oC
D16: Viscosity @ 100 oC
D17: Viscosity @ 135 °C
D18: Viscosity @ 150 oC | G18: 345.24 | H18: 345.24 | I18: 345.24 | J18: 345.24
D19: V50 | G19: 46.58 | H19: 46.58 | I19: 46.58 | J19: 46.58
D20: Sulfur | E20: ASTM D4294 | F20: %wt | G20: 5.975 | H20: 5.928 | I20: 5.928 | J20: 5.928 | K20: 1.9585 | L20: 2.0885 | M20: 2.28 | N20: 2.245 | O20: 0.867 | P20: 0.941 | Q20: 1.037 | R20: 1.121 | S20: 1.17 | T20: 1.214 | U20: 1.267 | V20: 1.291 | W20: 1.315 | AN20: 1.899 | AO20: 2.018 | AR20: 2.0885 | AU20: 2.277 | AV20: 2.271 | AW20: 2.28 | AY20: 2.258 | BA20: 2.245 | BD20: 1.332 | BE20: 0.867 | BX20: 1.165 | BY20: 1.174 | BZ20: =AVERAGE(BX20:BY20) -> 1.1695 | CA20: 1.214
E21: ASTM D2622 | F21: %wt | BZ21: =AVERAGE(BX21:BY21) -> #DIV/0!
F22: PPMw | BZ22: =AVERAGE(BX22:BY22) -> #DIV/0!
D23: Total Nitrogen | E23: ASTM D4629 | F23: PPMw | BZ23: =AVERAGE(BX23:BY23) -> #DIV/0!
E24: ASTM D5762 | F24: PPMw | G24: 3930.63 | H24: 4041.95 | I24: 4041.95 | J24: 4041.95 | K24: 2817 | L24: 2944.995 | M24: 3097.58 | N24: 3018.15 | O24: 2417 | P24: 2557.72 | Q24: 2664.55 | R24: 2562 | S24: 2610.51 | T24: 2543 | U24: 2775.885 | V24: 2593.16 | W24: 2669.55 | AN24: 3019.71 | AO24: 2817 | AR24: 2900.66 | BD24: 2629.03 | BE24: 2417.33 | BX24: 2610.51 | BY24: 2510.04 | BZ24: =AVERAGE(BX24:BY24) -> 2560.275 | CA24: 2543.47
B25: 0.4519 | F25: %wt | G25: =G24/10000 -> 0.393063 | H25: =H24/10000 -> 0.404195 | I25: =I24/10000 -> 0.404195 | J25: =J24/10000 -> 0.404195 | K25: 0.2817 | L25: =L24/10000 -> 0.2944995 | M25: =M24/10000 -> 0.309758 | N25: =N24/10000 -> 0.301815 | O25: =O24/10000 -> 0.2417 | P25: =P24/10000 -> 0.255772 | Q25: =Q24/10000 -> 0.266455 | R25: =R24/10000 -> 0.2562 | S25: =S24/10000 -> 0.261051 | ... AL25: =AL24/10000 -> 0 | AN25: =AN24/10000 -> 0.301971 | AO25: =AO24/10000 -> 0.2817 | AR25: =AR24/10000 -> 0.290066 | AU25: =AU24/10000 -> 0 | BD25: 0.262903 | BE25: 0.241733 | BX25: =BX24/10000 -> 0.261051 | BY25: =BY24/10000 -> 0.251004 | BZ25: =AVERAGE(BX25:BY25) -> 0.2560275 | CA25: =CA24/10000 -> 0.254347
D26: CHN | E26: ASTM D5291 | F26: %wt | BZ26: =AVERAGE(BX26:BY26) -> #DIV/0!
D27: Carbon | G27: 83.9 | H27: 83.9 | I27: 83.9 | J27: 83.9 | K27: 87.68 | L27: 86.89 | M27: 88.44 | N27: 88.09 | O27: 88.54 | P27: 88.37 | Q27: 89.16 | R27: 89.59 | S27: 89.41 | T27: 89.56 | U27: 89.12 | V27: 89.66 | W27: 88.78 | AN27: 87.82 | AO27: 87.68 | AR27: 86.89 | BD27: 88.05 | BE27: 88.54 | BX27: 89.41 | BY27: 89.58 | BZ27: =AVERAGE(BX27:BY27) -> 89.495 | CA27: 89.56
D28: Hydrogen | G28: 9.748 | H28: 9.748 | I28: 9.748 | J28: 9.748 | K28: 11.09 | L28: 10.74 | M28: 10.97 | N28: 10.92 | O28: 11.46 | P28: 11.4 | Q28: 11.25 | R28: 11.16 | S28: 11.17 | T28: 11.11 | U28: 11.11 | V28: 11.07 | W28: 11.19 | AN28: 11.06 | AO28: 11.09 | AR28: 10.74 | BD28: 11.31 | BE28: 11.46 | BX28: 11.17 | BY28: 11.21 | BZ28: =AVERAGE(BX28:BY28) -> 11.19 | CA28: 11.11
D29: Nitrogen | G29: 0.4384 | H29: 0.4384 | I29: 0.4384 | J29: 0.4384 | K29: 0.2988 | L29: 0.3359 | M29: 0.3459 | N29: 0.3469 | O29: 0.28 | P29: 0.2364 | Q29: 0.2202 | R29: 0.32 | S29: 0.3517 | T29: 0.32 | U29: 0.276 | V29: 0.364 | W29: 0.3578 | AN29: 0.286 | AO29: 0.2988 | AR29: 0.3359 | BD29: 0.3147 | BE29: 0.2772 | BX29: 0.3517 | BY29: 0.2922 | BZ29: =AVERAGE(BX29:BY29) -> 0.32195 | CA29: 0.3249
D30: CHNS | G30: =(G$27+G$28+G$25+G$20) -> 100.01606 | H30: =(H$27+H$28+H$25+H$20) -> 99.980195 | I30: =(I$27+I$28+I$25+I$20) -> 99.980195 | J30: =(J$27+J$28+J$25+J$20) -> 99.980195 | K30: =(K$27+K$28+K$25+K$20) -> 101.0102 | L30: =(L$27+L$28+L$25+L$20) -> 100.013 | M30: =(M$27+M$28+M$25+M$20) -> 101.99976 | N30: =(N$27+N$28+N$25+N$20) -> 101.55682 | ... AL30: =(AL$27+AL$28+AL$25+AL$20) -> 0 | AN30: =(AN$27+AN$28+AN$25+AN$20) -> 101.08097 | AO30: =(AO$27+AO$28+AO$25+AO$20) -> 101.0697 | AR30: =(AR$27+AR$28+AR$25+AR$20) -> 100.00857 | AU30: =(AU$27+AU$28+AU$25+AU$20) -> 2.277 | BD30: 100.9549 | BE30: 101.10873 | BX30: =(BX$27+BX$28+BX$25+BX$20) -> 102.00605 | BY30: =(BY$27+BY$28+BY$25+BY$20) -> 102.215 | BZ30: =AVERAGE(BX30:BY30) -> 102.11053 | CA30: =(CA$27+CA$28+CA$25+CA$20) -> 102.13835
D31: CN | G31: =(100-G$33-G$34)/(1+(G$28/G$27)) -> 83.886525 | H31: =(100-H$33-H$34)/(1+(H$28/H$27)) -> 83.91662 | I31: =(100-I$33-I$34)/(1+(I$28/I$27)) -> 83.91662 | J31: =(100-J$33-J$34)/(1+(J$28/J$27)) -> 83.91662 | K31: =(100-K$33-K$34)/(1+(K$28/K$27)) -> 86.803115 | L31: =(100-L$33-L$34)/(1+(L$28/L$27)) -> 86.878706 | M31: =(100-M$33-M$34)/(1+(M$28/M$27)) -> 86.706088 | N31: =(100-N$33-N$34)/(1+(N$28/N$27)) -> 86.739625 | ... AL31: =(100-AL$33-AL$34)/(1+(AL$28/AL$27)) -> #DIV/0! | AN31: =(100-AN$33-AN$34)/(1+(AN$28/AN$27)) -> 86.880843 | AO31: =(100-AO$33-AO$34)/(1+(AO$28/AO$27)) -> 86.752014 | AR31: =(100-AR$33-AR$34)/(1+(AR$28/AR$27)) -> 86.882558 | AU31: =(100-AU$33-AU$34)/(1+(AU$28/AU$27)) -> #DIV/0! | BD31: 87.217161 | BE31: 87.569093 | BX31: =(100-BX$33-BX$34)/(1+(BX$28/BX$27)) -> 87.651663 | BY31: =(100-BY$33-BY$34)/(1+(BY$28/BY$27)) -> 87.638797 | BZ31: =AVERAGE(BX31:BY31) -> 87.64523 | CA31: =(100-CA$33-CA$34)/(1+(CA$28/CA$27)) -> 87.684991
D32: HN | F32: %wt | G32: =G$31*(G$28/G$27) -> 9.7464344 | H32: =H$31*(H$28/H$27) -> 9.749931 | I32: =I$31*(I$28/I$27) -> 9.749931 | J32: =J$31*(J$28/J$27) -> 9.749931 | K32: =K$31*(K$28/K$27) -> 10.979089 | L32: =L$31*(L$28/L$27) -> 10.738604 | M32: =M$31*(M$28/M$27) -> 10.754927 | N32: =N$31*(N$28/N$27) -> 10.752602 | ... AL32: =AL$31*(AL$28/AL$27) -> #DIV/0! | AN32: =AN$31*(AN$28/AN$27) -> 10.941723 | AO32: =AO$31*(AO$28/AO$27) -> 10.972626 | AR32: =AR$31*(AR$28/AR$27) -> 10.73908 | AU32: =AU$31*(AU$28/AU$27) -> #DIV/0! | BD32: 11.203022 | BE32: 11.334333 | BX32: =BX$31*(BX$28/BX$27) -> 10.950331 | BY32: =BY$31*(BY$28/BY$27) -> 10.967079 | BZ32: =AVERAGE(BX32:BY32) -> 10.958705 | CA32: =CA$31*(CA$28/CA$27) -> 10.877403
D33: NN | G33: =G$25*100/G$30 -> 0.39299987 | H33: =H$25*100/H$30 -> 0.40427507 | I33: =I$25*100/I$30 -> 0.40427507 | J33: =J$25*100/J$30 -> 0.40427507 | K33: =K$25*100/K$30 -> 0.27888273 | L33: =L$25*100/L$30 -> 0.29446122 | M33: =M$25*100/M$30 -> 0.30368503 | N33: =N$25*100/N$30 -> 0.29718833 | ... AL33: =AL$25*100/AL$30 -> #DIV/0! | AN33: =AN$25*100/AN$30 -> 0.29874169 | AO33: =AO$25*100/AO$30 -> 0.27871855 | AR33: =AR$25*100/AR$30 -> 0.29004116 | AU33: =AU$25*100/AU$30 -> 0 | BD33: 0.26041628 | BE33: 0.23908222 | BX33: =BX$25*100/BX$30 -> 0.25591717 | BY33: =BY$25*100/BY$30 -> 0.24556473 | BZ33: =AVERAGE(BX33:BY33) -> 0.25074095 | CA33: =CA$25*100/CA$30 -> 0.24902204
D34: SN | G34: =G$20*100/G$30 -> 5.9740404 | H34: =H$20*100/H$30 -> 5.9291743 | I34: =I$20*100/I$30 -> 5.9291743 | J34: =J$20*100/J$30 -> 5.9291743 | K34: =K$20*100/K$30 -> 1.9389131 | L34: =L$20*100/L$30 -> 2.0882285 | M34: =M$20*100/M$30 -> 2.2352994 | N34: =N$20*100/N$30 -> 2.2105853 | ... AL34: =AL$20*100/AL$30 -> #DIV/0! | AN34: =AN$20*100/AN$30 -> 1.8786919 | AO34: =AO$20*100/AO$30 -> 1.9966419 | AR34: =AR$20*100/AR$30 -> 2.0883211 | AU34: =AU$20*100/AU$30 -> 100 | BD34: 1.319401 | BE34: 0.8574927 | BX34: =BX$20*100/BX$30 -> 1.1420891 | BY34: =BY$20*100/BY$30 -> 1.1485594 | BZ34: =AVERAGE(BX34:BY34) -> 1.1453242 | CA34: =CA$20*100/CA$30 -> 1.188584
D35: HN/CN | G35: =G$32/G$31 -> 0.11618594 | H35: =H$32/H$31 -> 0.11618594 | I35: =I$32/I$31 -> 0.11618594 | J35: =J$32/J$31 -> 0.11618594 | K35: =K$32/K$31 -> 0.12648266 | L35: =L$32/L$31 -> 0.12360456 | M35: =M$32/M$31 -> 0.1240389 | N35: =N$32/N$31 -> 0.12396413 | ... AL35: =AL$32/AL$31 -> #DIV/0! | AN35: =AN$32/AN$31 -> 0.12593942 | AO35: =AO$32/AO$31 -> 0.12648266 | AR35: =AR$32/AR$31 -> 0.12360456 | AU35: =AU$32/AU$31 -> #DIV/0! | BD35: 0.12844974 | BE35: 0.12943302 | BX35: =BX$32/BX$31 -> 0.1249301 | BY35: =BY$32/BY$31 -> 0.12513954 | BZ35: =AVERAGE(BX35:BY35) -> 0.12503482 | CA35: =CA$32/CA$31 -> 0.12405092
D36: C | G36: =G27*100/G30 -> 83.886525 | H36: =H27*100/H30 -> 83.91662 | I36: =I27*100/I30 -> 83.91662 | J36: =J27*100/J30 -> 83.91662 | BZ36: =AVERAGE(BX36:BY36) -> #DIV/0!
D37: H | G37: =G28*100/G30 -> 9.7464344 | H37: =H28*100/H30 -> 9.749931 | I37: =I28*100/I30 -> 9.749931 | J37: =J28*100/J30 -> 9.749931 | BZ37: =AVERAGE(BX37:BY37) -> #DIV/0!
D38: N | G38: =G29*100/G30 -> 0.43832959 | H38: =H29*100/H30 -> 0.43848684 | I38: =I29*100/I30 -> 0.43848684 | J38: =J29*100/J30 -> 0.43848684 | BZ38: =AVERAGE(BX38:BY38) -> #DIV/0!
D39: S | G39: =G20*100/G30 -> 5.9740404 | H39: =H20*100/H30 -> 5.9291743 | I39: =I20*100/I30 -> 5.9291743 | J39: =J20*100/J30 -> 5.9291743 | BZ39: =AVERAGE(BX39:BY39) -> #DIV/0!
D40: H/C | G40: =G37/G36 -> 0.11618594 | H40: =H37/H36 -> 0.11618594 | I40: =I37/I36 -> 0.11618594 | J40: =J37/J36 -> 0.11618594 | BZ40: =AVERAGE(BX40:BY40) -> #DIV/0!
...

Sheet HPS LTO DAILY 
D1: RHCU Pilot Plant Laboratory Worksheet
D2: Batch Name : | F2: MEBU2026'01
D3: Date :
D4: Note : | F4: Repeat Acceptance test
AX5: LS_D3 ART
H6: ABQ3358 (No.3&5) | AX6: 01WT% | AY6: 1 | AZ6: 170.44444
G7: FEED | H7: 1 | I7: 2 | J7: 3 | K7: 4 | L7: 5 | M7: 6 | N7: 7 | O7: 8 | P7: 9 | Q7: 10 | R7: 11 | S7: 12 | T7: 13 | U7: 14 | V7: 15 | W7: 16 | X7: 17 | Y7: 18 | Z7: 19 | AA7: 20 | AB7: 21 | AC7: 22 | AD7: 23 | AE7: 24 | AF7: 25 | AG7: 26 | AH7: 27 | AI7: 28 | AX7: 02WT% | AY7: 2 | AZ7: 197.11111
D8: HPS | G8: ABQ3358 | H8: {='Master Template'!F5:AG5} -> 46077 | I8: 46078 | J8: #VALUE! | K8: #VALUE! | L8: #VALUE! | M8: #VALUE! | N8: #VALUE! | O8: #VALUE! | P8: #VALUE! | Q8: #VALUE! | R8: #VALUE! | S8: 1 | T8: 1 | U8: 1 | V8: 1 | W8: 1 | X8: 1 | Y8: 1 | Z8: 1 | AA8: 1 | AB8: 1 | AC8: 1 | AD8: 0 | AE8: 0 | AF8: 0 | AG8: 0 | AH8: 0 | AI8: 0 | AX8: 03WT% | AY8: 3 | AZ8: 216.05556
D9: SIMDIST | E9: 500 | F9: 560 | G9: FEED | I9: D2 | J9: D3 | K9: D4 | L9: D5 | M9: D6 | N9: D7 | O9: D8 | P9: D9 | Q9: D9-2 | R9: D10 | S9: D12 | T9: D13 | AJ9: HPS API (Degree) | AK9: 4.5 | AL9: -5 | AX9: 04WT% | AY9: 4 | AZ9: 230.11111
D10: 0 | E10: 500 | F10: 560 | G10: 312.8 | H10: 153.4 | I10: 140.2 | J10: 158.7 | K10: 156 | L10: 114.8 | M10: 130.7 | N10: 130.1 | O10: 131.8 | P10: 149.3 | Q10: 135 | R10: 133.1 | S10: 136.2 | T10: 132.6 | AK10: 4.5 | AL10: 105 | AT10: 0 | AU10: 560 | AX10: 05WT% | AY10: 5 | AZ10: 243.72222
D11: 1 | E11: 500 | F11: 560 | G11: 351.4 | H11: 188.1 | I11: 179 | J11: 192.8 | K11: 188.3 | L11: 136.6 | M11: 148.3 | N11: 147.6 | O11: 150.6 | P11: 165.4 | Q11: 153.6 | R11: 152.3 | S11: 155.9 | T11: 154.1 | AJ11: 12.4 | AK11: 10.5 | AT11: 120 | AU11: 560 | AX11: 06WT% | AY11: 6 | AZ11: 254.66667
D12: 2 | E12: 500 | F12: 560 | G12: 389.4 | H12: 226.9 | I12: 220.7 | J12: 227.2 | K12: 222 | L12: 162.6 | M12: 169.4 | N12: 169.2 | O12: 173 | P12: 186.9 | Q12: 177.2 | R12: 176.4 | S12: 179.2 | T12: 177.9 | AJ12: 12.2 | AK12: 10.5 | AX12: 07WT% | AY12: 7 | AZ12: 265.83333
D13: 3 | E13: 500 | F13: 560 | G13: 417.2 | H13: 256 | I13: 247.3 | J13: 252.8 | K13: 244.3 | L13: 182.5 | M13: 185 | N13: 185.1 | O13: 187.1 | P13: 202.1 | Q13: 195 | R13: 194.2 | S13: 196.9 | T13: 195.8 | AJ13: 11.5 | AX13: 08WT% | AY13: 8 | AZ13: 275.55556
D14: 4 | E14: 500 | F14: 560 | G14: 443.3 | H14: 281.5 | I14: 269.8 | J14: 275.4 | K14: 264.9 | L14: 198.3 | M14: 198.7 | N14: 199.1 | O14: 200.7 | P14: 214.3 | Q14: 206.3 | R14: 205.5 | S14: 207.9 | T14: 207.2 | AJ14: 11.3 | AT14: 0 | AU14: 160 | AX14: 09WT% | AY14: 9 | AZ14: 285.94444
D15: 5 | E15: 500 | F15: 560 | G15: 468.2 | H15: 301.5 | I15: 290.8 | J15: 295.8 | K15: 283.3 | L15: 209.6 | M15: 208.3 | N15: 209.4 | O15: 212.7 | P15: 223.4 | Q15: 217.4 | R15: 216.9 | S15: 218.6 | T15: 218.2 | AJ15: 16 | AT15: 120 | AU15: 160 | AX15: 10WT% | AY15: 10 | AZ15: 293.94444
D16: 6 | E16: 500 | F16: 560 | G16: 490.8 | H16: 318.3 | I16: 307.5 | J16: 312.9 | K16: 299.9 | L16: 219.3 | M16: 218 | N16: 219 | O16: 221.5 | P16: 231.3 | Q16: 225.6 | R16: 225.3 | S16: 227.2 | T16: 226.7 | AJ16: 15.8 | AX16: 11WT% | AY16: 11 | AZ16: 301.94444
D17: 7 | E17: 500 | F17: 560 | G17: 507.6 | H17: 332.8 | I17: 322.5 | J17: 327.9 | K17: 314.6 | L17: 227.7 | M17: 225.5 | N17: 226.9 | O17: 229.7 | P17: 241.2 | Q17: 233.7 | R17: 233.4 | S17: 235.7 | T17: 235.3 | AJ17: 15.8 | AT17: 0 | AU17: 360 | AX17: 12WT% | AY17: 12 | AZ17: 309.33333
D18: 8 | E18: 500 | F18: 560 | G18: 519.5 | H18: 345.8 | I18: 336 | J18: 341.7 | K18: 328.2 | L18: 235.7 | M18: 232.6 | N18: 234.4 | O18: 238.2 | P18: 249.7 | Q18: 243.5 | R18: 243.3 | S18: 244.8 | T18: 244.2 | AJ18: 15.8 | AT18: 120 | AU18: 360 | AX18: 13WT% | AY18: 13 | AZ18: 316.44444
D19: 9 | E19: 500 | F19: 560 | G19: 528.6 | H19: 357 | I19: 348.4 | J19: 354.5 | K19: 340.8 | L19: 244.4 | M19: 241.6 | N19: 243.6 | O19: 247.1 | P19: 258.6 | Q19: 251.8 | R19: 251.2 | S19: 253.5 | T19: 252 | AJ19: 15.7 | AX19: 14WT% | AY19: 14 | AZ19: 323.94444
D20: 10 | E20: 500 | F20: 560 | G20: 535.8 | H20: 367.4 | I20: 359.3 | J20: 365.9 | K20: 352.6 | L20: 252.5 | M20: 249.7 | N20: 251.4 | O20: 255.4 | P20: 266.3 | Q20: 260.1 | R20: 259.2 | S20: 261.2 | T20: 258.8 | AJ20: 15.7 | AT20: 0 | AU20: 560 | AX20: 15WT% | AY20: 15 | AZ20: 330.77778
D21: 11 | E21: 500 | F21: 560 | G21: 541.1 | H21: 376.4 | I21: 369.5 | J21: 375.7 | K21: 363 | L21: 260.3 | M21: 257.5 | N21: 259.5 | O21: 263.1 | P21: 274.1 | Q21: 267.5 | R21: 266 | S21: 268.4 | T21: 264.9 | AJ21: 15.6 | AT21: 120 | AU21: 560 | AX21: 16WT% | AY21: 16 | AZ21: 338.05556
D22: 12 | E22: 500 | F22: 560 | G22: 546 | H22: 384.1 | I22: 378.5 | J22: 384.8 | K22: 372.7 | L22: 267.7 | M22: 264.7 | N22: 266.6 | O22: 270.1 | P22: 282 | Q22: 275.7 | R22: 273.7 | S22: 276.2 | T22: 271.7 | AJ22: 15 | AX22: 17WT% | AY22: 17 | AZ22: 344.66667
D23: 13 | E23: 500 | F23: 560 | G23: 551.1 | H23: 391.4 | I23: 386.6 | J23: 393.7 | K23: 381.3 | L23: 275.4 | M23: 271.2 | N23: 274.1 | O23: 277.6 | P23: 289 | Q23: 283 | R23: 281.3 | S23: 283.2 | T23: 278.6 | AJ23: 15.6 | AX23: 18WT% | AY23: 18 | AZ23: 351.44444
D24: 14 | E24: 500 | F24: 560 | G24: 555.7 | H24: 399.5 | I24: 394.8 | J24: 403 | K24: 389.4 | L24: 282.6 | M24: 278 | N24: 281.6 | O24: 284.8 | P24: 295.8 | Q24: 290.5 | R24: 288.3 | S24: 290.6 | T24: 285.1 | AJ24: 15.6 | AX24: 19WT% | AY24: 19 | AZ24: 357.22222
D25: 15 | E25: 500 | F25: 560 | G25: 559.6 | H25: 407.7 | I25: 403 | J25: 411.9 | K25: 398.3 | L25: 289.9 | M25: 284.8 | N25: 288.2 | O25: 291.6 | P25: 301.6 | Q25: 297.6 | R25: 294.8 | S25: 297.3 | T25: 291.5 | AJ25: 15 | AX25: 20WT% | AY25: 20 | AZ25: 363.72222
D26: 16 | E26: 500 | F26: 560 | G26: 563.2 | H26: 414.8 | I26: 411.5 | J26: 419.9 | K26: 407 | L26: 296.8 | M26: 291.2 | N26: 294.3 | O26: 298.1 | P26: 308.2 | Q26: 304.1 | R26: 300.8 | S26: 303.7 | T26: 297.4 | AJ26: 15.1 | AX26: 21WT% | AY26: 21 | AZ26: 369.5
D27: 17 | E27: 500 | F27: 560 | G27: 566.6 | H27: 421.2 | I27: 418.5 | J27: 427.2 | K27: 415 | L27: 303.4 | M27: 297.8 | N27: 300 | O27: 304.6 | P27: 314 | Q27: 310.7 | R27: 307.4 | S27: 310 | T27: 304.1 | AX27: 22WT% | AY27: 22 | AZ27: 375.66667
D28: 18 | E28: 500 | F28: 560 | G28: 569.7 | H28: 427.5 | I28: 425.2 | J28: 434.8 | K28: 422.2 | L28: 310.1 | M28: 303.2 | N28: 306.5 | O28: 310.9 | P28: 320.4 | Q28: 316.3 | R28: 313.2 | S28: 315.5 | T28: 310.5 | AX28: 23WT% | AY28: 23 | AZ28: 381.33333
D29: 19 | E29: 500 | F29: 560 | G29: 572.7 | H29: 433.9 | I29: 431.6 | J29: 442.4 | K29: 429 | L29: 315.8 | M29: 309.1 | N29: 312.8 | O29: 316.2 | P29: 326.8 | Q29: 322.7 | R29: 319.4 | S29: 321.7 | T29: 315.9 | AX29: 24WT% | AY29: 24 | AZ29: 387.44444
D30: 20 | E30: 500 | F30: 560 | G30: 575.6 | H30: 440.4 | I30: 438.9 | J30: 449.8 | K30: 436.5 | L30: 322.3 | M30: 314.4 | N30: 318.1 | O30: 322.4 | P30: 332 | Q30: 328.4 | R30: 325.8 | S30: 327.3 | T30: 322.1 | AX30: 25WT% | AY30: 25 | AZ30: 392.88889
D31: 21 | E31: 500 | F31: 560 | G31: 578.6 | H31: 446.9 | I31: 445.8 | J31: 456.7 | K31: 443.7 | L31: 328 | M31: 320.4 | N31: 324.1 | O31: 328 | P31: 337.9 | Q31: 334.6 | R31: 331.1 | S31: 333.2 | T31: 327.5 | AX31: 26WT% | AY31: 26 | AZ31: 398.72222
D32: 22 | E32: 500 | F32: 560 | G32: 581.5 | H32: 453.1 | I32: 452.2 | J32: 463.4 | K32: 450.7 | L32: 334.2 | M32: 326.2 | N32: 329.1 | O32: 333.7 | P32: 342.9 | Q32: 340.7 | R32: 337 | S32: 339 | T32: 333.7 | AX32: 27WT% | AY32: 27 | AZ32: 403.88889
D33: 23 | E33: 500 | F33: 560 | G33: 584.4 | H33: 458.9 | I33: 458.4 | J33: 470.3 | K33: 457.1 | L33: 339.9 | M33: 331 | N33: 334.8 | O33: 339.6 | P33: 348.2 | Q33: 345.7 | R33: 342.1 | S33: 343.9 | T33: 339.7 | AX33: 28WT% | AY33: 28 | AZ33: 409.44444
D34: 24 | E34: 500 | F34: 560 | G34: 587.3 | H34: 464.7 | I34: 464.7 | J34: 477.3 | K34: 463.4 | L34: 345.7 | M34: 336.5 | N34: 340.4 | O34: 344.4 | P34: 353.1 | Q34: 350.7 | R34: 347.5 | S34: 348.8 | T34: 344.7 | AX34: 29WT% | AY34: 29 | AZ34: 414.61111
D35: 25 | E35: 500 | F35: 560 | G35: 590.1 | H35: 471.1 | I35: 471.2 | J35: 483.9 | K35: 470 | L35: 351.5 | M35: 341.8 | N35: 345.2 | O35: 349.3 | P35: 357.1 | Q35: 355.1 | R35: 352.4 | S35: 353.2 | T35: 350.3 | AX35: 30WT% | AY35: 30 | AZ35: 420
D36: 26 | E36: 500 | F36: 560 | G36: 592.9 | H36: 477.3 | I36: 477.8 | J36: 489.9 | K36: 476.5 | L36: 356.4 | M36: 346.3 | N36: 349.8 | O36: 353.8 | P36: 361.8 | Q36: 359.7 | R36: 356.5 | S36: 357.6 | T36: 355.4 | AX36: 31WT% | AY36: 31 | AZ36: 424.94444
D37: 27 | E37: 500 | F37: 560 | G37: 595.7 | H37: 483.3 | I37: 483.9 | J37: 495.8 | K37: 482.8 | L37: 362 | M37: 350.8 | N37: 354.2 | O37: 358 | P37: 366.1 | Q37: 364.6 | R37: 361.1 | S37: 362.2 | T37: 360.5 | AX37: 32WT% | AY37: 32 | AZ37: 430.27778
D38: 28 | E38: 500 | F38: 560 | G38: 598.4 | H38: 488.9 | I38: 489.7 | J38: 501.6 | K38: 488.5 | L38: 367.1 | M38: 354.8 | N38: 358.3 | O38: 362.6 | P38: 370.9 | Q38: 369 | R38: 365.4 | S38: 366.4 | T38: 365.9 | AX38: 33WT% | AY38: 33 | AZ38: 435.33333
... D67: 57 | E67: 500 | F67: 560 | G67: 712.9 | H67: 604.9 | I67: 603.4 | J67: 610 | K67: 594 | L67: 508.7 | M67: 482.4 | N67: 487.9 | O67: 494.4 | P67: 504 | Q67: 504.6 | R67: 499.4 | S67: 498.3 | T67: 494.7 | AX67: 62WT% | AY67: 62 | AZ67: 566.27778
D68: 58 | E68: 500 | F68: 560 | G68: - | H68: 608.6 | I68: 606.9 | J68: 613.5 | K68: 596.8 | L68: 513.5 | M68: 486.8 | N68: 492.3 | O68: 498.7 | P68: 508.4 | Q68: 509.1 | R68: 503.8 | S68: 502.6 | T68: 499.2 | AX68: 63WT% | AY68: 63 | AZ68: 569.77778
...

Sheet Master Template
F2: VR | AM2: ISV | BL2: HPS: ABQ3358(Aging) | BP2: HPS | CO2: LTO | CS2: LTO | DS2: High Gas | DW2: High Gas | EV2: Low Gas | EZ2: Low Gas
F3: Aging-ABQ3358 | BL3: Aging-ABQ3358 | CO3: Aging-ABQ3358(Aging) | DS3: Aging-ABQ3358 | EV3: Aging- ABQ3358
C4: Pilot Plant Operation---> | F4: 46076 | G4: 46077 | H4: 04/03/2026 | I4: 05/03/2026 | J4: 07/03/2026 | K4: 08/03/2026 | L4: 09/03/2026 | M4: 10/03/2026 | N4: 13/03/2026 | O4: 14/03/2026 | P4: 15/03/2026
C5: Lab Date (Sample Day)--> | F5: =F4+1 -> 46077 | G5: =G4+1 -> 46078 | H5: =H4+1 -> #VALUE! | I5: =I4+1 -> #VALUE! | J5: =J4+1 -> #VALUE! | K5: =K4+1 -> #VALUE! | L5: =L4+1 -> #VALUE! | M5: =M4+1 -> #VALUE! | ... AA5: =AA4+1 -> 1
C6: Day on stream--> | F6: 1 | G6: 2 | H6: 3 | I6: 4 | J6: 5 | K6: 6 | L6: 7 | M6: 8 | N6: 9 | O6: 10 | P6: 11 | Q6: 12 | R6: 13 | S6: 14 | T6: 15 | U6: 16 | V6: 17 | W6: 18 | X6: 19 | Y6: 20 | Z6: 21 | AA6: 22 | AB6: 23 | AC6: 24 | AD6: 25 | AE6: 26 | AF6: 27 | AG6: 28 | AI6: 1 | AJ6: 2 | AK6: 3 | AL6: 4 | AM6: 5 | AN6: 6 | AO6: 7 | AP6: 8 | AQ6: 9 | AR6: 10 | AS6: 11 | AT6: 12 | AU6: 13 | AV6: 14 | AW6: 15 | AX6: 16 | AY6: 17 | AZ6: 18 | BA6: 19 | BB6: 20 | BC6: 21 | BD6: 22 | BE6: 23 | BF6: 24 | BG6: 25 | BH6: 26 | BI6: 27 | BJ6: 28 | BL6: 1 | BM6: 2 | BN6: 3 | BO6: 4 | BP6: 5 | BQ6: 6 | BR6: 7 | BS6: 8 | BT6: 9 | BU6: 10 | BV6: 11 | BW6: 12 | BX6: 13 | BY6: 14 | BZ6: 15 | CA6: 16 | CB6: 17 | CC6: 18 | CD6: 19 | CE6: 20 | CF6: 21 | CG6: 22 | CH6: 23 | CI6: 24 | CJ6: 25 | CK6: 26 | CL6: 27 | CM6: 28 | CO6: 1 | CP6: 2 | CQ6: 3 | CR6: 4 | CS6: 5 | CT6: 6 | CU6: 7 | CV6: 8 | CW6: 9 | CX6: 10 | CY6: 11 | CZ6: 12 | DA6: 13 | DB6: 14 | DC6: 15 | DD6: 16 | DE6: 17 | DF6: 18 | DG6: 19 | DH6: 20 | DI6: 21 | DJ6: 22 | DK6: 23 | DL6: 24 | DM6: 25 | DN6: 26 | DO6: 27 | DP6: 28 | DS6: 1 | DT6: 2 | DU6: 3 | DV6: 4 | DW6: 5 | DX6: 6 | DY6: 7 | DZ6: 8 | EA6: 9 | EB6: 10 | EC6: 11 | ED6: 12 | EE6: 13 | EF6: 14 | EG6: 15 | EH6: 16 | EI6: 17 | EJ6: 18 | EK6: 19 | EL6: 20 | EM6: 21 | EN6: 22 | EO6: 23 | EP6: 24 | EQ6: 25 | ER6: 26 | ES6: 27 | ET6: 28 | EV6: 1 | EW6: 2 | EX6: 3 | EY6: 4 | EZ6: 5 | FA6: 6 | FB6: 7 | FC6: 8 | FD6: 9 | FE6: 10 | FF6: 11 | FG6: 12 | FH6: 13 | FI6: 14 | FJ6: 15 | FK6: 16 | FL6: 17 | FM6: 18 | FN6: 19 | FO6: 20 | FP6: 21 | FQ6: 22 | FR6: 23 | FS6: 24 | FT6: 25 | FU6: 26 | FV6: 27 | FW6: 28
F7: %wt | J7: %wt | P7: %wt | AI7: %wt | AM7: %wt | AS7: %wt | BL7: %wt | BP7: %wt | BV7: %wt | CO7: %wt | CS7: %wt | CY7: %wt | DS7: %wt | DW7: %wt | EC7: %wt | EV7: %vol(mol) | EZ7: %vol(mol) | FF7: %vol(mol)
C8: IBP-90 | F8: {='HPS DAILY'!$G$66:$G$73} -> 0 | G8: {='HPS DAILY'!$G$66:$G$73} -> 0 | H8: {='HPS DAILY'!$G$66:$G$73} -> 0 | I8: {='HPS DAILY'!$G$66:$G$73} -> 0 | J8: {='HPS DAILY'!$H$66:$H$73} -> 0 | K8: {='HPS DAILY'!$H$66:$H$73} -> 0 | L8: {='HPS DAILY'!$H$66:$H$73} -> 0 | M8: {='HPS DAILY'!$H$66:$H$73} -> 0 | N8: {='HPS DAILY'!$H$66:$H$73} -> 0 | O8: {='HPS DAILY'!$H$66:$H$73} -> 0 | P8: {='HPS DAILY'!$H$66:$H$73} -> 0 | Q8: {='HPS DAILY'!$H$66:$H$73} -> 0 | ... W8: {='HPS DAILY'!$H$66:$H$73} -> 0 | X8: {='HPS DAILY'!$G$66:$G$73} -> 0 | Y8: {='HPS DAILY'!$G$66:$G$73} -> 0 | Z8: {='HPS DAILY'!$G$66:$G$73} -> 0 | AA8: {='HPS DAILY'!$G$66:$G$73} -> 0 | AB8: {='HPS DAILY'!$J$66:$J$73} -> 0 | AC8: {='HPS DAILY'!$J$66:$J$73} -> 0 | AD8: {='HPS DAILY'!$J$66:$J$73} -> 0 | AE8: {='HPS DAILY'!$J$66:$J$73} -> 0 | AF8: {='HPS DAILY'!$J$66:$J$73} -> 0 | AG8: {='HPS DAILY'!$J$66:$J$73} -> 0 | AI8: {=ISV!G65:G$72} -> 0 | AJ8: {=ISV!H65:H$72} -> 0.2 | AK8: {=ISV!I65:I$72} -> 0 | AL8: {=ISV!J65:J$72} -> 0 | AM8: {=ISV!K65:K$72} -> 0 | AN8: {=ISV!L65:L$72} -> 0 | AO8: {=ISV!M65:M$72} -> 0 | AP8: {=ISV!N65:N$72} -> 0 | ... BJ8: {=ISV!AH65:AH$72} -> 0 | BL8: {='HPS DAILY'!K$66:K$73} -> 0.116 | BM8: {='HPS DAILY'!L$66:L$73} -> 0.146 | BN8: {='HPS DAILY'!M$66:M$73} -> 0.073666667 | BO8: {='HPS DAILY'!N$66:N$73} -> 0.051 | BP8: {='HPS DAILY'!O$66:O$73} -> 0.034 | BQ8: {='HPS DAILY'!P$66:P$73} -> 0.044 | BR8: {='HPS DAILY'!Q$66:Q$73} -> 0.048 | BS8: {='HPS DAILY'!R$66:R$73} -> 0.031 | ... CM8: {='HPS DAILY'!AL$66:AL$73} -> 0 | CO8: {='LTO DAILY'!H$55:H$62} -> 0 | CP8: {='LTO DAILY'!I$55:I$62} -> 1.2 | CQ8: {='LTO DAILY'!J$55:J$62} -> 4.3 | CR8: {='LTO DAILY'!K$55:K$62} -> 4.1 | CS8: {='LTO DAILY'!L$55:L$62} -> 1.5 | CT8: {='LTO DAILY'!M$55:M$62} -> 4.2 | CU8: {='LTO DAILY'!N$55:N$62} -> 1.1 | CV8: {='LTO DAILY'!O$55:O$62} -> 2.2 | ... DP8: {='LTO DAILY'!AI$55:AI$62} -> 0 | DR8: H2 | DS8: {='HPS DAILY'!K106:K112} -> 59.08 | DT8: {='HPS DAILY'!L106:L112} -> 73.825 | DU8: {='HPS DAILY'!M106:M112} -> 72.11 | DV8: {='HPS DAILY'!N106:N112} -> 73.02 | DW8: {='HPS DAILY'!O106:O112} -> 49.76 | DX8: {='HPS DAILY'!P106:P112} -> 79.96 | DY8: {='HPS DAILY'!Q106:Q112} -> 51.72 | DZ8: {='HPS DAILY'!R106:R112} -> 51.87 | ... ET8: {='HPS DAILY'!AL106:AL112} -> 0 | EV8: {='HPS DAILY'!K$93:K$99} -> 18.73 | EW8: =EX8 -> 2.51 | EX8: {='HPS DAILY'!M$93:M$99} -> 2.51 | EY8: {='HPS DAILY'!N$93:N$99} -> 1.03 | EZ8: {='HPS DAILY'!O$93:O$99} -> 1.29 | FA8: {='HPS DAILY'!P$93:P$99} -> 1.42 | FB8: {='HPS DAILY'!Q$93:Q$99} -> 1.61 | FC8: {='HPS DAILY'!R$93:R$99} -> 0.96 | FD8: {='HPS DAILY'!S$93:S$99} -> 1.66 | FE8: {='HPS DAILY'!T$93:T$99} -> 1.29 | ... FW8: {='HPS DAILY'!AL$93:AL$99} -> 0 | FX8: H2
C9: 90-160 | F9: 0 | G9: 0 | H9: 0 | I9: 0 | J9: 0 | K9: 0 | L9: 0 | M9: 0 | N9: 0 | O9: 0 | P9: 0 | Q9: 0 | R9: 0 | S9: 0 | T9: 0 | U9: 0 | V9: 0 | W9: 0 | X9: 0 | Y9: 0 | Z9: 0 | AA9: 0 | AB9: 0 | AC9: 0 | AD9: 0 | AE9: 0 | AF9: 0 | AG9: 0 | AI9: 0 | AJ9: 12.389 | AK9: 0 | AL9: 0 | AM9: 0 | AN9: 0 | AO9: 0 | AP9: 0 | AQ9: 0 | AR9: 0 | AS9: 0 | AT9: 0 | AU9: 0 | AV9: 0 | AW9: 0 | AX9: 0 | AY9: 0 | AZ9: 0 | BA9: 0 | BB9: 0 | BC9: 0 | BD9: 0 | BE9: 0 | BF9: 0 | BG9: 0 | BH9: 0 | BI9: 0 | BJ9: 0 | BL9: 0.508 | BM9: 0.49 | BN9: 0.462 | BO9: 0.496 | BP9: 1.42 | BQ9: 1.446 | BR9: 1.454 | BS9: 1.411 | BT9: 1.0025 | BU9: 1.212 | BV9: 1.112 | BW9: 1.089 | BX9: 1.095 | BY9: 0 | BZ9: 0 | CA9: 0 | CB9: 0 | CC9: 0 | CD9: 0 | CE9: 0 | CF9: 0 | CG9: 0 | CH9: 0 | CI9: 0 | CJ9: 0 | CK9: 0 | CL9: 0 | CM9: 0 | CO9: 0 | CP9: 19.2 | CQ9: 18.7 | CR9: 20.1 | CS9: 17 | CT9: 19.8 | CU9: 14.5 | CV9: 16.6 | CW9: 15.125 | CX9: 16.4 | CY9: 14.7 | CZ9: 16.7 | DA9: 16.4 | DB9: 0 | DC9: 0 | DD9: 0 | DE9: 0 | DF9: 0 | DG9: 0 | DH9: 0 | DI9: 0 | DJ9: 0 | DK9: 0 | DL9: 0 | DM9: 0 | DN9: 0 | DO9: 0 | DP9: 0 | DR9: CH4 | DS9: 5.22 | DT9: 5.795 | DU9: 6.47 | DV9: 6.75 | DW9: 14.86 | DX9: 14.57 | DY9: 13.73 | DZ9: 13.88 | EA9: 13.88 | EB9: 13.33 | EC9: 13.77 | ED9: 13.56 | EE9: 13.7 | EF9: 0 | EG9: 0 | EH9: 0 | EI9: 0 | EJ9: 0 | EK9: 0 | EL9: 0 | EM9: 0 | EN9: 0 | EO9: 0 | EP9: 0 | EQ9: 0 | ER9: 0 | ES9: 0 | ET9: 0 | EV9: 0.74 | EW9: =EX9 -> 0.06 | EX9: 0.06 | EY9: 0.03 | EZ9: 0.08 | FA9: 0.17 | FB9: 0.18 | FC9: 0.05 | FD9: 0.14 | FE9: 0.08 | FF9: 0.03 | FG9: 0.04 | FH9: 0.14 | FI9: 0 | FJ9: 0 | FK9: 0 | FL9: 0 | FM9: 0 | FN9: 0 | FO9: 0 | FP9: 0 | FQ9: 0 | FR9: 0 | FS9: 0 | FT9: 0 | FU9: 0 | FV9: 0 | FW9: 0 | FX9: CH4
C10: 160-250 | F10: 0 | G10: 0 | H10: 0 | I10: 0 | J10: 0 | K10: 0 | L10: 0 | M10: 0 | N10: 0 | O10: 0 | P10: 0 | Q10: 0 | R10: 0 | S10: 0 | T10: 0 | U10: 0 | V10: 0 | W10: 0 | X10: 0 | Y10: 0 | Z10: 0 | AA10: 0 | AB10: 0 | AC10: 0 | AD10: 0 | AE10: 0 | AF10: 0 | AG10: 0 | AI10: 0 | AJ10: 1.609 | AK10: 0 | AL10: 0 | AM10: 0 | AN10: 0 | AO10: 0 | AP10: 0 | AQ10: 0 | AR10: 0 | AS10: 0 | AT10: 0 | AU10: 0 | AV10: 0 | AW10: 0 | AX10: 0 | AY10: 0 | AZ10: 0 | BA10: 0 | BB10: 0 | BC10: 0 | BD10: 0 | BE10: 0 | BF10: 0 | BG10: 0 | BH10: 0 | BI10: 0 | BJ10: 0 | BL10: 2.4005 | BM10: 2.302 | BN10: 2.344 | BO10: 2.733 | BP10: 8.318 | BQ10: 8.582 | BR10: 8.332 | BS10: 8.017 | BT10: 7.4415 | BU10: 7.629 | BV10: 7.645 | BW10: 7.537 | BX10: 7.6 | BY10: 0 | BZ10: 0 | CA10: 0 | CB10: 0 | CC10: 0 | CD10: 0 | CE10: 0 | CF10: 0 | CG10: 0 | CH10: 0 | CI10: 0 | CJ10: 0 | CK10: 0 | CL10: 0 | CM10: 0 | CO10: 0 | CP10: 35.5 | CQ10: 36.6 | CR10: 37.9 | CS10: 42.1 | CT10: 41.1 | CU10: 45.3 | CV10: 43.9 | CW10: 40.55 | CX10: 42.8 | CY10: 45.3 | CZ10: 44.3 | DA10: 44.6 | DB10: 0 | DC10: 0 | DD10: 0 | DE10: 0 | DF10: 0 | DG10: 0 | DH10: 0 | DI10: 0 | DJ10: 0 | DK10: 0 | DL10: 0 | DM10: 0 | DN10: 0 | DO10: 0 | DP10: 0 | DR10: C2H6 | DS10: 4.28 | DT10: 4.46 | DU10: 5.32 | DV10: 5.57 | DW10: 11.82 | DX10: 11.6 | DY10: 10.77 | DZ10: 11.05 | EA10: 11.05 | EB10: 10.86 | EC10: 10.98 | ED10: 10.78 | EE10: 10.76 | EF10: 0 | EG10: 0 | EH10: 0 | EI10: 0 | EJ10: 0 | EK10: 0 | EL10: 0 | EM10: 0 | EN10: 0 | EO10: 0 | EP10: 0 | EQ10: 0 | ER10: 0 | ES10: 0 | ET10: 0 | EV10: 0.54 | EW10: =EX10 -> 0.11 | EX10: 0.11 | EY10: 0.05 | EZ10: 0.14 | FA10: 0.27 | FB10: 0.3 | FC10: 0.1 | FD10: 0.225 | FE10: 0.14 | FF10: 0.05 | FG10: 0.06 | FH10: 0.26 | FI10: 0 | FJ10: 0 | FK10: 0 | FL10: 0 | FM10: 0 | FN10: 0 | FO10: 0 | FP10: 0 | FQ10: 0 | FR10: 0 | FS10: 0 | FT10: 0 | FU10: 0 | FV10: 0 | FW10: 0 | FX10: C2H6
C11: 250-360 | F11: 1.091 | G11: 1.091 | H11: 1.091 | I11: 1.091 | J11: 0.677 | K11: 0.677 | L11: 0.677 | M11: 0.677 | N11: 0.677 | O11: 0.677 | P11: 0.677 | Q11: 0.677 | R11: 0.677 | S11: 0.677 | T11: 0.677 | U11: 0.677 | V11: 0.677 | W11: 0.677 | X11: 1.091 | Y11: 1.091 | Z11: 1.091 | AA11: 1.091 | AB11: 0 | AC11: 0 | AD11: 0 | AE11: 0 | AF11: 0 | AG11: 0 | AI11: 0 | AJ11: 22.95 | AK11: 0 | AL11: 0 | AM11: 0 | AN11: 0 | AO11: 0 | AP11: 0 | AQ11: 0 | AR11: 0 | AS11: 0 | AT11: 0 | AU11: 0 | AV11: 0 | AW11: 0 | AX11: 0 | AY11: 0 | AZ11: 0 | BA11: 0 | BB11: 0 | BC11: 0 | BD11: 0 | BE11: 0 | BF11: 0 | BG11: 0 | BH11: 0 | BI11: 0 | BJ11: 0 | BL11: 7.2175 | BM11: 6.7215 | BN11: 6.8943333 | BO11: 7.441 | BP11: 18.18 | BQ11: 19.139 | BR11: 18.54 | BS11: 17.995 | BT11: 17.7355 | BU11: 17.899 | BV11: 17.748 | BW11: 17.891 | BX11: 18.123 | BY11: 0 | BZ11: 0 | CA11: 0 | CB11: 0 | CC11: 0 | CD11: 0 | CE11: 0 | CF11: 0 | CG11: 0 | CH11: 0 | CI11: 0 | CJ11: 0 | CK11: 0 | CL11: 0 | CM11: 0 | CO11: 0 | CP11: 30.2 | CQ11: 29.7 | CR11: 28.8 | CS11: 30.7 | CT11: 28.3 | CU11: 31.8 | CV11: 30.4 | CW11: 31.25 | CX11: 30.2 | CY11: 31.6 | CZ11: 30.2 | DA11: 30.5 | DB11: 0 | DC11: 0 | DD11: 0 | DE11: 0 | DF11: 0 | DG11: 0 | DH11: 0 | DI11: 0 | DJ11: 0 | DK11: 0 | DL11: 0 | DM11: 0 | DN11: 0 | DO11: 0 | DP11: 0 | DR11: C3H8 | DS11: 4.85 | DT11: 4.735 | DU11: 5.39 | DV11: 5.62 | DW11: 11.25 | DX11: 11.14 | DY11: 10.78 | DZ11: 10.92 | EA11: 10.92 | EB11: 11.39 | EC11: 10.93 | ED11: 10.78 | EE11: 10.74 | EF11: 0 | EG11: 0 | EH11: 0 | EI11: 0 | EJ11: 0 | EK11: 0 | EL11: 0 | EM11: 0 | EN11: 0 | EO11: 0 | EP11: 0 | EQ11: 0 | ER11: 0 | ES11: 0 | ET11: 0 | EV11: 1.18 | EW11: =EX11 -> 0.16 | EX11: 0.16 | EY11: 0.08 | EZ11: 0.24 | FA11: 0.41 | FB11: 0.45 | FC11: 0.24 | FD11: 0.38 | FE11: 0.28 | FF11: 0.09 | FG11: 0.15 | FH11: 0.47 | FI11: 0 | FJ11: 0 | FK11: 0 | FL11: 0 | FM11: 0 | FN11: 0 | FO11: 0 | FP11: 0 | FQ11: 0 | FR11: 0 | FS11: 0 | FT11: 0 | FU11: 0 | FV11: 0 | FW11: 0 | FX11: C3H8
C12: 360-500 | F12: 5.247 | G12: 5.247 | H12: 5.247 | I12: 5.247 | J12: 4.116 | K12: 4.116 | L12: 4.116 | M12: 4.116 | N12: 4.116 | O12: 4.116 | P12: 4.116 | Q12: 4.116 | R12: 4.116 | S12: 4.116 | T12: 4.116 | U12: 4.116 | V12: 4.116 | W12: 4.116 | X12: 5.247 | Y12: 5.247 | Z12: 5.247 | AA12: 5.247 | AB12: 0.6 | AC12: 0.6 | AD12: 0.6 | AE12: 0.6 | AF12: 0.6 | AG12: 0.6 | AI12: 0 | AJ12: 10.41 | AK12: 0 | AL12: 0 | AM12: 0 | AN12: 0 | AO12: 0 | AP12: 0 | AQ12: 0 | AR12: 0 | AS12: 0 | AT12: 0 | AU12: 0 | AV12: 0 | AW12: 0 | AX12: 0 | AY12: 0 | AZ12: 0 | BA12: 0 | BB12: 0 | BC12: 0 | BD12: 0 | BE12: 0 | BF12: 0 | BG12: 0 | BH12: 0 | BI12: 0 | BJ12: 0 | BL12: 22.606 | BM12: 20.2555 | BN12: 19.087667 | BO12: 19.404 | BP12: 30.225 | BQ12: 31.839 | BR12: 31.418 | BS12: 30.901 | BT12: 30.4305 | BU12: 30.359 | BV12: 30.876 | BW12: 30.835 | BX12: 31.282 | BY12: 0 | BZ12: 0 | CA12: 0 | CB12: 0 | CC12: 0 | CD12: 0 | CE12: 0 | CF12: 0 | CG12: 0 | CH12: 0 | CI12: 0 | CJ12: 0 | CK12: 0 | CL12: 0 | CM12: 0 | CO12: 0 | CP12: 13.8 | CQ12: 10.7 | CR12: 9.1 | CS12: 8.7 | CT12: 6.6 | CU12: 7.3 | CV12: 6.9 | CW12: 11.975 | CX12: 8.5 | CY12: 7.4 | CZ12: 6.9 | DA12: 6.9 | DB12: 0 | DC12: 0 | DD12: 0 | DE12: 0 | DF12: 0 | DG12: 0 | DH12: 0 | DI12: 0 | DJ12: 0 | DK12: 0 | DL12: 0 | DM12: 0 | DN12: 0 | DO12: 0 | DP12: 0 | DR12: C4H10(Total) | DS12: 5.85 | DT12: 5.215 | DU12: 4.27 | DV12: 4.41 | DW12: 7.12 | DX12: 7.35 | DY12: 7.37 | DZ12: 7.21 | EA12: 7.21 | EB12: 7.95 | EC12: 7.26 | ED12: 7.24 | EE12: 7.15 | EF12: 0 | EG12: 0 | EH12: 0 | EI12: 0 | EJ12: 0 | EK12: 0 | EL12: 0 | EM12: 0 | EN12: 0 | EO12: 0 | EP12: 0 | EQ12: 0 | ER12: 0 | ES12: 0 | ET12: 0 | EV12: 1.47 | EW12: =EX12 -> 0.17 | EX12: 0.17 | EY12: 0.11 | EZ12: 0.41 | FA12: 0.46 | FB12: 0.5 | FC12: 0.51 | FD12: 0.545 | FE12: 0.48 | FF12: 0.2 | FG12: 0.31 | FH12: 0.68 | FI12: 0 | FJ12: 0 | FK12: 0 | FL12: 0 | FM12: 0 | FN12: 0 | FO12: 0 | FP12: 0 | FQ12: 0 | FR12: 0 | FS12: 0 | FT12: 0 | FU12: 0 | FV12: 0 | FW12: 0 | FX12: C4H10(Total)
C13: 500-560 | F13: 8.571 | G13: 8.571 | H13: 8.571 | I13: 8.571 | J13: 7.563 | K13: 7.563 | L13: 7.563 | M13: 7.563 | N13: 7.563 | O13: 7.563 | P13: 7.563 | Q13: 7.563 | R13: 7.563 | S13: 7.563 | T13: 7.563 | U13: 7.563 | V13: 7.563 | W13: 7.563 | X13: 8.571 | Y13: 8.571 | Z13: 8.571 | AA13: 8.571 | AB13: 11.2 | AC13: 11.2 | AD13: 11.2 | AE13: 11.2 | AF13: 11.2 | AG13: 11.2 | AI13: 0 | AJ13: 9.7772 | AK13: 0 | AL13: 0 | AM13: 0 | AN13: 0 | AO13: 0 | AP13: 0 | AQ13: 0 | AR13: 0 | AS13: 0 | AT13: 0 | AU13: 0 | AV13: 0 | AW13: 0 | AX13: 0 | AY13: 0 | AZ13: 0 | BA13: 0 | BB13: 0 | BC13: 0 | BD13: 0 | BE13: 0 | BF13: 0 | BG13: 0 | BH13: 0 | BI13: 0 | BJ13: 0 | BL13: 13.8965 | BM13: 13.5685 | BN13: 14.078667 | BO13: 14.951 | BP13: 13.464 | BQ13: 14.0473 | BR13: 14.12 | BS13: 13.981 | BT13: 13.813 | BU13: 13.754 | BV13: 14.102 | BW13: 13.953 | BX13: 13.941 | BY13: 0 | BZ13: 0 | CA13: 0 | CB13: 0 | CC13: 0 | CD13: 0 | CE13: 0 | CF13: 0 | CG13: 0 | CH13: 0 | CI13: 0 | CJ13: 0 | CK13: 0 | CL13: 0 | CM13: 0 | CO13: 0 | CP13: 0.1 | CQ13: 0 | CR13: 0 | CS13: 0 | CT13: 0 | CU13: 0 | CV13: 0 | CW13: 0 | CX13: 0 | CY13: 0 | CZ13: 0 | DA13: 0 | DB13: 0 | DC13: 0 | DD13: 0 | DE13: 0 | DF13: 0 | DG13: 0 | DH13: 0 | DI13: 0 | DJ13: 0 | DK13: 0 | DL13: 0 | DM13: 0 | DN13: 0 | DO13: 0 | DP13: 0 | DR13: C5H12 | DS13: 3.11 | DT13: 2.185 | DU13: 3.06 | DV13: 3.07 | DW13: 3.05 | DX13: 3.53 | DY13: 3.65 | DZ13: 3.58 | EA13: 3.58 | EB13: 3.79 | EC13: 3.79 | ED13: 3.79 | EE13: 3.71 | EF13: 0 | EG13: 0 | EH13: 0 | EI13: 0 | EJ13: 0 | EK13: 0 | EL13: 0 | EM13: 0 | EN13: 0 | EO13: 0 | EP13: 0 | EQ13: 0 | ER13: 0 | ES13: 0 | ET13: 0 | EV13: 0.94 | EW13: =EX13 -> 0.11 | EX13: 0.11 | EY13: 0.12 | EZ13: 0.49 | FA13: 0.39 | FB13: 0.38 | FC13: 0.69 | FD13: 0.585 | FE13: 0.5 | FF13: 0.4 | FG13: 0.48 | FH13: 0.69 | FI13: 0 | FJ13: 0 | FK13: 0 | FL13: 0 | FM13: 0 | FN13: 0 | FO13: 0 | FP13: 0 | FQ13: 0 | FR13: 0 | FS13: 0 | FT13: 0 | FU13: 0 | FV13: 0 | FW13: 0 | FX13: C5H12
C14: 560 plus | F14: 85.091 | G14: 85.091 | H14: 85.091 | I14: 85.091 | J14: 87.644 | K14: 87.644 | L14: 87.644 | M14: 87.644 | N14: 87.644 | O14: 87.644 | P14: 87.644 | Q14: 87.644 | R14: 87.644 | S14: 87.644 | T14: 87.644 | U14: 87.644 | V14: 87.644 | W14: 87.644 | X14: 85.091 | Y14: 85.091 | Z14: 85.091 | AA14: 85.091 | AB14: 88.2 | AC14: 88.2 | AD14: 88.2 | AE14: 88.2 | AF14: 88.2 | AG14: 88.2 | AI14: 100 | AJ14: 42.6648 | AK14: 100 | AL14: 100 | AM14: 100 | AN14: 100 | AO14: 100 | AP14: 100 | AQ14: 100 | AR14: 100 | AS14: 100 | AT14: 100 | AU14: 100 | AV14: 100 | AW14: 100 | AX14: 100 | AY14: 100 | AZ14: 100 | BA14: 100 | BB14: 100 | BC14: 100 | BD14: 100 | BE14: 100 | BF14: 100 | BG14: 100 | BH14: 100 | BI14: 100 | BJ14: 100 | BL14: 53.2555 | BM14: 56.5165 | BN14: 57.059667 | BO14: 54.924 | BP14: 28.359 | BQ14: 24.9027 | BR14: 26.088 | BS14: 27.664 | BT14: 29.555 | BU14: 29.116 | BV14: 28.465 | BW14: 28.665 | BX14: 27.881 | BY14: 100 | BZ14: 100 | CA14: 100 | CB14: 100 | CC14: 100 | CD14: 100 | CE14: 100 | CF14: 100 | CG14: 100 | CH14: 100 | CI14: 100 | CJ14: 100 | CK14: 100 | CL14: 100 | CM14: 100 | CO14: 0 | CP14: 0 | CQ14: 0 | CR14: 0 | CS14: 0 | CT14: 0 | CU14: 0 | CV14: 0 | CW14: 0 | CX14: 0 | CY14: 0 | CZ14: 0 | DA14: 0 | DB14: 0 | DC14: 0 | DD14: 0 | DE14: 0 | DF14: 0 | DG14: 0 | DH14: 0 | DI14: 0 | DJ14: 0 | DK14: 0 | DL14: 0 | DM14: 0 | DN14: 0 | DO14: 0 | DP14: 0 | DR14: C6H14 plus | DS14: 2.37 | DT14: 4.205 | DU14: 2.98 | DV14: 1.42 | DW14: 1.97 | DX14: 1.71 | DY14: 1.76 | DZ14: 1.14 | EA14: 1.14 | EB14: 2.8 | EC14: 2.91 | ED14: 3.26 | EE14: 2.94 | EF14: 0 | EG14: 0 | EH14: 0 | EI14: 0 | EJ14: 0 | EK14: 0 | EL14: 0 | EM14: 0 | EN14: 0 | EO14: 0 | EP14: 0 | EQ14: 0 | ER14: 0 | ES14: 0 | ET14: 0 | EV14: 0.42 | EW14: =EX14 -> 0.12 | EX14: 0.12 | EY14: 0.42 | EZ14: 0.92 | FA14: 0.7 | FB14: 0.63 | FC14: 0.45 | FD14: 0.525 | FE14: 0.53 | FF14: 0.48 | FG14: 0.82 | FH14: 0.93 | FI14: 0 | FJ14: 0 | FK14: 0 | FL14: 0 | FM14: 0 | FN14: 0 | FO14: 0 | FP14: 0 | FQ14: 0 | FR14: 0 | FS14: 0 | FT14: 0 | FU14: 0 | FV14: 0 | FW14: 0 | FX14: C6H14 plus
C15: Total | F15: 100 | G15: 100 | H15: 100 | I15: 100 | J15: 100 | K15: 100 | L15: 100 | M15: 100 | N15: 100 | O15: 100 | P15: 100 | Q15: 100 | R15: 100 | S15: 100 | T15: 100 | U15: 100 | V15: 100 | W15: 100 | X15: 100 | Y15: 100 | Z15: 100 | AA15: 100 | AB15: 100 | AC15: 100 | AD15: 100 | AE15: 100 | AF15: 100 | AG15: 100 | AI15: 100 | AJ15: 100 | AK15: 100 | AL15: 100 | AM15: 100 | AN15: 100 | AO15: 100 | AP15: 100 | AQ15: 100 | AR15: 100 | AS15: 100 | AT15: 100 | AU15: 100 | AV15: 100 | AW15: 100 | AX15: 100 | AY15: 100 | AZ15: 100 | BA15: 100 | BB15: 100 | BC15: 100 | BD15: 100 | BE15: 100 | BF15: 100 | BG15: 100 | BH15: 100 | BI15: 100 | BJ15: 100 | BL15: 100 | BM15: 100 | BN15: 100 | BO15: 100 | BP15: 100 | BQ15: 100 | BR15: 100 | BS15: 100 | BT15: 100 | BU15: 100 | BV15: 100 | BW15: 100 | BX15: 100 | BY15: 100 | BZ15: 100 | CA15: 100 | CB15: 100 | CC15: 100 | CD15: 100 | CE15: 100 | CF15: 100 | CG15: 100 | CH15: 100 | CI15: 100 | CJ15: 100 | CK15: 100 | CL15: 100 | CM15: 100 | CO15: 0 | CP15: 100 | CQ15: 100 | CR15: 100 | CS15: 100 | CT15: 100 | CU15: 100 | CV15: 100 | CW15: 100 | CX15: 100 | CY15: 100 | CZ15: 100 | DA15: 100 | DB15: 0 | DC15: 0 | DD15: 0 | DE15: 0 | DF15: 0 | DG15: 0 | DH15: 0 | DI15: 0 | DJ15: 0 | DK15: 0 | DL15: 0 | DM15: 0 | DN15: 0 | DO15: 0 | DP15: 0
C16: 560 plus, TOP acceptance'Dec24 | K16: 26.91 | L16: 30.22 | M16: 29.99 | N16: 32.135 | O16: 33.8 | P16: 32.29 | BL16: 60.116 | BM16: 63.283 | BN16: 61.009 | BO16: 61.402 | BQ16: 26.91 | BR16: 30.22 | BS16: 29.99 | BT16: 32.135 | BU16: 33.8 | BV16: 32.29
C17: 560 plus, TOP acceptance'Dec26 | BL17: ='HPS DAILY'!K72 -> 53.2555 | BM17: ='HPS DAILY'!L72 -> 56.5165 | BN17: ='HPS DAILY'!M72 -> 57.059667 | BO17: ='HPS DAILY'!N72 -> 54.924 | BP17: ='HPS DAILY'!O72 -> 28.359 | BQ17: ='HPS DAILY'!P72 -> 24.9027 | BR17: ='HPS DAILY'!Q72 -> 26.088 | BS17: ='HPS DAILY'!R72 -> 27.664 | ... CG17: ='HPS DAILY'!AF72 -> 100
C18: 560 plus, ART, acceptance | F18: 56.4181 | G18: 55.5455 | H18: 55.6545 | I18: 55.7818 | J18: 23.1831 | K18: 25.9861 | L18: 25.9286 | M18: 27.0423 | N18: 29.4189 | O18: 29.72 | P18: 28.6528 | BL18: 56.4181 | BM18: 55.5455 | BN18: 55.6545 | BO18: 55.7818 | BP18: 23.1831 | BQ18: 25.9861 | BR18: 25.9286 | BS18: 27.0423 | BT18: 29.4189 | BU18: 29.72 | BV18: 28.6528 | DR18: Nitrogen | DS18: {='HPS DAILY'!K117:AA117} -> 0.14 | DT18: 0.19 | DU18: 0.4 | DV18: 0.15 | DW18: 0.17 | DX18: 0.15 | DY18: 0.22 | DZ18: 0.34 | EA18: 0.34 | EB18: 0.12 | EC18: 0.13 | ED18: 0.13 | EE18: 0.15 | EF18: 0 | EG18: 0 | EH18: 0 | EI18: 0 | EV18: {='HPS DAILY'!K104:AL104} -> 75.95 | EW18: 93.3 | EX18: 96.76 | EY18: 98.17 | EZ18: 96.44 | FA18: 96.17 | FB18: 95.96 | FC18: 97 | FD18: 95.94 | FE18: 96.7 | FF18: 98.74 | FG18: 98.14 | FH18: 95.73 | FI18: 0 | FJ18: 0 | FK18: 0 | FL18: 0 | FM18: 0 | FN18: 0 | FO18: 0 | FP18: 0 | FQ18: 0 | FR18: 0 | FS18: 0 | FT18: 0 | FU18: 0 | FV18: 0 | FW18: 0 | FX18: Nitrogen
C19: 560plus, MEBU25002 | F19: 59.673 | G19: 58.045 | H19: 59.301 | I19: 59.834 | BL19: 59.673 | BM19: 58.045 | BN19: 59.301 | BO19: 59.834
C20: Ni, ppm | F20: ='HPS DAILY'!$G$42 -> 61.59 | G20: ='HPS DAILY'!$G$42 -> 61.59 | H20: ='HPS DAILY'!$G$42 -> 61.59 | I20: ='HPS DAILY'!$G$42 -> 61.59 | J20: ='HPS DAILY'!$H$42 -> 64.7 | K20: ='HPS DAILY'!$H$42 -> 64.7 | L20: ='HPS DAILY'!$H$42 -> 64.7 | M20: ='HPS DAILY'!$H$42 -> 64.7 | N20: ='HPS DAILY'!$H$42 -> 64.7 | O20: ='HPS DAILY'!$H$42 -> 64.7 | P20: ='HPS DAILY'!$H$42 -> 64.7 | Q20: ='HPS DAILY'!$H$42 -> 64.7 | ... S20: ='HPS DAILY'!$H$42 -> 64.7 | T20: ='HPS DAILY'!$I$42 -> 64.7 | U20: ='HPS DAILY'!$I$42 -> 64.7 | V20: ='HPS DAILY'!$I$42 -> 64.7 | W20: ='HPS DAILY'!$I$42 -> 64.7 | X20: ='HPS DAILY'!$I$42 -> 64.7 | Y20: ='HPS DAILY'!$J$42 -> 64.7 | Z20: ='HPS DAILY'!$J$42 -> 64.7 | AA20: ='HPS DAILY'!$J$42 -> 64.7 | AB20: ='HPS DAILY'!$J$42 -> 64.7 | AC20: ='HPS DAILY'!$J$42 -> 64.7 | AD20: ='HPS DAILY'!$J$42 -> 64.7 | AE20: ='HPS DAILY'!$J$42 -> 64.7 | AF20: ='HPS DAILY'!$J$42 -> 64.7 | AG20: ='HPS DAILY'!$J$42 -> 64.7 | AI20: =ISV!G$41 -> 0 | AJ20: =ISV!H$41 -> 50.42 | AK20: =ISV!I$41 -> 0 | AL20: =ISV!J$41 -> 0 | AM20: =ISV!K$41 -> 94.75 | AN20: =ISV!L$41 -> 72.69 | AO20: =ISV!M$41 -> 0 | AP20: =ISV!N$41 -> 0 | ... BJ20: =ISV!AH$41 -> 0 | BL20: {='HPS DAILY'!K42:AL42} -> 19.865 | BM20: 20.99 | BN20: 22.606667 | BO20: 21.64 | BP20: 3.88 | BQ20: 4.75 | BR20: 6 | BS20: 6.81 | BT20: 7.655 | BU20: 8.31 | BV20: 9.31 | BW20: 9.21 | BX20: 9.6 | BY20: 0 | BZ20: 0 | CA20: 0 | CB20: 0 | CC20: 0 | CD20: 0 | CE20: 0 | CF20: 0 | CG20: 0 | CH20: 0 | CI20: 0 | CJ20: 0 | CK20: 0 | CL20: 0 | CM20: 0
C21: Ni, ppm, ART, Low and High | J21: 97.9 | K21: 97.9 | L21: 97.9 | M21: 97.9 | N21: 97.9 | O21: 97.9 | P21: 97.9 | Q21: 97.9 | R21: 97.9 | BL21: 19 | BM21: 20.5 | BN21: 21.5 | BO21: 21.9 | BP21: 8 | BQ21: 12 | BR21: 13 | BS21: 14.1 | BT21: 15.2 | BU21: 16.2 | BV21: 20.5 | BW21: 30 | BX21: 30.8 | BY21: 28 | BZ21: 30 | CA21: 30.7
C22: Ni, ppm, TOP, Acceptance'Dec24 | K22: 4.83 | L22: 6.31 | M22: 6.74 | N22: 7.68 | O22: 8.52 | P22: 9.16 | BQ22: 4.83 | BR22: 6.31 | BS22: 6.74 | BT22: 7.68 | BU22: 8.52 | BV22: 9.16
C23: Ni, ppm, ART, Acceptance | F23: 18.8 | G23: 19.9 | H23: 20.9 | I23: 21.1 | J23: 3.81 | K23: 5.45 | L23: 6.54 | M23: 7.49 | N23: 8.34 | O23: 8.68 | P23: 9.19 | BL23: 18.8 | BM23: 19.9 | BN23: 20.9 | BO23: 21.1 | BP23: 3.81 | BQ23: 5.45 | BR23: 6.54 | BS23: 7.49 | BT23: 8.34 | BU23: 8.68 | BV23: 9.19
