Workbook
Name AllottedFunds: #REF!
Name ColumnTitle2: #REF!
Name ColumnTitleRegion1..D4.2: #REF!
Name FundsRemaining: INDEX(#REF!,ROWS(#REF!),1)
Name FundsRemainingLabel: #REF!
Name FundsUsed: #REF!
Name FundsUsedLabel: #REF!
Name RowTitleRegion1..C11: #REF!
Name Title1: #REF!

Sheet ISV
D1: RHCU Pilot Plant Laboratory Worksheet
D2: Batch Name : | E2: Low&High Sedimentation
D3: Date : | E3: 17/07-01/8/2025
D4: Note : | E4: MEBU ACCEPTANCE TEST | G4: CATALYST AGING | K4: CRACKING EXPERIMENT
G5: ABQ3358 | K5: Low Sedim | Q5: High Sedim
F6: Day on stream | G6: 1 | H6: 2 | I6: 3 | J6: 4 | K6: 5 | L6: 6 | M6: 7 | N6: 8 | O6: 9 | P6: 10 | Q6: 11 | R6: 12 | S6: 13 | T6: 14 | U6: 15 | V6: 16
D8: Properties | E8: Method | F8: Unit | G8: ISV | H8: ISV | I8: ISV | J8: ISV | K8: ISV | L8: ISV | M8: ISV | N8: ISV | O8: ISV | P8: ISV | Q8: ISV | R8: ISV | S8: ISV | T8: ISV | U8: ISV | V8: ISV
D9: Ratio | E9: - | F9: %wt.
D10: Weight | E10: - | F10: kg
D11: Density | E11: ASTM D4052 | F11: kg/L
D12: Relative Density@25/25 oC | E12: ASTM D70 | F12: -
D13: Viscosity @ -20 oC | E13: ASTM D445 | F13: cSt.
D14: Viscosity @ 40 oC
D15: Viscosity @ 70 oC
D16: Viscosity @ 100 oC
D17: Viscosity @ 150 oC
D18: V50
D19: Sulfur | E19: ASTM D4294 | F19: %wt | G19: 2.79 | H19: 4.33 | I19: 4.36 | J19: 4.385 | K19: 4.38 | L19: 3.746 | M19: 3.78 | N19: 3.907 | R19: 3.93 | S19: 3.505 | T19: 3.35
E20: ASTM D2622 | F20: %wt
F21: PPMw
D22: Total Nitrogen | E22: ASTM D4629 | F22: PPMw
E23: ASTM D5762 | F23: PPMw | G23: 1995 | I23: 4296.49 | K23: 3875 | L23: 4435.98 | M23: 6599 | N23: 6260.77 | R23: 6667 | S23: 7325 | T23: 7539
B24: 0.4519 | F24: %wt | G24: =G23/10000 -> 0.1995 | H24: =H23/10000 -> 0 | I24: =I23/10000 -> 0.429649 | J24: =J23/10000 -> 0 | K24: =K23/10000 -> 0.3875 | L24: =L23/10000 -> 0.443598 | M24: =M23/10000 -> 0.6599 | N24: =N23/10000 -> 0.626077 | ... V24: =V23/10000 -> 0
D25: CHN | E25: ASTM D5291 | F25: %wt
D26: Carbon | G26: 88.02 | H26: 86.25 | I26: 86.14 | K26: 86.59 | L26: 85.53 | M26: 85.98 | N26: 86.67 | R26: 86.99 | S26: 87.85 | T26: 86.78
D27: Hydrogen | G27: 10.59 | H27: 9.916 | I27: 10.69 | K27: 9.78 | L27: 10.12 | M27: 10.99 | N27: 10.78 | R27: 10.44 | S27: 10.64 | T27: 11
D28: Nitrogen | G28: 0.27 | H28: 0.5029 | I28: 0.5381 | K28: 0.66 | L28: 0.6406 | M28: 0.861 | N28: 1.802 | R28: 2.32 | S28: 2.84 | T28: 4.34
D29: CHNS | G29: =(G$26+G$27+G$24+G$19) -> 101.5995 | H29: =(H$26+H$27+H$24+H$19) -> 100.496 | I29: =(I$26+I$27+I$24+I$19) -> 101.61965 | K29: =(K$26+K$27+K$24+K$19) -> 101.1375 | L29: =(L$26+L$27+L$24+L$19) -> 99.839598 | M29: =(M$26+M$27+M$24+M$19) -> 101.4099 | N29: =(N$26+N$27+N$24+N$19) -> 101.98308 | R29: =(R$26+R$27+R$24+R$19) -> 102.0267 | S29: =(S$26+S$27+S$24+S$19) -> 102.7275 | T29: =(T$26+T$27+T$24+T$19) -> 101.8839
D30: CN | G30: =(100-G$32-G$33)/(1+(G$27/G$26)) -> 86.634285 | H30: =(100-H$32-H$33)/(1+(H$27/H$26)) -> 85.824311 | I30: =(100-I$32-I$33)/(1+(I$27/I$26)) -> 84.767071 | K30: =(100-K$32-K$33)/(1+(K$27/K$26)) -> 85.616117 | L30: =(100-L$32-L$33)/(1+(L$27/L$26)) -> 85.667412 | M30: =(100-M$32-M$33)/(1+(M$27/M$26)) -> 84.784622 | N30: =(100-N$32-N$33)/(1+(N$27/N$26)) -> 84.984688 | R30: =(100-R$32-R$33)/(1+(R$27/R$26)) -> 85.261995 | S30: =(100-S$32-S$33)/(1+(S$27/S$26)) -> 85.51751 | T30: =(100-T$32-T$33)/(1+(T$27/T$26)) -> 85.175381
D31: HN | F31: %wt | G31: =G$30*(G$27/G$26) -> 10.42328 | H31: =H$30*(H$27/H$26) -> 9.8670594 | I31: =I$30*(I$27/I$26) -> 10.519619 | K31: =K$30*(K$27/K$26) -> 9.6700037 | L31: =L$30*(L$27/L$26) -> 10.136259 | M31: =M$30*(M$27/M$26) -> 10.837206 | N31: =N$30*(N$27/N$26) -> 10.570381 | R31: =R$30*(R$27/R$26) -> 10.232616 | S31: =S$30*(S$27/S$26) -> 10.357499 | T31: =T$30*(T$27/T$26) -> 10.796603
D32: NN | G32: =G$24*100/G$29 -> 0.19635923 | H32: =H$24*100/H$29 -> 0 | I32: =I$24*100/I$29 -> 0.42280111 | K32: =K$24*100/K$29 -> 0.38314176 | L32: =L$24*100/L$29 -> 0.44431068 | M32: =M$24*100/M$29 -> 0.65072542 | N32: =N$24*100/N$29 -> 0.61390283 | R32: =R$24*100/R$29 -> 0.6534564 | S32: =S$24*100/S$29 -> 0.71305152 | T32: =T$24*100/T$29 -> 0.7399599
D33: SN | G33: =G$19*100/G$29 -> 2.7460765 | H33: =H$19*100/H$29 -> 4.3086292 | I33: =I$19*100/I$29 -> 4.2905088 | K33: =K$19*100/K$29 -> 4.3307379 | L33: =L$19*100/L$29 -> 3.7520183 | M33: =M$19*100/M$29 -> 3.7274467 | N33: =N$19*100/N$29 -> 3.8310278 | R33: =R$19*100/R$29 -> 3.8519329 | S33: =S$19*100/S$29 -> 3.4119394 | T33: =T$19*100/T$29 -> 3.2880563
D34: HN/CN | G34: =G$31/G$30 -> 0.12031357 | H34: =H$31/H$30 -> 0.11496812 | I34: =I$31/I$30 -> 0.1241003 | K34: =K$31/K$30 -> 0.11294607 | L34: =L$31/L$30 -> 0.11832106 | M34: =M$31/M$30 -> 0.12782042 | N34: =N$31/N$30 -> 0.12437983 | R34: =R$31/R$30 -> 0.12001379 | S34: =S$31/S$30 -> 0.12111554 | T34: =T$31/T$30 -> 0.12675732
D35: C
D36: H
D37: N
D38: S
D39: H/C
D40: ICP | E40: ASTM D7691 UOP 389 | F40: PPMw
D41: Nickle (Ni) | G41: 269.69 | H41: 1886.78 | I41: 88.02 | K41: 75.77 | L41: 151.41 | M41: 137.3 | N41: 120.12 | R41: 181.05 | S41: 231.47 | T41: 216.66
...

Sheet LTO DAILY
D1: RHCU Pilot Plant Laboratory Worksheet
D2: Batch Name : | E2: SR ABQ3358 ACCEPTANCE TEST
D3: Date : | E3: 17/07-01/8/2025
D4: Note : | E4: MEBU ACCEPTANCE TEST | H4: CRACKING EXPERIMENT
F5: Day on stream | G5: Day on stream | H5: 1 | I5: 2 | J5: 3 | K5: 4 | L5: 5 | M5: 6 | N5: 7 | O5: 8 | P5: 9 | Q5: 10 | R5: 11 | S5: 12 | T5: 13 | U5: 14 | V5: 15 | W5: 16_1 | X5: 16_2
G6: Date | W6: at 04.00 02/08/25 | X6: at 18.00 01/08/25
D7: Properties | E7: Method | F7: Unit | G7: SR ABQ3358 | H7: LTO | I7: LTO | J7: LTO | K7: LTO | L7: LTO | M7: LTO | N7: LTO | O7: LTO | P7: LTO | Q7: LTO | R7: LTO | S7: LTO | T7: LTO | U7: LTO | V7: LTO | W7: LTO | X7: LTO
D8: Ratio | E8: - | F8: %wt. | G8: 100
D9: API | E9: - | F9: kg | H9: 44 | I9: 43.8 | J9: 45.66 | K9: 44.2 | L9: 43.75 | M9: 43.8 | N9: 45.4 | O9: 45.62 | P9: 45.25 | Q9: 45.86 | R9: 47.55 | S9: 45.6 | T9: 44.61 | U9: 45.7 | V9: 46.37 | W9: 47.2 | X9: 43.4
D10: Density | E10: ASTM D4052 | F10: kg/L | H10: 0.8055 | I10: 0.8066 | J10: 0.7979 | K10: 0.8045 | L10: 0.8066 | M10: 0.8063 | N10: 0.7992 | O10: 0.7981 | P10: 0.7998 | Q10: 0.797 | R10: 0.7895 | S10: 0.7983 | T10: 0.8027 | U10: 0.7978 | V10: 0.7947 | W10: 0.7911 | X10: 0.8081
D11: Relative Density@25/25 oC | E11: ASTM D70 | F11: -
D12: Viscosity @ -20 oC | E12: ASTM D445 | F12: cSt.
D13: Viscosity @ 40 oC
D14: Viscosity @ 70 oC
D15: Viscosity @ 100 oC
D16: Viscosity @ 150 oC
D17: V50
D18: Sulfur | E18: ASTM D4294 | F18: %wt | G18: 5.986 | H18: 0.102 | I18: 0.136 | J18: 0.1427 | K18: 0.15322 | L18: 0.1455 | M18: 0.0726 | N18: 0.0901 | O18: 0.0751 | P18: 0.0833 | Q18: 0.07879 | R18: 0.0831 | S18: 0.0879 | T18: 0.09671 | U18: 0.089 | V18: 0.08729 | W18: 0.0789 | X18: 0.0974
E19: ASTM D2622 | F19: %wt
F20: PPMw
D21: Total Nitrogen | E21: ASTM D4629 | F21: PPMw
E22: ASTM D5762 | F22: PPMw | G22: 3301 | H22: 268 | I22: 516.7 | J22: 542.3 | K22: 768.1 | L22: 716.84 | M22: 803 | N22: 917.2 | O22: 952 | P22: 978.07 | Q22: 974.47 | R22: 915.45 | S22: 1012 | T22: 955.3 | U22: 921.48 | V22: 868.19 | W22: 777.6 | X22: 980
B23: 0.4519 | F23: %wt | G23: 0.3301 | H23: =H22/10000 -> 0.0268 | I23: =I22/10000 -> 0.05167 | J23: =J22/10000 -> 0.05423 | K23: =K22/10000 -> 0.07681 | L23: =L22/10000 -> 0.071684 | M23: =M22/10000 -> 0.0803 | N23: =N22/10000 -> 0.09172 | O23: =O22/10000 -> 0.0952 | ... X23: =X22/10000 -> 0.098
D24: CHN | E24: ASTM D5291 | F24: %wt
D25: Carbon | G25: 84.31 | H25: 86.99 | I25: 86.33 | J25: 86.72 | K25: 85.54 | L25: 86.67 | M25: 85.59 | N25: 86.48 | O25: 86.98 | P25: 85.82 | Q25: 85.47 | R25: 86.77 | S25: 86.71 | T25: 87.83 | U25: 86.37 | V25: 86.35 | W25: 86.75 | X25: 87.53
D26: Hydrogen | G26: 9.782 | H26: 13.14 | I26: 12.27 | J26: 13.8 | K26: 13.91 | L26: 13.4 | M26: 13.22 | N26: 13.89 | O26: 14.01 | P26: 13.95 | Q26: 13.68 | R26: 14.08 | S26: 13.82 | T26: 13.93 | U26: 13.86 | V26: 13.9 | W26: 14.07 | X26: 14
D27: Nitrogen | G27: 0.4519 | H27: 0.14 | I27: 0.1145 | J27: 0.1206 | K27: 0.15 | L27: 0.17 | M27: 0.4184 | N27: 0.07366 | O27: 0.8998 | P27: 0.18 | Q27: 1.546 | R27: 1.229 | S27: 1.42 | T27: 1.61 | U27: 1.573 | V27: 1.535 | W27: 2.01 | X27: 3.03
D28: CHNS | G28: =(G25+G26+G27+G18) -> 100.5299 | H28: =H$25+H$26+H$23+H$18 -> 100.2588 | I28: =I$25+I$26+I$23+I$18 -> 98.78767 | J28: =J$25+J$26+J$23+J$18 -> 100.71693 | K28: =K$25+K$26+K$23+K$18 -> 99.68003 | L28: =L$25+L$26+L$23+L$18 -> 100.28718 | M28: =M$25+M$26+M$23+M$18 -> 98.9629 | N28: =N$25+N$26+N$23+N$18 -> 100.55182 | O28: =O$25+O$26+O$23+O$18 -> 101.1603 | ... X28: =X$25+X$26+X$23+X$18 -> 101.7254
D29: CN | G29: =(100-G31-G32)/(1+(G26/G25)) -> 83.974158 | H29: =(100-H$31-H$32)/(1+(H$26/H$25)) -> 86.765451 | I29: =(100-I$31-I$32)/(1+(I$26/I$25)) -> 87.389449 | J29: =(100-J$31-J$32)/(1+(J$26/J$25)) -> 86.102704 | K29: =(100-K$31-K$32)/(1+(K$26/K$25)) -> 85.814581 | L29: =(100-L$31-L$32)/(1+(L$26/L$25)) -> 86.42181 | M29: =(100-M$31-M$32)/(1+(M$26/M$25)) -> 86.486956 | N29: =(100-N$31-N$32)/(1+(N$26/N$25)) -> 86.005405 | O29: =(100-O$31-O$32)/(1+(O$26/O$25)) -> 85.982347 | ... X29: =(100-X$31-X$32)/(1+(X$26/X$25)) -> 86.045373
D30: HN | F30: %wt | G30: =G29*(G26/G25) -> 9.7430342 | H30: =H$29*(H$26/H$25) -> 13.106081 | I30: =I$29*(I$26/I$25) -> 12.420578 | J30: =J$29*(J$26/J$25) -> 13.701768 | K30: =K$29*(K$26/K$25) -> 13.954651 | L30: =L$29*(L$26/L$25) -> 13.361628 | M30: =M$29*(M$26/M$25) -> 13.358541 | N30: =N$29*(N$26/N$25) -> 13.813773 | O30: =O$29*(O$26/O$25) -> 13.849306 | ... X30: =X$29*(X$26/X$25) -> 13.762541
D31: NN | G31: =G23*100/G28 -> 0.32836002 | H31: =H$23*100/H$28 -> 0.026730821 | I31: =I$23*100/I$28 -> 0.052304098 | J31: =J$23*100/J$28 -> 0.053843976 | K31: =K$23*100/K$28 -> 0.077056558 | L31: =L$23*100/L$28 -> 0.071478725 | M31: =M$23*100/M$28 -> 0.081141519 | N31: =N$23*100/N$28 -> 0.091216648 | O31: =O$23*100/O$28 -> 0.094108064 | ... X31: =X$23*100/X$28 -> 0.096337788
D32: SN | G32: =G18*100/G28 -> 5.9544474 | H32: =H$18*100/H$28 -> 0.10173671 | I32: =I$18*100/I$28 -> 0.137669 | J32: =J$18*100/J$28 -> 0.14168422 | K32: =K$18*100/K$28 -> 0.15371183 | L32: =L$18*100/L$28 -> 0.14508334 | M32: =M$18*100/M$28 -> 0.073360825 | N32: =N$18*100/N$28 -> 0.089605539 | O32: =O$18*100/O$28 -> 0.074238609 | ... X32: =X$18*100/X$28 -> 0.095747965
D33: HN/CN | G33: =G30/G29 -> 0.1160242 | H33: =H$30/H$29 -> 0.15105185 | I33: =I$30/I$29 -> 0.14212904 | J33: =J$30/J$29 -> 0.15913284 | K33: =K$30/K$29 -> 0.16261398 | L33: =L$30/L$29 -> 0.15460944 | M33: =M$30/M$29 -> 0.1544573 | N33: =N$30/N$29 -> 0.16061517 | O33: =O$30/O$29 -> 0.16107151 | ... X33: =X$30/X$29 -> 0.15994516
D34: C | G34: =G25*100/G28 -> 83.865596
D35: H | G35: =G26*100/G28 -> 9.7304384
D36: N | G36: =G27*100/G28 -> 0.449518
D37: S | G37: =G18*100/G28 -> 5.9544474
D38: H/C | G38: =G35/G34 -> 0.1160242
D39: Simdist | E39: ASTM D2887 ASTM D7169 | F39: deg.C
D40: IBP | G40: 376 | H40: ='HPS LTO DAILY '!J116 -> 56.4 | I40: ='HPS LTO DAILY '!K116 -> 24.9 | J40: ='HPS LTO DAILY '!L116 -> 6.2 | K40: ='HPS LTO DAILY '!M116 -> 34.3 | L40: ='HPS LTO DAILY '!N116 -> 55.5 | M40: ='HPS LTO DAILY '!O116 -> 60.5 | N40: ='HPS LTO DAILY '!P116 -> 56 | O40: ='HPS LTO DAILY '!Q116 -> 56.3 | ... X40: ='HPS LTO DAILY '!Z116 -> 74.1
...

Sheet HPS DAILY
D1: RHCU Pilot Plant Laboratory Worksheet
D2: Batch Name : | E2: Low&High Sedimentation
D3: Date : | E3: 17/07-01/8/2025
D4: Note : | E4: MEBU ACCEPTANCE TEST | J4: CATALYST AGING | N4: CRACKING EXPERIMENT
J5: ABQ3358 | N5: Low Sedim | T5: High Sedim
G6: 9.782 | I6: Day on stream | J6: 1 | K6: 2 | L6: 3 | M6: 4 | N6: 5 | O6: 6 | P6: 7 | Q6: 8 | R6: 9 | S6: 10 | T6: 11 | U6: 12 | V6: 13 | W6: 14 | X6: 15 | Y6: 16_1 | Z6: 16_2
I7: Date | J7: 45856 | Y7: at 04.00 02/08/25 | Z7: at 18.00 01/08/25
D8: Properties | E8: Method | F8: Unit | G8: VR ABQ3358 | H8: VR Low Sedim | I8: VR High Sedim | J8: HPS | K8: HPS | L8: HPS | M8: HPS | N8: HPS | O8: HPS | P8: HPS | Q8: HPS | R8: HPS | S8: HPS | T8: HPS | U8: HPS | V8: HPS | W8: HPS | X8: HPS | Y8: HPS | Z8: HPS
D9: Ratio | E9: - | F9: %wt. | G9: 100
D10: API @ 15.6 degC | E10: - | G10: =(141.5/(G11/0.9991))-131.5 -> 3.3589621 | H10: =(141.5/(H11/0.9991))-131.5 -> 1.4314998 | I10: =(141.5/(I11/0.9991))-131.5 -> 1.8201151 | J10: 11.8 | K10: 11.9 | L10: 11.91 | M10: 11.86 | N10: 17.9 | O10: 15.7 | P10: 14.6 | Q10: 14.98 | R10: 14.76 | S10: 14.4 | T10: 15.12 | U10: 15.88 | V10: 15.45 | W10: 16.07 | X10: 15.69 | Y10: 15.1 | Z10: 15.6
D11: Density @ 15.6 degC | E11: ASTM D4052 | F11: kg/L | G11: 1.0483 | H11: 1.0635 | I11: 1.0604 | J11: 0.9868 | K11: 0.9858 | L11: 0.9857 | M11: 0.9861 | N11: 0.9462 | O11: 0.9604 | P11: 0.9677 | Q11: 0.9651 | R11: 0.9665 | S11: 0.9689 | T11: 0.9641 | U11: 0.9592 | V11: 0.962 | W11: 0.9579 | X11: 0.9604 | Y11: 0.9644 | Z11: 0.9612
D12: Relative Density@25/25 oC | E12: ASTM D70 | F12: - | G12: 1.049 | H12: 1.065 | I12: 1.061
D13: Viscosity @ -20 oC | E13: ASTM D445 | F13: cSt.
D14: Viscosity @ 40 oC
D15: Viscosity @ 70 oC
D16: Viscosity @ 100 oC
D17: Viscosity @ 135 °C
D18: Viscosity @ 150 oC
D19: V50
D20: Sulfur | E20: ASTM D4294 | F20: %wt | G20: 5.986 | H20: 5.69 | I20: 5.248 | J20: 2.34 | K20: 2.27 | L20: 2.334 | M20: 2.366 | N20: 1.01 | O20: 1.192 | P20: 1.45 | Q20: 1.412 | R20: 1.452 | S20: 1.539 | T20: 1.443 | U20: 1.24 | V20: 1.288 | W20: 1.265 | X20: 1.302 | Y20: 1.363 | Z20: 1.354
E21: ASTM D2622 | F21: %wt
F22: PPMw
D23: Total Nitrogen | E23: ASTM D4629 | F23: PPMw
E24: ASTM D5762 | F24: PPMw | G24: 5601 | H24: 7378 | I24: 7863.48 | J24: 3786 | K24: 3837 | L24: 3540 | M24: 3816 | N24: 3079.62 | O24: 5151 | P24: 5473 | Q24: 5357.83 | R24: 5756.65 | S24: 5612.97 | T24: 5704.94 | U24: 6137 | V24: 6649 | W24: 6476.22 | X24: 6435.59 | Y24: 6506 | Z24: 6415
B25: 0.4519 | F25: %wt | G25: =G24/10000 -> 0.5601 | H25: =H24/10000 -> 0.7378 | I25: =I24/10000 -> 0.786348 | J25: =J24/10000 -> 0.3786 | K25: =K24/10000 -> 0.3837 | L25: =L24/10000 -> 0.354 | M25: =M24/10000 -> 0.3816 | N25: =N24/10000 -> 0.307962 | ... Z25: =Z24/10000 -> 0.6415
D26: CHN | E26: ASTM D5291 | F26: %wt
D27: Carbon | G27: 84.31 | H27: 84.05 | I27: 84.66 | J27: 88.08 | K27: 87.96 | L27: 87.83 | M27: 87.56 | N27: 88.31 | O27: 88.14 | P27: 88.24 | Q27: 88.37 | R27: 88.46 | S27: 88.77 | T27: 88.86 | U27: 88.53 | V27: 88.67 | W27: 88.1 | X27: 88.52 | Y27: 88.35 | Z27: 88.33
D28: Hydrogen | G28: 9.782 | H28: 9.68 | I28: 9.79 | J28: 11.2 | K28: 10.56 | L28: 10.98 | M28: 11.44 | N28: 11.57 | O28: 11.26 | P28: 11.51 | Q28: 11.43 | R28: 11.44 | S28: 11.32 | T28: 11.41 | U28: 11.55 | V28: 11.65 | W28: 11.73 | X28: 11.77 | Y28: 11.55 | Z28: 11.86
D29: Nitrogen | G29: 0.567 | H29: 0.79 | I29: 2.509 | J29: 0.44 | K29: 0.4442 | L29: 0.44556 | M29: 0.44 | N29: 0.4857 | O29: 1.007 | P29: 0.525 | Q29: 1.045 | R29: 0.6473 | S29: 2.14 | T29: 2.195 | U29: 2.31 | V29: 3.16 | W29: 3.266 | X29: 5.147 | Y29: 4.89 | Z29: 9.03
D30: CHNS | G30: =(G$27+G$28+G$25+G$20) -> 100.6381 | H30: =(H$27+H$28+H$25+H$20) -> 100.1578 | I30: =(I$27+I$28+I$25+I$20) -> 100.48435 | J30: =(J$27+J$28+J$25+J$20) -> 101.9986 | K30: =(K$27+K$28+K$25+K$20) -> 101.1737 | L30: =(L$27+L$28+L$25+L$20) -> 101.498 | M30: =(M$27+M$28+M$25+M$20) -> 101.7476 | N30: =(N$27+N$28+N$25+N$20) -> 101.19796 | ... Z30: =(Z$27+Z$28+Z$25+Z$20) -> 102.1855
D31: CN | G31: =(100-G$33-G$34)/(1+(G$28/G$27)) -> 83.775429 | H31: =(100-H$33-H$34)/(1+(H$28/H$27)) -> 83.917578 | I31: =(100-I$33-I$34)/(1+(I$28/I$27)) -> 84.251927 | J31: =(100-J$33-J$34)/(1+(J$28/J$27)) -> 86.354126 | K31: =(100-K$33-K$34)/(1+(K$28/K$27)) -> 86.93959 | L31: =(100-L$33-L$34)/(1+(L$28/L$27)) -> 86.533725 | M31: =(100-M$33-M$34)/(1+(M$28/M$27)) -> 86.056084 | N31: =(100-N$33-N$34)/(1+(N$28/N$27)) -> 87.264603 | ... Z31: =(100-Z$33-Z$34)/(1+(Z$28/Z$27)) -> 86.440836
D32: HN | F32: %wt | G32: =G$31*(G$28/G$27) -> 9.7199768 | H32: =H$31*(H$28/H$27) -> 9.664749 | I32: =I$31*(I$28/I$27) -> 9.7428109 | J32: =J$31*(J$28/J$27) -> 10.980543 | K32: =K$31*(K$28/K$27) -> 10.437495 | L32: =L$31*(L$28/L$27) -> 10.817947 | M32: =M$31*(M$28/M$27) -> 11.243508 | N32: =N$31*(N$28/N$27) -> 11.433037 | ... Z32: =Z$31*(Z$28/Z$27) -> 11.606343
D33: NN | G33: =G$25*100/G$30 -> 0.55654866 | H33: =H$25*100/H$30 -> 0.73663759 | I33: =I$25*100/I$30 -> 0.7825577 | J33: =J$25*100/J$30 -> 0.37118157 | K33: =K$25*100/K$30 -> 0.37924876 | L33: =L$25*100/L$30 -> 0.34877535 | M33: =M$25*100/M$30 -> 0.3750457 | N33: =N$25*100/N$30 -> 0.30431641 | ... Z33: =Z$25*100/Z$30 -> 0.62777987
D34: SN | G34: =G$20*100/G$30 -> 5.9480455 | H34: =H$20*100/H$30 -> 5.6810353 | I34: =I$20*100/I$30 -> 5.2227039 | J34: =J$20*100/J$30 -> 2.2941491 | K34: =K$20*100/K$30 -> 2.2436661 | L34: =L$20*100/L$30 -> 2.2995527 | M34: =M$20*100/M$30 -> 2.325362 | N34: =N$20*100/N$30 -> 0.99804381 | ... Z34: =Z$20*100/Z$30 -> 1.3250412
D35: HN/CN | G35: =G$32/G$31 -> 0.1160242 | H35: =H$32/H$31 -> 0.11516954 | I35: =I$32/I$31 -> 0.11563903 | J35: =J$32/J$31 -> 0.12715713 | K35: =K$32/K$31 -> 0.12005457 | L35: =L$32/L$31 -> 0.12501423 | M35: =M$32/M$31 -> 0.13065327 | N35: =N$32/N$31 -> 0.13101574 | ... Z35: =Z$32/Z$31 -> 0.13426922
D36: C | G36: =G27*100/G30 -> 83.775429
D37: H | G37: =G28*100/G30 -> 9.7199768
D38: N | G38: =G29*100/G30 -> 0.56340491
D39: S | G39: =G20*100/G30 -> 5.9480455
D40: H/C | G40: =G37/G36 -> 0.1160242
...

Sheet LCF ABQ3358 Products
A1: Thaioil Laboratory Worksheet
L2: Update by: | M2: SCSE
L3: Update Date: | M3: 45684
A5: Properties | B5: Method | C5: Unit | D5: LCF FEED | E5: NAPHTHA | F5: KERO PLUS | G5: KERO | H5: GO | I5: LR | J5: VGO | K5: VTB | M5: LABIX (150 - 250 oC)
A6: CP range request | E6: IBP-160 | F6: 160-FBP | G6: 160-250 | H6: 250-360 | I6: 360-FBP | J6: 360-560 | K6: 560+ | M6: UOP-411 (%wt.) | Q6: Boiling Point
A7: %Yield by SIMDIST | B7: ASTM D-7169 | C7: %wt. | M7: n-Heptane (C7) and lighter | N7: x | Q7: 98.4
A8: %Yield by Autodest | B8: ASTM D-2892 | C8: %wt. | M8: n-Octane (C8) | N8: x | Q8: 125.1
A9: Density | B9: ASTM D-4052 | C9: kg/l | J9: 0.9577 | M9: n-Nonane (C9) | N9: x | Q9: 150.8
B10: API Gravity | C10: API | J10: 16.1 | M10: n-Decane (C10) | N10: x | Q10: 174.1
A11: Relative Density@25/25 oC | B11: ASTM D-70 | M11: n-Undecane (C11) | N11: x | Q11: 195.9
A12: RVP | B12: ASTM D-323 | C12: psi | M12: n-Dodecane (C12) | N12: x | Q12: 216.3
A13: Viscosity @ -20 oC | B13: ASTM D-445 | C13: cSt. | M13: n-Tridecame (C13) | N13: x | Q13: 234.8
A14: Viscosity @ 40 oC | M14: n-Tetradecane (C14) | N14: x | Q14: 252
A15: Viscosity @ 50 oC | M15: n-Pentadecane(C15) | N15: x | Q15: 267
A16: Viscosity @ 100 oC | M16: n-Hexadecane+ (C16+) | N16: x | Q16: 287
A17: Viscosity @ 150 oC | M17: TNP | N17: x
A18: Sulfur | B18: ASTM D-4294 | C18: %wt | J18: 1.183 | K18: 2.323 | M18: TNN | N18: x
C19: ppmw | J19: =J18*10000 -> 11830 | K19: =K18*10000 -> 23230
B20: ASTM D-2622 | C20: ppmw
A21: Mercaptan | B21: ASTM D-3227 | C21: ppmw | M21: Naphtha Component (%wt)
A22: Freezing point | B22: ASTM D-2386 | C22: °C | M22: ASTM D6839 | N22: 15-180 | Q22: ~49.3
A23: Flash point | B23: IP-170 | C23: °C | M23: C5 Naphthenes | N23: x | Q23: ~27.8
B24: ASTM D-93 | C24: °C | M24: C5 i-Paraffins | N24: x | Q24: ~36.1
A25: Acidity | B25: ASTM D-3242 | C25: mgKOH/g | M25: C5 n-Paraffins | N25: x | Q25: ~80.1
B26: ASTM D-664 | M26: C6 Aromatics | N26: x | Q26: ~80.7
A27: Total Nitrogen | B27: ASTM D5762 | C27: ppmw | J27: 3192 | K27: 3613 | M27: C6 Naphthenes | N27: x | Q27: ~60.3
A28: Basic Nitrogen | B28: SMS-1468 | C28: ppmw | M28: C6 i-Paraffins | N28: x | Q28: ~68.7
A29: C | B29: ASTM D5291 | C29: %wt | J29: 88.72 | K29: 88.95 | M29: C6 n-Paraffins | N29: x | Q29: ~110.6
A30: H | C30: %wt | J30: 11.25 | K30: 10.02 | M30: C7 Aromatics | N30: x
A31: N | C31: %wt | J31: 22.96 | K31: 25.46 | L31: ค่า N ที่สูง ต้องรอเปลี่ยน Copper stick | M31: C7 Naphthenes | N31: x
A32: Pour point | B32: ASTM D-97 | C32: °C | M32: C7 i-Paraffins | N32: x
A33: Nickle | B33: UOP-389 | C33: ppmw | J33: 0.15 | K33: 29.65 | M33: C7 n-Paraffins | N33: x | Q33: ~101
A34: Vanadium | J34: 0.48 | K34: 10.28 | M34: C8 Aromatics | N34: x | Q34: ~90
A35: Sodium | J35: 28.04 | K35: 33.25 | M35: C8 Naphthenes | N35: x | Q35: ~98.4
A36: Calcium | J36: 2.16 | K36: 11.7 | M36: C8 i-Paraffins | N36: x
A37: Iron | J37: 22.62 | K37: 11.05 | M37: C8 n-Paraffins | N37: x | Q37: ~138 (average, depends on isomer)
A38: Si | M38: C9 Aromatics | N38: x | Q38: ~150.8
A39: Iso-Parrafin | B39: ASTM D-6839 (GC) | C39: %wt | M39: C9 i-Paraffins | N39: x | Q39: ~99.2
A40: N-Parrafin | M40: C9 n-Paraffins | N40: x | Q40: ~125.7
A41: Naphthene | M41: C10+ Aromatics | N41: x | Q41: ~176 (depends on isomer)
...

Sheet LCF LS Products
A1: Thaioil Laboratory Worksheet
L2: Update by: | M2: SCSE
L3: Update Date: | M3: 45684
A5: Properties | B5: Method | C5: Unit | D5: LCF FEED | E5: NAPHTHA | F5: KERO PLUS | G5: KERO | H5: GO | I5: LR | J5: VGO | K5: VTB | M5: LABIX (150 - 250 oC)
A6: CP range request | E6: IBP-160 | F6: 160-FBP | G6: 160-250 | H6: 250-360 | I6: 360-FBP | J6: 360-560 | K6: 560+ | M6: UOP-411 (%wt.) | Q6: Boiling Point
A7: %Yield by SIMDIST | B7: ASTM D-7169 | C7: %wt. | E7: 2.4 | G7: 7.3 | H7: 14.7 | J7: 35.7 | K7: 40 | M7: n-Heptane (C7) and lighter | N7: x | Q7: 98.4
A8: %Yield by Autodest | B8: ASTM D-2892 | C8: %wt. | E8: 3 | G8: 7.2 | H8: 15.3 | J8: 32.3 | K8: 42.2 | M8: n-Octane (C8) | N8: x | Q8: 125.1
A9: Density | B9: ASTM D-4052 | C9: kg/l | E9: 0.7625 | G9: 0.8119 | H9: 0.8723 | J9: 0.9442 | M9: n-Nonane (C9) | N9: x | Q9: 150.8
B10: API Gravity | C10: API | E10: 53.9 | G10: 42.6 | H10: 30.6 | J10: 18.2 | M10: n-Decane (C10) | N10: x | Q10: 174.1
A11: Relative Density@25/25 oC | B11: ASTM D-70 | M11: n-Undecane (C11) | N11: x | Q11: 195.9
A12: RVP | B12: ASTM D-323 | C12: psi | M12: n-Dodecane (C12) | N12: x | Q12: 216.3
A13: Viscosity @ -20 oC | B13: ASTM D-445 | C13: cSt. | M13: n-Tridecame (C13) | N13: x | Q13: 234.8
A14: Viscosity @ 40 oC | M14: n-Tetradecane (C14) | N14: x | Q14: 252
A15: Viscosity @ 50 oC | M15: n-Pentadecane(C15) | N15: x | Q15: 267
A16: Viscosity @ 100 oC | M16: n-Hexadecane+ (C16+) | N16: x | Q16: 287
A17: Viscosity @ 150 oC | M17: TNP | N17: x
A18: Sulfur | B18: ASTM D-4294 | C18: %wt | J18: 0.967 | K18: 2.113 | M18: TNN | N18: x
C19: ppmw | E19: 253 | G19: 240 | H19: 2310 | J19: =J18*10000 -> 9670 | K19: =K18*10000 -> 21130
B20: ASTM D-2622 | C20: ppmw
A21: Mercaptan | B21: ASTM D-3227 | C21: ppmw | M21: Naphtha Component (%wt)
A22: Freezing point | B22: ASTM D-2386 | C22: °C | M22: ASTM D6839 | N22: 15-180 | Q22: ~49.3
A23: Flash point | B23: IP-170 | C23: °C | M23: C5 Naphthenes | N23: x | Q23: ~27.8
B24: ASTM D-93 | C24: °C | M24: C5 i-Paraffins | N24: x | Q24: ~36.1
A25: Acidity | B25: ASTM D-3242 | C25: mgKOH/g | M25: C5 n-Paraffins | N25: x | Q25: ~80.1
B26: ASTM D-664 | M26: C6 Aromatics | N26: x | Q26: ~80.7
A27: Total Nitrogen | B27: ASTM D5762 | C27: ppmw | E27: 74 | G27: 1027 | H27: 1472 | J27: 4325 | K27: 7675 | M27: C6 Naphthenes | N27: x | Q27: ~60.3
A28: Basic Nitrogen | B28: SMS-1468 | C28: ppmw | M28: C6 i-Paraffins | N28: x | Q28: ~68.7
A29: C | B29: ASTM D5291 | C29: %wt | J29: 88.59 | K29: 88.13 | M29: C6 n-Paraffins | N29: x | Q29: ~110.6
A30: H | C30: %wt | J30: 11.56 | K30: 9.83 | M30: C7 Aromatics | N30: x
A31: N | C31: %wt | J31: 7.9 | K31: 18.71 | L31: ค่า N ที่สูง ต้องรอเปลี่ยน Copper stick | M31: C7 Naphthenes | N31: x
A32: Pour point | B32: ASTM D-97 | C32: °C | M32: C7 i-Paraffins | N32: x | Y32: LCF VGO ABQ_3358 | Z32: LCF VTB ABQ_3358 | AA32: LCF VGO LS | AB32: LCF VTB LS | AC32: LCF VGO HS | AD32: LCF VTB HS
A33: Nickle | B33: UOP-389 | C33: ppmw | J33: 0.13 | K33: 50.7 | M33: C7 n-Paraffins | N33: x | Q33: ~101 | X33: Ni | Y33: 0.15 | Z33: 29.65 | AA33: 0.13 | AB33: 50.7 | AC33: 0.2 | AD33: 52.5
A34: Vanadium | J34: 0 | K34: 47.5 | M34: C8 Aromatics | N34: x | Q34: ~90 | X34: V | Y34: 0.48 | Z34: 10.28 | AA34: 0 | AB34: 47.5 | AC34: 0 | AD34: 48.6
A35: Sodium | J35: 37.15 | K35: 22.9 | M35: C8 Naphthenes | N35: x | Q35: ~98.4 | X35: Na | Y35: 28.04 | Z35: 33.25 | AA35: 37.15 | AB35: 22.9 | AC35: 42.2 | AD35: 24
A36: Calcium | J36: 15.25 | K36: 1.2 | X36: Ca | Y36: 2.16 | Z36: 11.7 | AA36: 15.25 | AB36: 1.2 | AC36: 13.8 | AD36: 3.5
A37: Iron | J37: 2.12 | K37: 6.6 | M37: C8 i-Paraffins | N37: x | X37: Fe | Y37: 22.62 | Z37: 11.05 | AA37: 2.12 | AB37: 6.6 | AC37: 10.9 | AD37: 6.5
A38: Si | M38: C8 n-Paraffins | N38: x | Q38: ~138 (average, depends on isomer)
A39: Iso-Parrafin | B39: ASTM D-6839 (GC) | C39: %wt | M39: C9 Aromatics | N39: x | Q39: ~150.8 | Y39: LCF VGO ABQ_3358 | Z39: LCF VTB ABQ_3358 | AA39: LCF VGO LS | AB39: LCF VTB LS | AC39: LCF VGO HS | AD39: LCF VTB HS
A40: N-Parrafin | M40: C9 i-Paraffins | N40: x | Q40: ~99.2 | X40: S | Y40: 25.5 | Z40: 0 | AA40: 32.4 | AB40: 0 | AC40: 34 | AD40: 4.6
A41: Naphthene | M41: C9 n-Paraffins | N41: x | Q41: ~125.7 | X41: A | Y41: 73.9 | Z41: 68.8 | AA41: 66.9 | AB41: 53.6 | AC41: 64.9 | AD41: 43.1
...

Sheet LCF HS Products
A1: Thaioil Laboratory Worksheet
L2: Update by: | M2: SCSE
L3: Update Date: | M3: 45684
A5: Properties | B5: Method | C5: Unit | D5: LCF FEED | E5: NAPHTHA | F5: KERO PLUS | G5: KERO | H5: GO | I5: LR | J5: VGO | K5: VTB | M5: LABIX (150 - 250 oC)
A6: CP range request | E6: IBP-160 | F6: 160-FBP | G6: 160-250 | H6: 250-360 | I6: 360-FBP | J6: 360-560 | K6: 560+ | M6: UOP-411 (%wt.) | Q6: Boiling Point
A7: %Yield by SIMDIST | B7: ASTM D-7169 | C7: %wt. | E7: 3.058 | G7: 10.155 | H7: 15.764 | J7: 32.634 | K7: 38.389 | M7: n-Heptane (C7) and lighter | N7: x | Q7: 98.4
A8: %Yield by Autodest | B8: ASTM D-2892 | C8: %wt. | M8: n-Octane (C8) | N8: x | Q8: 125.1
A9: Density | B9: ASTM D-4052 | C9: kg/l | E9: 0.7446 | G9: 0.8047 | H9: 0.8706 | J9: 0.9391 | M9: n-Nonane (C9) | N9: x | Q9: 150.8
B10: API Gravity | C10: API | E10: 58.3 | G10: 44.2 | H10: 30.9 | J10: 19 | M10: n-Decane (C10) | N10: x | Q10: 174.1
A11: Relative Density@25/25 oC | B11: ASTM D-70 | M11: n-Undecane (C11) | N11: x | Q11: 195.9
A12: RVP | B12: ASTM D-323 | C12: psi | M12: n-Dodecane (C12) | N12: x | Q12: 216.3
A13: Viscosity @ -20 oC | B13: ASTM D-445 | C13: cSt. | M13: n-Tridecame (C13) | N13: x | Q13: 234.8
A14: Viscosity @ 40 oC | M14: n-Tetradecane (C14) | N14: x | Q14: 252
A15: Viscosity @ 50 oC | M15: n-Pentadecane(C15) | N15: x | Q15: 267
A16: Viscosity @ 100 oC | M16: n-Hexadecane+ (C16+) | N16: x | Q16: 287
A17: Viscosity @ 150 oC | M17: TNP | N17: x
A18: Sulfur | B18: ASTM D-4294 | C18: %wt | J18: 0.91 | K18: 5.606 | M18: TNN | N18: x
C19: ppmw | E19: 247.835 | G19: 336.9 | H19: 2750 | J19: 9100 | K19: =K18*10000 -> 56060
B20: ASTM D-2622 | C20: ppmw
A21: Mercaptan | B21: ASTM D-3227 | C21: ppmw | M21: Naphtha Component (%wt)
A22: Freezing point | B22: ASTM D-2386 | C22: °C | M22: ASTM D6839 | N22: 15-180 | Q22: ~49.3
A23: Flash point | B23: IP-170 | C23: °C | M23: C5 Naphthenes | N23: x | Q23: ~27.8
B24: ASTM D-93 | C24: °C | M24: C5 i-Paraffins | N24: x | Q24: ~36.1
A25: Acidity | B25: ASTM D-3242 | C25: mgKOH/g | M25: C5 n-Paraffins | N25: x | Q25: ~80.1
B26: ASTM D-664 | M26: C6 Aromatics | N26: x | Q26: ~80.7
A27: Total Nitrogen | B27: ASTM D5762 | C27: ppmw | E27: 130.12 | G27: 964.55 | H27: 1926 | J27: 5243 | K27: 9436 | M27: C6 Naphthenes | N27: x | Q27: ~60.3
A28: Basic Nitrogen | B28: SMS-1468 | C28: ppmw | M28: C6 i-Paraffins | N28: x | Q28: ~68.7
A29: C | B29: ASTM D5291 | C29: %wt | J29: 86.8 | K29: 88.26 | M29: C6 n-Paraffins | N29: x | Q29: ~110.6
A30: H | C30: %wt | J30: 11.43 | K30: 9.82 | M30: C7 Aromatics | N30: x
A31: N | C31: %wt | J31: 13.6 | K31: 18.68 | L31: ค่า N ที่สูง ต้องรอเปลี่ยน Copper stick | M31: C7 Naphthenes | N31: x
A32: Pour point | B32: ASTM D-97 | C32: °C | M32: C7 i-Paraffins | N32: x
A33: Nickle | B33: UOP-389 | C33: ppmw | J33: 0.2 | K33: 52.5 | M33: C7 n-Paraffins | N33: x | Q33: ~101
A34: Vanadium | J34: 0 | K34: 48.6 | M34: C8 Aromatics | N34: x | Q34: ~90
A35: Sodium | J35: 42.2 | K35: 24 | M35: C8 Naphthenes | N35: x | Q35: ~98.4
A36: Calcium | J36: 13.8 | K36: 3.5 | M36: C8 i-Paraffins | N36: x
A37: Iron | J37: 10.9 | K37: 6.5 | M37: C8 n-Paraffins | N37: x | Q37: ~138 (average, depends on isomer)
A38: Si | M38: C9 Aromatics | N38: x | Q38: ~150.8
A39: Iso-Parrafin | B39: ASTM D-6839 (GC) | C39: %wt | M39: C9 i-Paraffins | N39: x | Q39: ~99.2
A40: N-Parrafin | M40: C9 n-Paraffins | N40: x | Q40: ~125.7
A41: Naphthene | M41: C10+ Aromatics | N41: x | Q41: ~176 (depends on isomer)
...

Sheet SCEP FULL TEST
A1: Thaioil Laboratory Worksheet
T2: Update by: | U2: SCSE
T3: Update Date: | U3: 45684
A5: Properties | B5: Method | C5: Unit | D5: Crude | E5: LPG | F5: TOP | G5: HN | H5: HN/KERO | I5: KERO | J5: KERO/GO | K5: GO | L5: GO | M5: LR | N5: L-Waxy | O5: H-Waxy | P5: SR | R5: KERO | T5: LABIX (150 - 250 oC)
A6: CP range request | F6: 15-85 | G6: 85-150 | H6: 150-180 | I6: 180-220 | J6: 220-250 | K6: 250-300 | L6: 300-360 | M6: 360-FBP | N6: 360-525 | O6: 525-575 | P6: 575+ | R6: 150-250 | T6: UOP-411 (%wt.) | X6: Boiling Point
A7: %Yield by SIMDIST | B7: ASTM D-7169 | C7: %wt. | E7: x | F7: x | G7: x | H7: x | I7: x | J7: x | K7: x | L7: x | N7: x | O7: x | P7: x | T7: n-Heptane (C7) and lighter | U7: x | X7: 98.4
A8: %Yield by Autodest | B8: ASTM D-2892 | C8: %wt. | E8: x | F8: x | G8: x | H8: x | I8: x | J8: x | K8: x | L8: x | N8: x | O8: x | P8: x | R8: x | T8: n-Octane (C8) | U8: x | X8: 125.1
A9: Density | B9: ASTM D-4052 | C9: kg/l | F9: x | G9: x | H9: x | I9: x | J9: x | K9: x | L9: x | M9: x | R9: x | T9: n-Nonane (C9) | U9: x | X9: 150.8
B10: ASTM D-1298 | C10: kg/l | T10: n-Decane (C10) | U10: x | X10: 174.1
A11: Relative Density@25/25 oC | B11: ASTM D-70 | P11: x | T11: n-Undecane (C11) | U11: x | X11: 195.9
A12: RVP | B12: ASTM D-323 | C12: psi | D12: x | T12: n-Dodecane (C12) | U12: x | X12: 216.3
A13: Viscosity @ -20 oC | B13: ASTM D-445 | C13: cSt. | I13: x | J13: x | T13: n-Tridecame (C13) | U13: x | X13: 234.8
A14: Viscosity @ 40 oC | D14: x | K14: x | L14: x | T14: n-Tetradecane (C14) | U14: x | X14: 252
A15: Viscosity @ 50 oC | T15: n-Pentadecane(C15) | U15: x | X15: 267
A16: Viscosity @ 100 oC | O16: x | P16: x | T16: n-Hexadecane+ (C16+) | U16: x | X16: 287
A17: Viscosity @ 130 oC | T17: TNP | U17: x
A18: Sulfur | B18: ASTM D-4294 | C18: %wt | D18: x | N18: x | O18: x | P18: x | T18: TNN | U18: x
B19: ASTM D-2622 | C19: %wt | H19: x | I19: x | J19: x | K19: x | L19: x | R19: x
C20: ppmw
A21: Mercaptan | B21: ASTM D-3227 | C21: ppmw | D21: x | F21: x | H21: x | I21: x | J21: x | K21: x | R21: x | T21: Naphtha Component (%wt)
A22: Freezing point | B22: ASTM D-2386 | C22: °C | H22: x | I22: x | J22: x | K22: x | T22: ASTM D6839 | U22: 15-180 | X22: ~49.3
A23: Flash point | B23: IP-170 | C23: °C | H23: x | I23: x | T23: C5 Naphthenes | U23: x | X23: ~27.8
B24: ASTM D-93 | C24: °C | J24: x | K24: x | L24: x | T24: C5 i-Paraffins | U24: x | X24: ~36.1
A25: Acidity | B25: ASTM D-3242 | C25: mgKOH/g | T25: C5 n-Paraffins | U25: x | X25: ~80.1
B26: ASTM D-664 | D26: x | M26: x | N26: x | O26: x | P26: x | T26: C6 Aromatics | U26: x | X26: ~80.7
A27: Total Nitrogen | B27: ASTM D-4629 | C27: ppmw | D27: x | F27: x | G27: x | H27: x | I27: x | J27: x | K27: x | L27: x | N27: x | O27: x | T27: C6 Naphthenes | U27: x | X27: ~60.3
A28: Basic Nitrogen | B28: SMS-1468 | C28: ppmw | D28: x | N28: x | O28: x | T28: C6 i-Paraffins | U28: x | X28: ~68.7
A29: Pour point | B29: ASTM D-97 | C29: °C | D29: x | T29: C6 n-Paraffins | U29: x | X29: ~110.6
A30: Nickle | B30: IP501 | C30: ppmw | K30: x | L30: x | P30: x | T30: C7 Aromatics | U30: x
A31: Vanadium | K31: x | L31: x | P31: x | T31: C7 Naphthenes | U31: x
A32: Sodium | P32: x | T32: C7 i-Paraffins | U32: x
A33: Nickle | B33: UOP-389 | C33: ppmw | O33: x | T33: C7 n-Paraffins | U33: x | X33: ~101
A34: Vanadium | O34: x | T34: C8 Aromatics | U34: x | X34: ~90
A35: Sodium | O35: x | T35: C8 Naphthenes | U35: x | X35: ~98.4
A36: Si | K36: x | L36: x | T36: C8 i-Paraffins | U36: x
A37: Iso-Parrafin | B37: ASTM D-6839 (GC) | C37: %wt | F37: x | T37: C8 n-Paraffins | U37: x | X37: ~138 (average, depends on isomer)
A38: N-Parrafin | F38: x | T38: C9 Aromatics | U38: x | X38: ~150.8
A39: Naphthene | F39: x | T39: C9 i-Paraffins | U39: x | X39: ~99.2
A40: Aromatic | F40: x | T40: C9 n-Paraffins | U40: x | X40: ~125.7
A41: Olefin | F41: x | T41: C10+ Aromatics | U41: x | X41: ~176 (depends on isomer)
...

Sheet CII
P8: 4.5 | Q8: -5
P9: 4.5 | Q9: 100
P11: 10.5 | Q11: -5
P12: 10.5 | Q12: 100

Sheet HPS LTO DAILY 
D1: RHCU Pilot Plant Laboratory Worksheet
D2: Batch Name : | J2: Low&High Sedimentation
D3: Date : | J3: 17/07-01/8/2025
D4: Note : | J4: MEBU ACCEPTANCE TEST
AQ5: LS_D3 ART
J6: ABQ3358 | N6: Low Sedim | T6: High Sedim | AQ6: 01WT% | AR6: 1 | AS6: 170.44444
G7: FEED | H7: FEED | I7: FEED | J7: 1 | K7: 2 | L7: 3 | M7: 4 | N7: 5 | O7: 6 | P7: 7 | Q7: 8 | R7: 9 | S7: 10 | T7: 11 | U7: 12 | V7: 13 | W7: 14 | X7: 15 | Y7: 16_1 | Z7: 16_2 | AQ7: 02WT% | AR7: 2 | AS7: 197.11111
D8: HPS | G8: ABQ3358 | H8: LowSed | I8: HighSed | AQ8: 03WT% | AR8: 3 | AS8: 216.05556
D9: SIMDIST | E9: 500 | F9: 560 | G9: FEED | H9: LS Feed | I9: HS Feed | J9: 45856 | K9: 45857 | L9: 45858 | M9: 45859 | N9: 45860 | O9: 45861 | P9: 45862 | Q9: 45863 | R9: 45864 | S9: 45865 | T9: 45866 | U9: 45867 | V9: 45868 | W9: 45869 | X9: 45870 | Y9: 45871 | Z9: 45872 | AB9: Time-On-Stream (Day) | AC9: LTO API (Degree) | AD9: HPS API (Degree) | AE9: 4.5 | AF9: -5 | AQ9: 04WT% | AR9: 4 | AS9: 230.11111
D10: 0 | E10: 500 | F10: 560 | G10: 375.98 | H10: 462.3 | I10: 436.7 | J10: 142.1 | K10: 140.2 | L10: 152.5 | M10: 133.6 | N10: 95.5 | O10: 110.4 | P10: 111.6 | Q10: 96.3 | R10: 123.5 | S10: 111.7 | T10: 68.7 | U10: 107.7 | V10: 121.9 | W10: 77 | X10: 114.7 | Y10: 116.5 | Z10: 116.6 | AE10: 4.5 | AF10: 105 | AN10: 0 | AO10: 560 | AQ10: 05WT% | AR10: 5 | AS10: 243.72222
D11: 1 | E11: 500 | F11: 560 | G11: 402 | H11: 528.9 | I11: 499.2 | J11: 173.4 | K11: 187.3 | L11: 185.3 | M11: 179.1 | N11: 125.7 | O11: 133.4 | P11: 136.2 | Q11: 132.8 | R11: 142.9 | S11: 137.3 | T11: 92.1 | U11: 128.6 | V11: 144.2 | W11: 116.1 | X11: 133.9 | Y11: 141.6 | Z11: 141.3 | AB11: 1 | AC11: 41.2 | AD11: 12.4 | AE11: 10.5 | AN11: 120 | AO11: 560 | AQ11: 06WT% | AR11: 6 | AS11: 254.66667
D12: 2 | E12: 500 | F12: 560 | G12: 422 | H12: 546.9 | I12: 527.2 | J12: 215 | K12: 232 | L12: 226.6 | M12: 224.9 | N12: 155.6 | O12: 162.3 | P12: 162.8 | Q12: 163.4 | R12: 168.1 | S12: 163.2 | T12: 139.4 | U12: 158.9 | V12: 169.7 | W12: 147.8 | X12: 158.2 | Y12: 170.7 | Z12: 165.7 | AB12: 2 | AC12: 41.6 | AD12: 12.2 | AE12: 10.5 | AQ12: 07WT% | AR12: 7 | AS12: 265.83333
D13: 3 | E13: 500 | F13: 560 | G13: 462 | H13: 555.2 | I13: 538.6 | J13: 248.3 | K13: 261.4 | L13: 255 | M13: 255.3 | N13: 174.7 | O13: 180.8 | P13: 181.4 | Q13: 183.2 | R13: 183.5 | S13: 180.4 | T13: 162.4 | U13: 177 | V13: 185.8 | W13: 168.4 | X13: 174.9 | Y13: 190.5 | Z13: 184.1 | AB13: 3 | AC13: 42 | AD13: 11.5 | AQ13: 08WT% | AR13: 8 | AS13: 275.55556
D14: 4 | E14: 500 | F14: 560 | G14: 489 | H14: 561 | I14: 546.5 | J14: 270.7 | K14: 285.2 | L14: 279.1 | M14: 279.7 | N14: 190.5 | O14: 196.7 | P14: 196.4 | Q14: 198.4 | R14: 197.7 | S14: 196.6 | T14: 178.2 | U14: 193.2 | V14: 200.3 | W14: 182.3 | X14: 188.3 | Y14: 205.1 | Z14: 199.2 | AB14: 4 | AC14: 42.5 | AD14: 11.3 | AN14: 0 | AO14: 160 | AQ14: 09WT% | AR14: 9 | AS14: 285.94444
D15: 5 | E15: 500 | F15: 560 | G15: 510 | H15: 565.7 | I15: 553.1 | J15: 291.2 | K15: 305.6 | L15: 299.2 | M15: 300.9 | N15: 203.2 | O15: 211.2 | P15: 209.9 | Q15: 211.3 | R15: 209.7 | S15: 210.8 | T15: 193.1 | U15: 206 | V15: 212.1 | W15: 195.3 | X15: 200.3 | Y15: 217.3 | Z15: 213.1 | AB15: 5 | AC15: 43 | AD15: 16 | AN15: 120 | AO15: 160 | AQ15: 10WT% | AR15: 10 | AS15: 293.94444
D16: 6 | E16: 500 | F16: 560 | G16: 518 | H16: 569.7 | I16: 558.5 | J16: 308.6 | K16: 323.2 | L16: 317.3 | M16: 317.7 | N16: 216 | O16: 222.6 | P16: 220.8 | Q16: 222.5 | R16: 220.4 | S16: 222.9 | T16: 204.4 | U16: 217.6 | V16: 221.4 | W16: 206.1 | X16: 210 | Y16: 229.1 | Z16: 224.4 | AB16: 6 | AC16: 44.6 | AD16: 15.8 | AQ16: 11WT% | AR16: 11 | AS16: 301.94444
D17: 7 | E17: 500 | F17: 560 | G17: 525 | H17: 573.2 | I17: 563.2 | J17: 324.2 | K17: 338.6 | L17: 332.5 | M17: 332.7 | N17: 226 | O17: 234 | P17: 231.5 | Q17: 233.1 | R17: 230.6 | S17: 235.2 | T17: 215.7 | U17: 228.8 | V17: 231.3 | W17: 216.3 | X17: 219.1 | Y17: 239.5 | Z17: 235.2 | AB17: 7 | AC17: 44.8 | AD17: 15.8 | AN17: 0 | AO17: 360 | AQ17: 12WT% | AR17: 12 | AS17: 309.33333
D18: 8 | E18: 500 | F18: 560 | G18: 533 | H18: 576.7 | I18: 567.4 | J18: 338.5 | K18: 351.3 | L18: 345.5 | M18: 345.9 | N18: 235.1 | O18: 244.8 | P18: 241.8 | Q18: 242.9 | R18: 239.8 | S18: 246.7 | T18: 225.7 | U18: 238.3 | V18: 239.7 | W18: 224.8 | X18: 227.7 | Y18: 250.3 | Z18: 246.7 | AB18: 8 | AC18: 44.5 | AD18: 15.8 | AN18: 120 | AO18: 360 | AQ18: 13WT% | AR18: 13 | AS18: 316.44444
D19: 9 | E19: 500 | F19: 560 | G19: 538 | H19: 580.1 | I19: 571.1 | J19: 351.6 | K19: 362.4 | L19: 356.3 | M19: 357.3 | N19: 245.2 | O19: 253.6 | P19: 250.5 | Q19: 252.7 | R19: 249.9 | S19: 256.4 | T19: 234.8 | U19: 249.4 | V19: 249.7 | W19: 233.9 | X19: 236 | Y19: 259.7 | Z19: 255.5 | AB19: 9 | AC19: 45 | AD19: 15.7 | AQ19: 14WT% | AR19: 14 | AS19: 323.94444
D20: 10 | E20: 500 | F20: 560 | G20: 543.5 | H20: 583.4 | I20: 574.7 | J20: 363.5 | K20: 374.1 | L20: 366.7 | M20: 367.8 | N20: 253.3 | O20: 264 | P20: 260.3 | Q20: 261.9 | R20: 258.4 | S20: 267.8 | T20: 245 | U20: 258.1 | V20: 257 | W20: 242.2 | X20: 244.6 | Y20: 268.8 | Z20: 266 | AB20: 10 | AC20: 44.6 | AD20: 15.7 | AN20: 0 | AO20: 560 | AQ20: 15WT% | AR20: 15 | AS20: 330.77778
D21: 11 | E21: 500 | F21: 560 | G21: 548 | H21: 586.6 | I21: 578.2 | J21: 374.4 | K21: 387.1 | L21: 378.3 | M21: 379.7 | N21: 262.5 | O21: 273.1 | P21: 268.3 | Q21: 271.3 | R21: 267.8 | S21: 277.8 | T21: 253.3 | U21: 268 | V21: 266.5 | W21: 250.8 | X21: 252.3 | Y21: 278.4 | Z21: 275.2 | AB21: 11 | AC21: 45 | AD21: 15.6 | AN21: 120 | AO21: 560 | AQ21: 16WT% | AR21: 16 | AS21: 338.05556
D22: 12 | E22: 500 | F22: 560 | G22: 553 | H22: 589.6 | I22: 581.7 | J22: 384.5 | K22: 397.2 | L22: 390.2 | M22: 391.3 | N22: 270.2 | O22: 283 | P22: 278.1 | Q22: 280.6 | R22: 276.9 | S22: 287.1 | T22: 262.7 | U22: 276.9 | V22: 274 | W22: 258.3 | X22: 260.2 | Y22: 286.6 | Z22: 284.9 | AB22: 12 | AC22: 45 | AD22: 15 | AQ22: 17WT% | AR22: 17 | AS22: 344.66667
D23: 13 | E23: 500 | F23: 560 | G23: 556 | H23: 592.6 | I23: 585.1 | J23: 394.2 | K23: 406 | L23: 398.9 | M23: 400 | N23: 278.8 | O23: 291.5 | P23: 286.4 | Q23: 288.6 | R23: 286.1 | S23: 296.8 | T23: 270.5 | U23: 285.8 | V23: 283.3 | W23: 266.8 | X23: 268.2 | Y23: 295 | Z23: 293.3 | AB23: 13 | AC23: 45.2 | AD23: 15.6 | AQ23: 18WT% | AR23: 18 | AS23: 351.44444
D24: 14 | E24: 500 | F24: 560 | G24: 560 | H24: 595.6 | I24: 588.4 | J24: 404 | K24: 414.7 | L24: 407.3 | M24: 408.3 | N24: 286.4 | O24: 299.4 | P24: 294.6 | Q24: 296.9 | R24: 294.4 | S24: 305.2 | T24: 279.8 | U24: 293.9 | V24: 290.9 | W24: 274.4 | X24: 276.1 | Y24: 301.9 | Z24: 300.3 | AB24: 14 | AC24: 45.4 | AD24: 15.6 | AQ24: 19WT% | AR24: 19 | AS24: 357.22222
D25: 15 | E25: 500 | F25: 560 | G25: 563 | H25: 598.5 | I25: 591.6 | J25: 413.2 | K25: 424.4 | L25: 415.7 | M25: 417 | N25: 294.1 | O25: 306.9 | P25: 301.6 | Q25: 304.2 | R25: 301.9 | S25: 314.5 | T25: 287.4 | U25: 300.7 | V25: 298.7 | W25: 283.1 | X25: 284.1 | Y25: 310 | Z25: 308.4 | AB25: 15 | AC25: 45.5 | AD25: 15 | AQ25: 20WT% | AR25: 20 | AS25: 363.72222
D26: 16 | E26: 500 | F26: 560 | G26: 566 | H26: 601.4 | I26: 594.8 | J26: 421.9 | K26: 433.3 | L26: 424.9 | M26: 426.3 | N26: 301 | O26: 314.2 | P26: 309.5 | Q26: 312.2 | R26: 309.7 | S26: 322.2 | T26: 295.4 | U26: 308.5 | V26: 305.2 | W26: 290.5 | X26: 291.5 | Y26: 316.6 | Z26: 315.2 | AB26: 16 | AC26: 45.5 | AD26: 15.1 | AQ26: 21WT% | AR26: 21 | AS26: 369.5
D27: 17 | E27: 500 | F27: 560 | G27: 569 | H27: 604.4 | I27: 598 | J27: 430.1 | K27: 441.2 | L27: 433.3 | M27: 434.6 | N27: 308 | O27: 321.7 | P27: 316 | Q27: 319.1 | R27: 316.6 | S27: 330 | T27: 301.8 | U27: 314.9 | V27: 313 | W27: 297.9 | X27: 298.4 | Y27: 324.3 | Z27: 323.3 | AQ27: 22WT% | AR27: 22 | AS27: 375.66667
D28: 18 | E28: 500 | F28: 560 | G28: 572 | H28: 607.3 | I28: 601.2 | J28: 438.5 | K28: 448.8 | L28: 440.7 | M28: 442.1 | N28: 314.9 | O28: 328.5 | P28: 323.7 | Q28: 326.4 | R28: 324.2 | S28: 338.6 | T28: 309.6 | U28: 322.7 | V28: 319.2 | W28: 304.4 | X28: 304.9 | Y28: 330.8 | Z28: 330.2 | AQ28: 23WT% | AR28: 23 | AS28: 381.33333
D29: 19 | E29: 500 | F29: 560 | G29: 575 | H29: 610.2 | I29: 604.6 | J29: 446.5 | K29: 457.3 | L29: 448 | M29: 449.4 | N29: 321.3 | O29: 336.2 | P29: 330.2 | Q29: 333.1 | R29: 330.8 | S29: 346 | T29: 315.8 | U29: 329.1 | V29: 326.5 | W29: 311.8 | X29: 312 | Y29: 338.1 | Z29: 338 | AQ29: 24WT% | AR29: 24 | AS29: 387.44444
D30: 20 | E30: 500 | F30: 560 | G30: 578 | H30: 613.1 | I30: 607.9 | J30: 454.4 | K30: 465.4 | L30: 455.9 | M30: 457.4 | N30: 328.2 | O30: 342.6 | P30: 337.5 | Q30: 340.1 | R30: 338.2 | S30: 353.6 | T30: 323.2 | U30: 336.6 | V30: 332.5 | W30: 317.9 | X30: 318.2 | Y30: 344.6 | Z30: 344.7 | AQ30: 25WT% | AR30: 25 | AS30: 392.88889
D31: 21 | E31: 500 | F31: 560 | G31: 581 | H31: 616.1 | I31: 611.2 | J31: 462 | K31: 472.5 | L31: 463.6 | M31: 465.2 | N31: 334.2 | O31: 349.8 | P31: 343.9 | Q31: 346.8 | R31: 345 | S31: 360.1 | T31: 329.4 | U31: 343 | V31: 339.7 | W31: 325 | X31: 324.8 | Y31: 350.7 | Z31: 351 | AQ31: 26WT% | AR31: 26 | AS31: 398.72222
D32: 22 | E32: 500 | F32: 560 | G32: 584 | H32: 619.2 | I32: 614.5 | J32: 469.5 | K32: 479.5 | L32: 470.6 | M32: 472.3 | N32: 340.8 | O32: 355.6 | P32: 350.3 | Q32: 353.2 | R32: 351.8 | S32: 366.6 | T32: 336.6 | U32: 349.9 | V32: 345.6 | W32: 330.7 | X32: 330.7 | Y32: 356.8 | Z32: 357.6 | AQ32: 27WT% | AR32: 27 | AS32: 403.88889
D33: 23 | E33: 500 | F33: 560 | G33: 587 | H33: 622.3 | I33: 618 | J33: 476.7 | K33: 486.9 | L33: 477.3 | M33: 479 | N33: 346.4 | O33: 362.1 | P33: 355.9 | Q33: 359.5 | R33: 358.2 | S33: 374.8 | T33: 342.7 | U33: 355.6 | V33: 352.5 | W33: 337.9 | X33: 337.5 | Y33: 362.5 | Z33: 363.7 | AQ33: 28WT% | AR33: 28 | AS33: 409.44444
D34: 24 | E34: 500 | F34: 560 | G34: 590 | H34: 625.3 | I34: 621.5 | J34: 483.7 | K34: 494.3 | L34: 484.2 | M34: 486.1 | N34: 352.3 | O34: 368 | P34: 361.9 | Q34: 365.7 | R34: 364.6 | S34: 382.7 | T34: 349.4 | U34: 361.9 | V34: 358.2 | W34: 343.6 | X34: 343.1 | Y34: 369 | Z34: 371 | AQ34: 29WT% | AR34: 29 | AS34: 414.61111
D35: 25 | E35: 500 | F35: 560 | G35: 593 | H35: 628.4 | I35: 624.9 | J35: 490.4 | K35: 500.6 | L35: 491.3 | M35: 493.1 | N35: 357.5 | O35: 375.3 | P35: 367.7 | Q35: 372.3 | R35: 371.2 | S35: 390.7 | T35: 355 | U35: 367.8 | V35: 364.6 | W35: 350.5 | X35: 349.7 | Y35: 376.6 | Z35: 379 | AQ35: 30WT% | AR35: 30 | AS35: 420
D36: 26 | E36: 500 | F36: 560 | G36: 595 | H36: 631.4 | I36: 628.4 | J36: 496.8 | K36: 506.4 | L36: 497.8 | M36: 499.3 | N36: 363.2 | O36: 382.2 | P36: 374.1 | Q36: 378.5 | R36: 377.7 | S36: 397.6 | T36: 361.2 | U36: 374.9 | V36: 370.5 | W36: 355.8 | X36: 355 | Y36: 385 | Z36: 387.2 | AQ36: 31WT% | AR36: 31 | AS36: 424.94444
D37: 27 | E37: 500 | F37: 560 | G37: 598 | H37: 634.4 | I37: 631.8 | J37: 502.6 | K37: 512.4 | L37: 503.3 | M37: 505 | N37: 368.5 | O37: 389 | P37: 381.5 | Q37: 385.7 | R37: 385 | S37: 404.1 | T37: 366.8 | U37: 383.5 | V37: 377.3 | W37: 362.4 | X37: 361.3 | Y37: 392.1 | Z37: 394.6 | AQ37: 32WT% | AR37: 32 | AS37: 430.27778
D38: 28 | E38: 500 | F38: 560 | G38: 600 | H38: 637.5 | I38: 635.2 | J38: 508.1 | K38: 518.7 | L38: 508.7 | M38: 510.6 | N38: 375.1 | O38: 395.6 | P38: 388.1 | Q38: 391.8 | R38: 391.4 | S38: 410.6 | T38: 373.9 | U38: 391 | V38: 383.6 | W38: 367.8 | X38: 366.6 | Y38: 397.9 | Z38: 400.5 | AQ38: 33WT% | AR38: 33 | AS38: 435.33333
... D54: 44 | E54: 500 | F54: 560 | G54: 647 | H54: 702.9 | I54: 721.3 | J54: 573 | K54: 584.1 | L54: 575.8 | M54: 577.2 | N54: 465.4 | O54: 488.8 | P54: 479.2 | Q54: 481.6 | R54: 484.1 | S54: 511.1 | T54: 472.3 | U54: 489.4 | V54: 474.7 | W54: 460.6 | X54: 456.7 | Y54: 494.6 | Z54: 503.2 | AQ54: 49WT% | AR54: 49 | AS54: 513.11111
D55: 45 | E55: 500 | F55: 560 | G55: 650 | H55: 708.2 | I55: - | J55: 576.1 | K55: 587 | L55: 578.8 | M55: 580.2 | N55: 471 | O55: 494.6 | P55: 484.6 | Q55: 487.4 | R55: 490.1 | S55: 517 | T55: 478.1 | U55: 495.6 | V55: 480.1 | W55: 466.7 | X55: 463 | Y55: 500.1 | Z55: 508.8 | AQ55: 50WT% | AR55: 50 | AS55: 517.5
...

Sheet Lab Results Summary
F35: CrkConv avg | H35: =AVERAGE('Master Template'!J141:L141) -> 65.60365 | I35: % | J35: last 3 days

Sheet CatConv
G53: 4.5 | H53: -2
G54: 4.5 | H54: 150
G56: 10.5 | H56: -2
G57: 10.5 | H57: 150
X75: ART
X76: D | Y76: 6 | Z76: 8 | AA76: 12 | AB76: 14
W89: =17.4-2.3 -> 15.1

Sheet FeedStock_Summ
D2: ABQ 3358
D3: 50%BSH, 30%Arab light, 3% aromatic, and others .i.e. Arab medium
D4: Aging Feed | E4: Low Sedimentation | G4: High Sedimentation | J4: Single VR Property | X4: Assay
E5: ART | F5: TOP | G5: ART | H5: TOP | J5: BSH | K5: BSH_Assay (550+) | L5: CLK | M5: CLK_Assay | N5: SEPIA | O5: SEPIA_Assay | P5: Pazflor(Predicted by ART) | Q5: Pazflor_Assay | R5: PHET | S5: PHET_Assay | T5: NAPO | U5: NAPO_Assay | X5: SEPIA | Y5: PAZFLOR
C6: 560 plus(1040degF), wt% | E6: 95.34 | F6: 96.2 | G6: 93.87 | H6: 93.7 | J6: 94 | K6: 550+ | L6: 95.5 | M6: 575+ | N6: 93.3 | O6: 550+ | P6: 566 plus | Q6: 575 | R6: 98 | S6: 550+ | T6: 95 | U6: 575+ | W6: Cut | X6: 575+ | Y6: 575+
C7: N, %wt | E7: 0.61 | F7: 0.74 | G7: 0.7 | H7: 0.78 | J7: 0.34 | K7: 0.4947 | L7: 0.79 | M7: 0.8919 | N7: 0.9449 | O7: 0.9357 | P7: 0.762 | Q7: 0.9075 | R7: 0.2866 | S7: 0.2767 | T7: 0.84 | U7: 0.9924 | W7: N | X7: 0.8689 | Y7: =0.9075 -> 0.9075
C8: S, %wt | E8: 5.8 | F8: 5.7 | G8: 4.4 | H8: 5.248 | J8: 7.6 | K8: 7.43 | L8: 5.8 | M8: 6.53 | N8: 0.845 | O8: 0.82 | P8: 0.76 | Q8: 0.91 | R8: 0.267 | S8: 0.077 | T8: 3.37 | U8: 3.21 | W8: S | X8: 0.76 | Y8: 0.91
C9: MCR, %wt | E9: 26.89 | F9: 31.6 | G9: 25.28 | H9: 32.07 | J9: 33 | K9: 29.2 | L9: 30.1 | M9: 36.2 | N9: 16.88 | O9: 15.5 | P9: 20.9 | Q9: 23.4 | R9: 20.295 | S9: 11.1 | T9: 34.335 | U9: 33.2 | X9: 16.8 | Y9: 23.4
C10: C5 As,%wt | E10: 34.97 | F10: 33.22 | G10: 33.19 | H10: 40.28 | J10: 35.1 | L10: 33.17 | N10: 14.79 | P10: - | R10: 27.5 | T10: 47.3
C11: C7 As, %wt | E11: 20.25 | F11: 20.9 | G11: 20.54 | H11: 22 | J11: 21.3 | K11: 19.7 | L11: 19.8 | M11: 15 | N11: 4.4 | O11: 3.4 | P11: 4.74 | Q11: 4.6 | R11: 10.05 | S11: 0.2 | T11: 31.85 | U11: 24.6 | X11: 4.3 | Y11: 4.6
C12: Ni, ppm | E12: 97.9 | F12: 113.36 | G12: 138 | H12: 171.3 | J12: 77.7 | K12: 67.5 | L12: 173.4 | M12: 191 | N12: 54.39 | O12: 50.9 | P12: 98.9 | Q12: 110.9 | R12: 44.42 | S12: 11 | T12: 356.73 | U12: 365.5 | X12: 49.6 | Y12: 46.1
C13: V, ppm | E13: 266 | F13: 285.96 | G13: 351 | H13: 481.4 | J13: 273.45 | K13: 257.4 | L13: 431.17 | M13: 523 | N13: 56.75 | O13: 49.9 | P13: 38.4 | Q13: 46.1 | R13: 0.71 | S13: 0.8 | T13: 958.57 | U13: 978 | X13: 45.1 | Y13: 110.9
C14: Fe, ppm
C15: Density, kg/L
C16: H, %wt
C17: C, %wt
C18: H/C | E18: 0.113 | F18: 0.115 | G18: 0.116 | H18: 0.116 | J18: 0.115 | L18: 0.116 | N18: 0.128 | P18: 0.118 | R18: 0.139 | T18: 0.12 | W18: H/C
C19: CHNS
C20: N/S | E20: =E7/E8 -> 0.10517241 | F20: =F7/F8 -> 0.12982456 | G20: =G7/G8 -> 0.15909091 | H20: =H7/H8 -> 0.14862805 | J20: =J7/J8 -> 0.044736842 | L20: =L7/L8 -> 0.1362069 | N20: =N7/N8 -> 1.1182249 | P20: =P7/P8 -> 1.0026316 | R20: =R7/R8 -> 1.0734082 | T20: =T7/T8 -> 0.24925816 | W20: N/S | X20: =X7/X8 -> 1.1432895 | Y20: =Y7/Y8 -> 0.99725275
C21: Ni/V | E21: =E12/E13 -> 0.36804511 | F21: =F12/F13 -> 0.39641908 | G21: =G12/G13 -> 0.39316239 | H21: =H12/H13 -> 0.35583714 | J21: =J12/J13 -> 0.28414701 | L21: =L12/L13 -> 0.40216156 | N21: =N12/N13 -> 0.9584141 | P21: =P12/P13 -> 2.5755208 | R21: =R12/R13 -> 62.56338 | T21: =T12/T13 -> 0.3721481 | W21: Ni/V | X21: =X12/X13 -> 1.0997783 | Y21: =Y12/Y13 -> 0.41568981
C22: Wax, %wt | K22: 2.9 | M22: 4.8 | O22: 5.8 | Q22: 6.8 | S22: 24 | U22: 4.3 | W22: Wax | X22: 0.6 | Y22: 7.4
C23: UOPK | W23: UOPK | X23: 12 | Y23: 11.7
J24: Heavy: Good | L24: Heavy: Moerate Difficult | N24: Medium: Difficult crude | R24: Light: Difficult-Parraffinic | T24: Heavy: Difficult Asphaltene
C25: BSH | D25: 55 | E25: 55 | F25: 55 | G25: 40 | H25: 40
C26: CLK | D26: 25 | E26: 25 | F26: 25 | G26: 25 | H26: 25
C27: PAZFLOR | D27: 10 | E27: 10 | F27: - | G27: 10 | H27: -
C28: SEPIA | D28: - | E28: - | F28: 10 | G28: - | H28: 10
C29: PHET | D29: 10 | E29: 10 | F29: 10 | G29: 10 | H29: 10
C30: NAPO | G30: 15 | H30: 15
E31: =SUM(E25:E30) -> 100 | F31: =SUM(F25:F30) -> 100 | G31: =SUM(G25:G30) -> 100 | H31: =SUM(H25:H30) -> 100
M34: 75 | Q34: 85
L35: BSH | M35: 0.4 | N35: =M35*$M$34 -> 30 | O35: =N35*J8/100 -> 2.28 | Q35: 0.55 | R35: =$Q$34*Q35 -> 46.75 | S35: =R35*J8/100 -> 3.553
L36: CLK | M36: 0.25 | N36: =M36*$M$34 -> 18.75 | O36: =N36*L8/100 -> 1.0875 | Q36: 0.25 | R36: =$Q$34*Q36 -> 21.25 | S36: =R36*L8/100 -> 1.2325
L37: SEPIA | M37: 0.1 | N37: =M37*$M$34 -> 7.5 | O37: =N37*N8/100 -> 0.063375 | Q37: 0.1 | R37: =$Q$34*Q37 -> 8.5 | S37: =R37*O8/100 -> 0.0697
L38: PHET | M38: 0.1 | N38: =M38*$M$34 -> 7.5 | O38: =N38*R8/100 -> 0.020025 | Q38: 0.1 | R38: =$Q$34*Q38 -> 8.5 | S38: =R8*R38/100 -> 0.022695
L39: NAPO | M39: 0.15 | N39: =M39*$M$34 -> 11.25 | O39: =N39*T8/100 -> 0.379125 | S39: =SUM(S35:S38) -> 4.877895
O40: =SUM(O35:O39) -> 3.830025 | S40: =S39/Q34 -> 0.057387
O41: =O40/M34 -> 0.051067

Sheet Master Template
F2: VR | J2: VR | P2: VR | X2: ISV: ABQ3358 | AB2: ISV: Low Sedim | AH2: ISV: High Sedim | AP2: HPS: ABQ3358(Aging) | AT2: HPS | AZ2: HPS | BH2: LTO | BL2: LTO | BR2: LTO | CA2: High Gas | CE2: High Gas | CK2: High Gas | CS2: Low Gas | CW2: Low Gas | DC2: Low Gas
F3: Aging-ABQ3358 | J3: Low Sed | P3: High Sed | X3: Aging-ABQ3358 | AB3: Low Sed | AH3: High Sed | AP3: Aging- ABQ3358 | AT3: Low Sed | AZ3: High Sed | BH3: Aging-ABQ3358(Aging) | BL3: Low Sed | BR3: High Sed | CA3: Aging-ABQ3358 | CE3: Low Sed | CK3: High Sed | CS3: Aging- ABQ3358 | CW3: Low Sed | DC3: High Sed
C4: Pilot Plant Operation---> | F4: 45855 | G4: 45856 | H4: 45857 | I4: 45858 | J4: 45859 | K4: 45860 | L4: 45861 | M4: 45862 | N4: 45863 | O4: 45864 | P4: 45865 | Q4: 45866 | R4: 45867 | S4: 45868 | T4: 45869 | U4: 45870
C5: Lab Date--> | F5: 45856 | G5: 45857 | H5: 45858 | I5: 45859 | J5: 45860 | K5: 45861
C6: Day on stream--> | F6: 1 | G6: 2 | H6: 3 | I6: 4 | J6: 5 | K6: 6 | L6: 7 | M6: 8 | N6: 9 | O6: 10 | P6: 11 | Q6: 12 | R6: 13 | S6: 14 | T6: 15 | U6: 16 | V6: 16_2 | X6: 1 | Y6: 2 | Z6: 3 | AA6: 4 | AB6: 5 | AC6: 6 | AD6: 7 | AE6: 8 | AF6: 9 | AG6: 10 | AH6: 11 | AI6: 12 | AJ6: 13 | AK6: 14 | AL6: 15 | AM6: 16 | AN6: 16_2 | AP6: 1 | AQ6: 2 | AR6: 3 | AS6: 4 | AT6: 5 | AU6: 6 | AV6: 7 | AW6: 8 | AX6: 9 | AY6: 10 | AZ6: 11 | BA6: 12 | BB6: 13 | BC6: 14 | BD6: 15 | BE6: 16 | BF6: 16_2 | BH6: 1 | BI6: 2 | BJ6: 3 | BK6: 4 | BL6: 5 | BM6: 6 | BN6: 7 | BO6: 8 | BP6: 9 | BQ6: 10 | BR6: 11 | BS6: 12 | BT6: 13 | BU6: 14 | BV6: 15 | BW6: 16 | BX6: 16_2 | CA6: 1 | CB6: 2 | CC6: 3 | CD6: 4 | CE6: 5 | CF6: 6 | CG6: 7 | CH6: 8 | CI6: 9 | CJ6: 10 | CK6: 11 | CL6: 12 | CM6: 13 | CN6: 14 | CO6: 15 | CP6: 16 | CQ6: 16_2 | CS6: 1 | CT6: 2 | CU6: 3 | CV6: 4 | CW6: 5 | CX6: 6 | CY6: 7 | CZ6: 8 | DA6: 9 | DB6: 10 | DC6: 11 | DD6: 12 | DE6: 13 | DF6: 14 | DG6: 15 | DH6: 16 | DI6: 16_2
F7: %wt | J7: %wt | P7: %wt | X7: %wt | AB7: %wt | AH7: %wt | AP7: %wt | AT7: %wt | AZ7: %wt | BH7: %wt | BL7: %wt | BR7: %wt | CA7: %wt | CE7: %wt | CK7: %wt | CS7: %vol(mol) | CW7: %vol(mol) | DC7: %vol(mol)
C8: IBP-90 | F8: {='HPS DAILY'!$G$66:$G$73} -> 0 | G8: {='HPS DAILY'!$G$66:$G$73} -> 0 | H8: {='HPS DAILY'!$G$66:$G$73} -> 0 | I8: {='HPS DAILY'!$G$66:$G$73} -> 0 | J8: {='HPS DAILY'!H66:H73} -> 0 | K8: {='HPS DAILY'!H66:H73} -> 0 | L8: {='HPS DAILY'!H66:H73} -> 0 | M8: {='HPS DAILY'!H66:H73} -> 0 | N8: {='HPS DAILY'!H66:H73} -> 0 | O8: {='HPS DAILY'!H66:H73} -> 0 | P8: {='HPS DAILY'!I66:I73} -> 0 | Q8: {='HPS DAILY'!I66:I73} -> 0 | R8: {='HPS DAILY'!I66:I73} -> 0 | S8: {='HPS DAILY'!I66:I73} -> 0 | T8: {='HPS DAILY'!I66:I73} -> 0 | U8: {='HPS DAILY'!$I$66:$I$73} -> 0 | V8: {='HPS DAILY'!$I$66:$I$73} -> 0 | X8: {=ISV!G65:G$72} -> 0.142 | Y8: {=ISV!H65:H$72} -> 0.504 | Z8: {=ISV!I65:I$72} -> 0.121 | AA8: {=ISV!J65:J$72} -> 0 | AB8: {=ISV!K65:K$72} -> 0.19 | AC8: {=ISV!L65:L$72} -> 0.36 | AD8: {=ISV!M65:M$72} -> 0.693 | AE8: {=ISV!N65:N$72} -> 0.23 | ... AM8: {=ISV!V65:V$72} -> 0 | AP8: {='HPS DAILY'!J$66:J$73} -> 0.143 | AQ8: {='HPS DAILY'!K$66:K$73} -> 0.266 | AR8: {='HPS DAILY'!L$66:L$73} -> 0.151 | AS8: {='HPS DAILY'!M$66:M$73} -> 0.264 | AT8: {='HPS DAILY'!N$66:N$73} -> 0.584 | AU8: {='HPS DAILY'!O$66:O$73} -> 0.73 | AV8: {='HPS DAILY'!P$66:P$73} -> 0.28 | AW8: {='HPS DAILY'!Q$66:Q$73} -> 0.454 | ... BF8: {='HPS DAILY'!Z$66:Z$73} -> 0.192 | BH8: {='LTO DAILY'!H$55:H$62} -> 2 | BI8: {='LTO DAILY'!I$55:I$62} -> 7.5 | BJ8: {='LTO DAILY'!J$55:J$62} -> 9.5 | BK8: {='LTO DAILY'!K$55:K$62} -> 6.5 | BL8: {='LTO DAILY'!L$55:L$62} -> 4.5 | BM8: {='LTO DAILY'!M$55:M$62} -> 2.5 | BN8: {='LTO DAILY'!N$55:N$62} -> 3.5 | BO8: {='LTO DAILY'!O$55:O$62} -> 3.5 | ... BX8: {='LTO DAILY'!X$55:X$62} -> 1.1 | BZ8: H2 | CA8: {='HPS DAILY'!J106:J112} -> 54.35 | CB8: {='HPS DAILY'!K106:K112} -> 46.17 | CC8: {='HPS DAILY'!L106:L112} -> 59.72 | CD8: {='HPS DAILY'!M106:M112} -> 71.92 | CE8: {='HPS DAILY'!N106:N112} -> 51.89 | CF8: {='HPS DAILY'!O106:O112} -> 51.32 | CG8: {='HPS DAILY'!P106:P112} -> 50.92 | CH8: {='HPS DAILY'!Q106:Q112} -> 49.96 | ... CQ8: {='HPS DAILY'!Z106:Z112} -> 0 | CS8: {='HPS DAILY'!J$93:J$99} -> 37.87 | CT8: =CU8 -> 13.51 | CU8: {='HPS DAILY'!L$93:L$99} -> 13.51 | CV8: {='HPS DAILY'!M$93:M$99} -> 5.58 | CW8: {='HPS DAILY'!N$93:N$99} -> 2 | CX8: {='HPS DAILY'!O$93:O$99} -> 2.11 | CY8: {='HPS DAILY'!P$93:P$99} -> 1.78 | CZ8: {='HPS DAILY'!Q$93:Q$99} -> 1.99 | DA8: {='HPS DAILY'!R$93:R$99} -> 2 | DB8: {='HPS DAILY'!S$93:S$99} -> 2.1 | ... DI8: {='HPS DAILY'!Z$93:Z$99} -> 0 | DJ8: H2
C9: 90-160 | F9: 0.007 | G9: 0.007 | H9: 0.007 | I9: 0.007 | J9: 0 | K9: 0 | L9: 0 | M9: 0 | N9: 0 | O9: 0 | P9: 0 | Q9: 0 | R9: 0 | S9: 0 | T9: 0 | U9: 0 | V9: 0 | X9: 41.623 | Y9: 2.633 | Z9: 0.345 | AA9: 0 | AB9: 0.573 | AC9: 0.495 | AD9: 0.596 | AE9: 0.552 | AF9: 0 | AG9: 0 | AH9: 0 | AI9: 0.141 | AJ9: 0.586 | AK9: 0 | AL9: 0 | AM9: 0 | AP9: 0.584 | AQ9: 0.402 | AR9: 0.457 | AS9: 0.494 | AT9: 1.697 | AU9: 1.605 | AV9: 1.588 | AW9: 1.393 | AX9: 1.505 | AY9: 1.484 | AZ9: 1.876 | BA9: 1.749 | BB9: 1.442 | BC9: 1.941 | BD9: 1.897 | BE9: 1.348 | BF9: 1.499 | BH9: 29 | BI9: 22 | BJ9: 23 | BK9: 22 | BL9: 23.5 | BM9: 24 | BN9: 26.5 | BO9: 26.5 | BP9: 25.5 | BQ9: 27.4 | BR9: 29.4 | BS9: 26.6 | BT9: 23.8 | BU9: 26.9 | BV9: 28.3 | BW9: 28.5 | BX9: 20.4 | BZ9: CH4 | CA9: 5.83 | CB9: 4.34 | CC9: 5.88 | CD9: 7.1 | CE9: 15.37 | CF9: 14.29 | CG9: 14.36 | CH9: 12.7 | CI9: 12.78 | CJ9: 13.91 | CK9: 14.9 | CL9: 15.42 | CM9: 15.02 | CN9: 14.69 | CO9: 13.62 | CP9: 13.62 | CQ9: 0 | CS9: 5.78 | CT9: =CU9 -> 0.21 | CU9: 0.21 | CV9: 0.1 | CW9: 0.15 | CX9: 0.19 | CY9: 0.12 | CZ9: 0.14 | DA9: 0.16 | DB9: 0.17 | DC9: 0.2 | DD9: 0.33 | DE9: 0.35 | DF9: 0.15 | DG9: 0.19 | DH9: 0.19 | DI9: 0 | DJ9: CH4
C10: 160-250 | F10: 0.264 | G10: 0.264 | H10: 0.264 | I10: 0.264 | J10: 0.03 | K10: 0.03 | L10: 0.03 | M10: 0.03 | N10: 0.03 | O10: 0.03 | P10: 0 | Q10: 0 | R10: 0 | S10: 0 | T10: 0 | U10: 0 | V10: 0 | X10: 13.215 | Y10: 1.962 | Z10: 0.962 | AA10: 0 | AB10: 1.381 | AC10: 1.542 | AD10: 2.232 | AE10: 2.031 | AF10: 0 | AG10: 0 | AH10: 0 | AI10: 1.038 | AJ10: 2.286 | AK10: 0 | AL10: 0 | AM10: 0 | AP10: 2.33 | AQ10: 1.913 | AR10: 2.169 | AS10: 2.015 | AT10: 7.016 | AU10: 6.629 | AV10: 7.044 | AW10: 6.84 | AX10: 7.343 | AY10: 6.839 | AZ10: 7.7 | BA10: 7.011 | BB10: 7.429 | BC10: 8.292 | BD10: 8.581 | BE10: 6.418 | BF10: 6.638 | BH10: 43.5 | BI10: 39.5 | BJ10: 36.5 | BK10: 37.5 | BL10: 39.5 | BM10: 45.5 | BN10: 45 | BO10: 45 | BP10: 46 | BQ10: 45.4 | BR10: 42.4 | BS10: 43.5 | BT10: 44.3 | BU10: 44.6 | BV10: 44.7 | BW10: 42 | BX10: 50.3 | BZ10: C2H6 | CA10: 5.2 | CB10: 3.69 | CC10: 4.78 | CD10: 5.68 | CE10: 11.69 | CF10: 11.12 | CG10: 11 | CH10: 10.13 | CI10: 10.07 | CJ10: 10.56 | CK10: 11.18 | CL10: 11.4 | CM10: 11.16 | CN10: 11.13 | CO10: 10.27 | CP10: 10.27 | CQ10: 0 | CS10: 9.36 | CT10: =CU10 -> 0.08 | CU10: 0.08 | CV10: 0.06 | CW10: 0.22 | CX10: 0.27 | CY10: 0.18 | CZ10: 0.2 | DA10: 0.22 | DB10: 0.23 | DC10: 0.36 | DD10: 0.53 | DE10: 0.53 | DF10: 0.29 | DG10: 0.34 | DH10: 0.34 | DI10: 0 | DJ10: C2H6
C11: 250-360 | F11: 1.041 | G11: 1.041 | H11: 1.041 | I11: 1.041 | J11: 0.165 | K11: 0.165 | L11: 0.165 | M11: 0.165 | N11: 0.165 | O11: 0.165 | P11: 0.219 | Q11: 0.219 | R11: 0.219 | S11: 0.219 | T11: 0.219 | U11: 0.219 | V11: 0.219 | X11: 2.579 | Y11: 2.907 | Z11: 3.044 | AA11: 0 | AB11: 4.586 | AC11: 4.597 | AD11: 5.359 | AE11: 4.618 | AF11: 0 | AG11: 0 | AH11: 0 | AI11: 4.492 | AJ11: 5.729 | AK11: 0 | AL11: 0 | AM11: 0 | AP11: 6.661 | AQ11: 6.17 | AR11: 6.61 | AS11: 6.505 | AT11: 16.115 | AU11: 14.157 | AV11: 14.746 | AW11: 14.393 | AX11: 14.273 | AY11: 13.709 | AZ11: 15.262 | BA11: 14.618 | BB11: 15.251 | BC11: 15.74 | BD11: 16.095 | BE11: 14.513 | BF11: 14.006 | BH11: 16.5 | BI11: 23 | BJ11: 24 | BK11: 26.5 | BL11: 25.5 | BM11: 23.5 | BN11: 21.5 | BO11: 21.5 | BP11: 21.5 | BQ11: 20.3 | BR11: 18.4 | BS11: 20.8 | BT11: 23.8 | BU11: 21 | BV11: 19.9 | BW11: 19.5 | BX11: 24.4 | BZ11: C3H8 | CA11: 6.23 | CB11: 3.97 | CC11: 5.11 | CD11: 5.36 | CE11: 9.96 | CF11: 10.14 | CG11: 9.98 | CH11: 10.06 | CI11: 9.68 | CJ11: 9.53 | CK11: 10.44 | CL11: 10.12 | CM11: 10.18 | CN11: 10.24 | CO11: 9.87 | CP11: 9.87 | CQ11: 0 | CS11: 13.81 | CT11: =CU11 -> 0.19 | CU11: 0.19 | CV11: 0.08 | CW11: 0.3 | CX11: 0.4 | CY11: 0.29 | CZ11: 0.3 | DA11: 0.33 | DB11: 0.32 | DC11: 0.6 | DD11: 0.8 | DE11: 0.79 | DF11: 0.46 | DG11: 0.53 | DH11: 0.53 | DI11: 0 | DJ11: C3H8
C12: 360-500 | F12: 4.743 | G12: 4.743 | H12: 4.743 | I12: 4.743 | J12: 0.472 | K12: 0.472 | L12: 0.472 | M12: 0.472 | N12: 0.472 | O12: 0.472 | P12: 0.805 | Q12: 0.805 | R12: 0.805 | S12: 0.805 | T12: 0.805 | U12: 0.805 | V12: 0.805 | X12: 7.742 | Y12: 10.257 | Z12: 10.558 | AA12: 0 | AB12: 15.267 | AC12: 12.727 | AD12: 12.381 | AE12: 10.598 | AF12: 0 | AG12: 0 | AH12: 0 | AI12: 10.946 | AJ12: 12.405 | AK12: 0 | AL12: 0 | AM12: 0 | AP12: 16.82 | AQ12: 16.152 | AR12: 17.013 | AS12: 16.838 | AT12: 26.524 | AU12: 23.328 | AV12: 24.245 | AW12: 24.226 | AX12: 23.512 | AY12: 22.968 | AZ12: 23 | BA12: 22.116 | BB12: 24.204 | BC12: 24.354 | BD12: 24.951 | BE12: 22.513 | BF12: 21.085 | BH12: 9 | BI12: 8 | BJ12: 7 | BK12: 7.5 | BL12: 7 | BM12: 4.5 | BN12: 3.5 | BO12: 3.5 | BP12: 3.5 | BQ12: 3.4 | BR12: 3.1 | BS12: 5.6 | BT12: 4.7 | BU12: 3.9 | BV12: 3.4 | BW12: 3.2 | BX12: 3.8 | BZ12: C4H10(Total) | CA12: 7.1 | CB12: 3.76 | CC12: 8.26 | CD12: 3.85 | CE12: 5.97 | CF12: 6.61 | CG12: 6.63 | CH12: 7.15 | CI12: 6.65 | CJ12: 6.43 | CK12: 6.95 | CL12: 6.46 | CM12: 6.82 | CN12: 6.76 | CO12: 7.04 | CP12: 7.04 | CQ12: 0 | CS12: 12.58 | CT12: =CU12 -> 0.7 | CU12: 0.7 | CV12: 0.23 | CW12: 0.45 | CX12: 0.52 | CY12: 0.41 | CZ12: 0.42 | DA12: 0.42 | DB12: 0.4 | DC12: 0.78 | DD12: 0.93 | DE12: 0.91 | DF12: 0.57 | DG12: 0.61 | DH12: 0.61 | DI12: 0 | DJ12: C4H10(Total)
